[2025-03-20T00:17:23.963+0000] {local_task_job_runner.py:123} INFO - ::group::Pre task execution logs
[2025-03-20T00:17:24.621+0000] {taskinstance.py:2614} INFO - Dependencies all met for dep_context=non-requeueable deps ti=<TaskInstance: automate_emploi_extraction.insert_data scheduled__2023-10-15T00:00:00+00:00 [queued]>
[2025-03-20T00:17:24.803+0000] {taskinstance.py:2614} INFO - Dependencies all met for dep_context=requeueable deps ti=<TaskInstance: automate_emploi_extraction.insert_data scheduled__2023-10-15T00:00:00+00:00 [queued]>
[2025-03-20T00:17:24.804+0000] {taskinstance.py:2867} INFO - Starting attempt 2 of 2
[2025-03-20T00:17:24.981+0000] {taskinstance.py:2890} INFO - Executing <Task(PythonOperator): insert_data> on 2023-10-15 00:00:00+00:00
[2025-03-20T00:17:25.298+0000] {standard_task_runner.py:72} INFO - Started process 20665 to run task
[2025-03-20T00:17:25.365+0000] {standard_task_runner.py:104} INFO - Running: ['airflow', 'tasks', 'run', 'automate_emploi_extraction', 'insert_data', 'scheduled__2023-10-15T00:00:00+00:00', '--job-id', '1270', '--raw', '--subdir', 'DAGS_FOLDER/dag_scraper_offres_emploi.py', '--cfg-path', '/tmp/tmp9yn98hvb']
[2025-03-20T00:17:25.368+0000] {standard_task_runner.py:105} INFO - Job 1270: Subtask insert_data
[2025-03-20T00:17:26.001+0000] {task_command.py:467} INFO - Running <TaskInstance: automate_emploi_extraction.insert_data scheduled__2023-10-15T00:00:00+00:00 [running]> on host DESKTOP-IM7V4RI.
[2025-03-20T00:17:26.708+0000] {taskinstance.py:3134} INFO - Exporting env vars: AIRFLOW_CTX_DAG_OWNER='airflow' AIRFLOW_CTX_DAG_ID='automate_emploi_extraction' AIRFLOW_CTX_TASK_ID='insert_data' AIRFLOW_CTX_EXECUTION_DATE='2023-10-15T00:00:00+00:00' AIRFLOW_CTX_TRY_NUMBER='2' AIRFLOW_CTX_DAG_RUN_ID='scheduled__2023-10-15T00:00:00+00:00'
[2025-03-20T00:17:26.711+0000] {logging_mixin.py:190} INFO - Task instance is in running state
[2025-03-20T00:17:26.712+0000] {logging_mixin.py:190} INFO -  Previous state of the Task instance: queued
[2025-03-20T00:17:26.713+0000] {logging_mixin.py:190} INFO - Current task name:insert_data state:running start_date:2025-03-20 00:17:24.622021+00:00
[2025-03-20T00:17:26.713+0000] {logging_mixin.py:190} INFO - Dag name:automate_emploi_extraction and current dag run status:running
[2025-03-20T00:17:26.715+0000] {taskinstance.py:732} INFO - ::endgroup::
[2025-03-20T00:17:27.049+0000] {taskinstance.py:3313} ERROR - Task failed with exception
Traceback (most recent call last):
  File "/home/mohammed/venv/lib/python3.11/site-packages/mysql/connector/network.py", line 799, in open_connection
    self.sock.connect(sockaddr)
ConnectionRefusedError: [Errno 111] Connection refused

The above exception was the direct cause of the following exception:

Traceback (most recent call last):
  File "/home/mohammed/venv/lib/python3.11/site-packages/airflow/models/taskinstance.py", line 768, in _execute_task
    result = _execute_callable(context=context, **execute_callable_kwargs)
             ^^^^^^^^^^^^^^^^^^^^^^^^^^^^^^^^^^^^^^^^^^^^^^^^^^^^^^^^^^^^^
  File "/home/mohammed/venv/lib/python3.11/site-packages/airflow/models/taskinstance.py", line 734, in _execute_callable
    return ExecutionCallableRunner(
           ^^^^^^^^^^^^^^^^^^^^^^^^
  File "/home/mohammed/venv/lib/python3.11/site-packages/airflow/utils/operator_helpers.py", line 252, in run
    return self.func(*args, **kwargs)
           ^^^^^^^^^^^^^^^^^^^^^^^^^^
  File "/home/mohammed/venv/lib/python3.11/site-packages/airflow/models/baseoperator.py", line 424, in wrapper
    return func(self, *args, **kwargs)
           ^^^^^^^^^^^^^^^^^^^^^^^^^^^
  File "/home/mohammed/venv/lib/python3.11/site-packages/airflow/operators/python.py", line 238, in execute
    return_value = self.execute_callable()
                   ^^^^^^^^^^^^^^^^^^^^^^^
  File "/home/mohammed/venv/lib/python3.11/site-packages/airflow/operators/python.py", line 256, in execute_callable
    return runner.run(*self.op_args, **self.op_kwargs)
           ^^^^^^^^^^^^^^^^^^^^^^^^^^^^^^^^^^^^^^^^^^^
  File "/home/mohammed/venv/lib/python3.11/site-packages/airflow/utils/operator_helpers.py", line 252, in run
    return self.func(*args, **kwargs)
           ^^^^^^^^^^^^^^^^^^^^^^^^^^
  File "/home/mohammed/airflow/dags/dag_scraper_offres_emploi.py", line 44, in insert_data_into_mysql
    connection = mysql.connector.connect(**MYSQL_CONFIG)
                 ^^^^^^^^^^^^^^^^^^^^^^^^^^^^^^^^^^^^^^^
  File "/home/mohammed/venv/lib/python3.11/site-packages/mysql/connector/pooling.py", line 323, in connect
    return MySQLConnection(*args, **kwargs)
           ^^^^^^^^^^^^^^^^^^^^^^^^^^^^^^^^
  File "/home/mohammed/venv/lib/python3.11/site-packages/mysql/connector/connection.py", line 184, in __init__
    self.connect(**kwargs)
  File "/home/mohammed/venv/lib/python3.11/site-packages/mysql/connector/abstracts.py", line 1529, in connect
    self._open_connection()
  File "/home/mohammed/venv/lib/python3.11/site-packages/mysql/connector/connection.py", line 410, in _open_connection
    raise err
  File "/home/mohammed/venv/lib/python3.11/site-packages/mysql/connector/connection.py", line 381, in _open_connection
    self._socket.open_connection()
  File "/home/mohammed/venv/lib/python3.11/site-packages/mysql/connector/network.py", line 810, in open_connection
    raise InterfaceError(
mysql.connector.errors.InterfaceError: 2002: Can't connect to local MySQL server through socket '%-.100s' (%s) (Warning: not all arguments converted during string formatting)
[2025-03-20T00:17:27.199+0000] {logging_mixin.py:190} INFO - Task instance in failure state
[2025-03-20T00:17:27.200+0000] {logging_mixin.py:190} INFO - Task start:2025-03-20 00:17:24.622021+00:00 end:2025-03-20 00:17:27.198340+00:00 duration:2.576319
[2025-03-20T00:17:27.201+0000] {logging_mixin.py:190} INFO - Task:<Task(PythonOperator): insert_data> dag:<DAG: automate_emploi_extraction> dagrun:<DagRun automate_emploi_extraction @ 2023-10-15 00:00:00+00:00: scheduled__2023-10-15T00:00:00+00:00, state:running, queued_at: 2025-03-19 23:59:47.331289+00:00. externally triggered: False>
[2025-03-20T00:17:27.201+0000] {logging_mixin.py:190} INFO - Failure caused by 2002: Can't connect to local MySQL server through socket '%-.100s' (%s) (Warning: not all arguments converted during string formatting)
[2025-03-20T00:17:27.202+0000] {taskinstance.py:1226} INFO - Marking task as FAILED. dag_id=automate_emploi_extraction, task_id=insert_data, run_id=scheduled__2023-10-15T00:00:00+00:00, execution_date=20231015T000000, start_date=20250320T001724, end_date=20250320T001727
[2025-03-20T00:17:29.565+0000] {taskinstance.py:341} INFO - ::group::Post task execution logs
[2025-03-20T00:17:29.566+0000] {standard_task_runner.py:124} ERROR - Failed to execute job 1270 for task insert_data (2002: Can't connect to local MySQL server through socket '%-.100s' (%s) (Warning: not all arguments converted during string formatting); 20665)
Traceback (most recent call last):
  File "/home/mohammed/venv/lib/python3.11/site-packages/mysql/connector/network.py", line 799, in open_connection
    self.sock.connect(sockaddr)
ConnectionRefusedError: [Errno 111] Connection refused

The above exception was the direct cause of the following exception:

Traceback (most recent call last):
  File "/home/mohammed/venv/lib/python3.11/site-packages/airflow/task/task_runner/standard_task_runner.py", line 117, in _start_by_fork
    ret = args.func(args, dag=self.dag)
          ^^^^^^^^^^^^^^^^^^^^^^^^^^^^^
  File "/home/mohammed/venv/lib/python3.11/site-packages/airflow/cli/cli_config.py", line 49, in command
    return func(*args, **kwargs)
           ^^^^^^^^^^^^^^^^^^^^^
  File "/home/mohammed/venv/lib/python3.11/site-packages/airflow/utils/cli.py", line 116, in wrapper
    return f(*args, **kwargs)
           ^^^^^^^^^^^^^^^^^^
  File "/home/mohammed/venv/lib/python3.11/site-packages/airflow/cli/commands/task_command.py", line 483, in task_run
    task_return_code = _run_task_by_selected_method(args, _dag, ti)
                       ^^^^^^^^^^^^^^^^^^^^^^^^^^^^^^^^^^^^^^^^^^^^
  File "/home/mohammed/venv/lib/python3.11/site-packages/airflow/cli/commands/task_command.py", line 256, in _run_task_by_selected_method
    return _run_raw_task(args, ti)
           ^^^^^^^^^^^^^^^^^^^^^^^
  File "/home/mohammed/venv/lib/python3.11/site-packages/airflow/cli/commands/task_command.py", line 341, in _run_raw_task
    return ti._run_raw_task(
           ^^^^^^^^^^^^^^^^^
  File "/home/mohammed/venv/lib/python3.11/site-packages/airflow/utils/session.py", line 97, in wrapper
    return func(*args, session=session, **kwargs)
           ^^^^^^^^^^^^^^^^^^^^^^^^^^^^^^^^^^^^^^
  File "/home/mohammed/venv/lib/python3.11/site-packages/airflow/models/taskinstance.py", line 3006, in _run_raw_task
    return _run_raw_task(
           ^^^^^^^^^^^^^^
  File "/home/mohammed/venv/lib/python3.11/site-packages/airflow/models/taskinstance.py", line 274, in _run_raw_task
    TaskInstance._execute_task_with_callbacks(
  File "/home/mohammed/venv/lib/python3.11/site-packages/airflow/models/taskinstance.py", line 3161, in _execute_task_with_callbacks
    result = self._execute_task(context, task_orig)
             ^^^^^^^^^^^^^^^^^^^^^^^^^^^^^^^^^^^^^^
  File "/home/mohammed/venv/lib/python3.11/site-packages/airflow/models/taskinstance.py", line 3185, in _execute_task
    return _execute_task(self, context, task_orig)
           ^^^^^^^^^^^^^^^^^^^^^^^^^^^^^^^^^^^^^^^
  File "/home/mohammed/venv/lib/python3.11/site-packages/airflow/models/taskinstance.py", line 768, in _execute_task
    result = _execute_callable(context=context, **execute_callable_kwargs)
             ^^^^^^^^^^^^^^^^^^^^^^^^^^^^^^^^^^^^^^^^^^^^^^^^^^^^^^^^^^^^^
  File "/home/mohammed/venv/lib/python3.11/site-packages/airflow/models/taskinstance.py", line 734, in _execute_callable
    return ExecutionCallableRunner(
           ^^^^^^^^^^^^^^^^^^^^^^^^
  File "/home/mohammed/venv/lib/python3.11/site-packages/airflow/utils/operator_helpers.py", line 252, in run
    return self.func(*args, **kwargs)
           ^^^^^^^^^^^^^^^^^^^^^^^^^^
  File "/home/mohammed/venv/lib/python3.11/site-packages/airflow/models/baseoperator.py", line 424, in wrapper
    return func(self, *args, **kwargs)
           ^^^^^^^^^^^^^^^^^^^^^^^^^^^
  File "/home/mohammed/venv/lib/python3.11/site-packages/airflow/operators/python.py", line 238, in execute
    return_value = self.execute_callable()
                   ^^^^^^^^^^^^^^^^^^^^^^^
  File "/home/mohammed/venv/lib/python3.11/site-packages/airflow/operators/python.py", line 256, in execute_callable
    return runner.run(*self.op_args, **self.op_kwargs)
           ^^^^^^^^^^^^^^^^^^^^^^^^^^^^^^^^^^^^^^^^^^^
  File "/home/mohammed/venv/lib/python3.11/site-packages/airflow/utils/operator_helpers.py", line 252, in run
    return self.func(*args, **kwargs)
           ^^^^^^^^^^^^^^^^^^^^^^^^^^
  File "/home/mohammed/airflow/dags/dag_scraper_offres_emploi.py", line 44, in insert_data_into_mysql
    connection = mysql.connector.connect(**MYSQL_CONFIG)
                 ^^^^^^^^^^^^^^^^^^^^^^^^^^^^^^^^^^^^^^^
  File "/home/mohammed/venv/lib/python3.11/site-packages/mysql/connector/pooling.py", line 323, in connect
    return MySQLConnection(*args, **kwargs)
           ^^^^^^^^^^^^^^^^^^^^^^^^^^^^^^^^
  File "/home/mohammed/venv/lib/python3.11/site-packages/mysql/connector/connection.py", line 184, in __init__
    self.connect(**kwargs)
  File "/home/mohammed/venv/lib/python3.11/site-packages/mysql/connector/abstracts.py", line 1529, in connect
    self._open_connection()
  File "/home/mohammed/venv/lib/python3.11/site-packages/mysql/connector/connection.py", line 410, in _open_connection
    raise err
  File "/home/mohammed/venv/lib/python3.11/site-packages/mysql/connector/connection.py", line 381, in _open_connection
    self._socket.open_connection()
  File "/home/mohammed/venv/lib/python3.11/site-packages/mysql/connector/network.py", line 810, in open_connection
    raise InterfaceError(
mysql.connector.errors.InterfaceError: 2002: Can't connect to local MySQL server through socket '%-.100s' (%s) (Warning: not all arguments converted during string formatting)
[2025-03-20T00:17:29.654+0000] {local_task_job_runner.py:266} INFO - Task exited with return code 1
[2025-03-20T00:17:29.820+0000] {taskinstance.py:3901} INFO - 0 downstream tasks scheduled from follow-on schedule check
[2025-03-20T00:17:29.837+0000] {local_task_job_runner.py:245} INFO - ::endgroup::
