[2025-03-17T00:24:27.541+0000] {local_task_job_runner.py:123} INFO - ::group::Pre task execution logs
[2025-03-17T00:24:27.671+0000] {taskinstance.py:2614} INFO - Dependencies all met for dep_context=non-requeueable deps ti=<TaskInstance: load_reviews_pipeline.dbt_run scheduled__2024-04-23T00:00:00+00:00 [queued]>
[2025-03-17T00:24:27.693+0000] {taskinstance.py:2614} INFO - Dependencies all met for dep_context=requeueable deps ti=<TaskInstance: load_reviews_pipeline.dbt_run scheduled__2024-04-23T00:00:00+00:00 [queued]>
[2025-03-17T00:24:27.694+0000] {taskinstance.py:2867} INFO - Starting attempt 2 of 2
[2025-03-17T00:24:28.156+0000] {taskinstance.py:2890} INFO - Executing <Task(BashOperator): dbt_run> on 2024-04-23 00:00:00+00:00
[2025-03-17T00:24:28.211+0000] {standard_task_runner.py:72} INFO - Started process 258258 to run task
[2025-03-17T00:24:28.257+0000] {standard_task_runner.py:104} INFO - Running: ['airflow', 'tasks', 'run', 'load_reviews_pipeline', 'dbt_run', 'scheduled__2024-04-23T00:00:00+00:00', '--job-id', '206', '--raw', '--subdir', 'DAGS_FOLDER/dag_load_reviews.py', '--cfg-path', '/tmp/tmpj14tw6kv']
[2025-03-17T00:24:28.259+0000] {standard_task_runner.py:105} INFO - Job 206: Subtask dbt_run
[2025-03-17T00:24:29.139+0000] {task_command.py:467} INFO - Running <TaskInstance: load_reviews_pipeline.dbt_run scheduled__2024-04-23T00:00:00+00:00 [running]> on host DESKTOP-IM7V4RI.
[2025-03-17T00:24:30.087+0000] {taskinstance.py:3134} INFO - Exporting env vars: AIRFLOW_CTX_DAG_OWNER='mohammed' AIRFLOW_CTX_DAG_ID='load_reviews_pipeline' AIRFLOW_CTX_TASK_ID='dbt_run' AIRFLOW_CTX_EXECUTION_DATE='2024-04-23T00:00:00+00:00' AIRFLOW_CTX_TRY_NUMBER='2' AIRFLOW_CTX_DAG_RUN_ID='scheduled__2024-04-23T00:00:00+00:00'
[2025-03-17T00:24:30.099+0000] {logging_mixin.py:190} INFO - Task instance is in running state
[2025-03-17T00:24:30.100+0000] {logging_mixin.py:190} INFO -  Previous state of the Task instance: queued
[2025-03-17T00:24:30.100+0000] {logging_mixin.py:190} INFO - Current task name:dbt_run state:running start_date:2025-03-17 00:24:27.672194+00:00
[2025-03-17T00:24:30.101+0000] {logging_mixin.py:190} INFO - Dag name:load_reviews_pipeline and current dag run status:running
[2025-03-17T00:24:30.102+0000] {taskinstance.py:732} INFO - ::endgroup::
[2025-03-17T00:24:30.132+0000] {subprocess.py:78} INFO - Tmp dir root location: /tmp
[2025-03-17T00:24:30.141+0000] {subprocess.py:88} INFO - Running command: ['/usr/bin/bash', '-c', 'cd /home/mohammed/.dbt/bank_reviews_project && dbt run']
[2025-03-17T00:24:30.304+0000] {subprocess.py:99} INFO - Output:
[2025-03-17T00:24:48.356+0000] {subprocess.py:106} INFO - [0m00:24:48  Running with dbt=1.9.3
[2025-03-17T00:24:52.045+0000] {subprocess.py:106} INFO - [0m00:24:52  Registered adapter: postgres=1.9.0
[2025-03-17T00:25:03.186+0000] {subprocess.py:106} INFO - [0m00:25:03  Found 6 models, 4 data tests, 2 sources, 433 macros
[2025-03-17T00:25:03.407+0000] {subprocess.py:106} INFO - [0m00:25:03
[2025-03-17T00:25:03.508+0000] {subprocess.py:106} INFO - [0m00:25:03  Concurrency: 4 threads (target='dev')
[2025-03-17T00:25:03.564+0000] {subprocess.py:106} INFO - [0m00:25:03
[2025-03-17T00:25:08.062+0000] {subprocess.py:106} INFO - [0m00:25:08  2 of 6 START sql table model public.my_first_dbt_model ......................... [RUN]
[2025-03-17T00:25:08.077+0000] {subprocess.py:106} INFO - [0m00:25:08  1 of 6 START sql view model public.clean_reviews ............................... [RUN]
[2025-03-17T00:25:08.085+0000] {subprocess.py:106} INFO - [0m00:25:08  3 of 6 START sql view model public.remove_duplicates ........................... [RUN]
[2025-03-17T00:25:08.112+0000] {subprocess.py:106} INFO - [0m00:25:08  4 of 6 START sql view model public.stg_clean_reviews ........................... [RUN]
[2025-03-17T00:25:10.370+0000] {subprocess.py:106} INFO - [0m00:25:10  3 of 6 ERROR creating sql view model public.remove_duplicates .................. [[31mERROR[0m in 2.23s]
[2025-03-17T00:25:12.597+0000] {subprocess.py:106} INFO - [0m00:25:12  4 of 6 ERROR creating sql view model public.stg_clean_reviews .................. [[31mERROR[0m in 4.47s]
[2025-03-17T00:25:12.615+0000] {subprocess.py:106} INFO - [0m00:25:12  5 of 6 SKIP relation public.dwh_model .......................................... [[33mSKIP[0m]
[2025-03-17T00:25:12.818+0000] {subprocess.py:106} INFO - [0m00:25:12  2 of 6 ERROR creating sql table model public.my_first_dbt_model ................ [[31mERROR[0m in 4.74s]
[2025-03-17T00:25:12.836+0000] {subprocess.py:106} INFO - [0m00:25:12  6 of 6 SKIP relation public.my_second_dbt_model ................................ [[33mSKIP[0m]
[2025-03-17T00:25:13.623+0000] {subprocess.py:106} INFO - [0m00:25:13  1 of 6 ERROR creating sql view model public.clean_reviews ...................... [[31mERROR[0m in 5.54s]
[2025-03-17T00:25:13.691+0000] {subprocess.py:106} INFO - [0m00:25:13
[2025-03-17T00:25:13.694+0000] {subprocess.py:106} INFO - [0m00:25:13  Finished running 1 table model, 5 view models in 0 hours 0 minutes and 10.12 seconds (10.12s).
[2025-03-17T00:25:14.383+0000] {subprocess.py:106} INFO - [0m00:25:14
[2025-03-17T00:25:14.384+0000] {subprocess.py:106} INFO - [0m00:25:14  [31mCompleted with 4 errors, 0 partial successes, and 0 warnings:[0m
[2025-03-17T00:25:14.385+0000] {subprocess.py:106} INFO - [0m00:25:14
[2025-03-17T00:25:14.386+0000] {subprocess.py:106} INFO - [0m00:25:14    Database Error in model remove_duplicates (models/remove_duplicates.sql)
[2025-03-17T00:25:14.387+0000] {subprocess.py:106} INFO -   syntax error at or near "external"
[2025-03-17T00:25:14.388+0000] {subprocess.py:106} INFO -   LINE 2: drop external if exists "project_data_wherhouse"."public"."r...
[2025-03-17T00:25:14.388+0000] {subprocess.py:106} INFO -                ^
[2025-03-17T00:25:14.388+0000] {subprocess.py:106} INFO - [0m00:25:14
[2025-03-17T00:25:14.389+0000] {subprocess.py:106} INFO - [0m00:25:14    Database Error in model stg_clean_reviews (models/stg_clean_reviews.sql)
[2025-03-17T00:25:14.389+0000] {subprocess.py:106} INFO -   relation "stg_clean_reviews__dbt_backup" already exists
[2025-03-17T00:25:14.389+0000] {subprocess.py:106} INFO -   compiled code at target/run/bank_reviews_project/models/stg_clean_reviews.sql
[2025-03-17T00:25:14.390+0000] {subprocess.py:106} INFO - [0m00:25:14
[2025-03-17T00:25:14.391+0000] {subprocess.py:106} INFO - [0m00:25:14    Database Error in model my_first_dbt_model (models/example/my_first_dbt_model.sql)
[2025-03-17T00:25:14.392+0000] {subprocess.py:106} INFO -   relation "my_first_dbt_model__dbt_backup" already exists
[2025-03-17T00:25:14.393+0000] {subprocess.py:106} INFO -   compiled code at target/run/bank_reviews_project/models/example/my_first_dbt_model.sql
[2025-03-17T00:25:14.394+0000] {subprocess.py:106} INFO - [0m00:25:14
[2025-03-17T00:25:14.395+0000] {subprocess.py:106} INFO - [0m00:25:14    Database Error in model clean_reviews (models/clean_reviews.sql)
[2025-03-17T00:25:14.396+0000] {subprocess.py:106} INFO -   relation "clean_reviews__dbt_backup" already exists
[2025-03-17T00:25:14.396+0000] {subprocess.py:106} INFO -   compiled code at target/run/bank_reviews_project/models/clean_reviews.sql
[2025-03-17T00:25:14.396+0000] {subprocess.py:106} INFO - [0m00:25:14
[2025-03-17T00:25:14.397+0000] {subprocess.py:106} INFO - [0m00:25:14  Done. PASS=0 WARN=0 ERROR=4 SKIP=2 TOTAL=6
[2025-03-17T00:25:19.098+0000] {subprocess.py:110} INFO - Command exited with return code 1
[2025-03-17T00:25:24.417+0000] {taskinstance.py:3313} ERROR - Task failed with exception
Traceback (most recent call last):
  File "/home/mohammed/venv/lib/python3.11/site-packages/airflow/models/taskinstance.py", line 768, in _execute_task
    result = _execute_callable(context=context, **execute_callable_kwargs)
             ^^^^^^^^^^^^^^^^^^^^^^^^^^^^^^^^^^^^^^^^^^^^^^^^^^^^^^^^^^^^^
  File "/home/mohammed/venv/lib/python3.11/site-packages/airflow/models/taskinstance.py", line 734, in _execute_callable
    return ExecutionCallableRunner(
           ^^^^^^^^^^^^^^^^^^^^^^^^
  File "/home/mohammed/venv/lib/python3.11/site-packages/airflow/utils/operator_helpers.py", line 252, in run
    return self.func(*args, **kwargs)
           ^^^^^^^^^^^^^^^^^^^^^^^^^^
  File "/home/mohammed/venv/lib/python3.11/site-packages/airflow/models/baseoperator.py", line 424, in wrapper
    return func(self, *args, **kwargs)
           ^^^^^^^^^^^^^^^^^^^^^^^^^^^
  File "/home/mohammed/venv/lib/python3.11/site-packages/airflow/operators/bash.py", line 276, in execute
    raise AirflowException(
airflow.exceptions.AirflowException: Bash command failed. The command returned a non-zero exit code 1.
[2025-03-17T00:25:24.739+0000] {logging_mixin.py:190} INFO - Task instance in failure state
[2025-03-17T00:25:24.766+0000] {logging_mixin.py:190} INFO - Task start:2025-03-17 00:24:27.672194+00:00 end:2025-03-17 00:25:24.574457+00:00 duration:56.902263
[2025-03-17T00:25:24.776+0000] {logging_mixin.py:190} INFO - Task:<Task(BashOperator): dbt_run> dag:<DAG: load_reviews_pipeline> dagrun:<DagRun load_reviews_pipeline @ 2024-04-23 00:00:00+00:00: scheduled__2024-04-23T00:00:00+00:00, state:running, queued_at: 2025-03-17 00:18:42.183270+00:00. externally triggered: False>
[2025-03-17T00:25:24.777+0000] {logging_mixin.py:190} INFO - Failure caused by Bash command failed. The command returned a non-zero exit code 1.
[2025-03-17T00:25:24.779+0000] {taskinstance.py:1226} INFO - Marking task as FAILED. dag_id=load_reviews_pipeline, task_id=dbt_run, run_id=scheduled__2024-04-23T00:00:00+00:00, execution_date=20240423T000000, start_date=20250317T002427, end_date=20250317T002524
[2025-03-17T00:25:27.065+0000] {taskinstance.py:341} INFO - ::group::Post task execution logs
[2025-03-17T00:25:27.183+0000] {standard_task_runner.py:124} ERROR - Failed to execute job 206 for task dbt_run (Bash command failed. The command returned a non-zero exit code 1.; 258258)
Traceback (most recent call last):
  File "/home/mohammed/venv/lib/python3.11/site-packages/airflow/task/task_runner/standard_task_runner.py", line 117, in _start_by_fork
    ret = args.func(args, dag=self.dag)
          ^^^^^^^^^^^^^^^^^^^^^^^^^^^^^
  File "/home/mohammed/venv/lib/python3.11/site-packages/airflow/cli/cli_config.py", line 49, in command
    return func(*args, **kwargs)
           ^^^^^^^^^^^^^^^^^^^^^
  File "/home/mohammed/venv/lib/python3.11/site-packages/airflow/utils/cli.py", line 116, in wrapper
    return f(*args, **kwargs)
           ^^^^^^^^^^^^^^^^^^
  File "/home/mohammed/venv/lib/python3.11/site-packages/airflow/cli/commands/task_command.py", line 483, in task_run
    task_return_code = _run_task_by_selected_method(args, _dag, ti)
                       ^^^^^^^^^^^^^^^^^^^^^^^^^^^^^^^^^^^^^^^^^^^^
  File "/home/mohammed/venv/lib/python3.11/site-packages/airflow/cli/commands/task_command.py", line 256, in _run_task_by_selected_method
    return _run_raw_task(args, ti)
           ^^^^^^^^^^^^^^^^^^^^^^^
  File "/home/mohammed/venv/lib/python3.11/site-packages/airflow/cli/commands/task_command.py", line 341, in _run_raw_task
    return ti._run_raw_task(
           ^^^^^^^^^^^^^^^^^
  File "/home/mohammed/venv/lib/python3.11/site-packages/airflow/utils/session.py", line 97, in wrapper
    return func(*args, session=session, **kwargs)
           ^^^^^^^^^^^^^^^^^^^^^^^^^^^^^^^^^^^^^^
  File "/home/mohammed/venv/lib/python3.11/site-packages/airflow/models/taskinstance.py", line 3006, in _run_raw_task
    return _run_raw_task(
           ^^^^^^^^^^^^^^
  File "/home/mohammed/venv/lib/python3.11/site-packages/airflow/models/taskinstance.py", line 274, in _run_raw_task
    TaskInstance._execute_task_with_callbacks(
  File "/home/mohammed/venv/lib/python3.11/site-packages/airflow/models/taskinstance.py", line 3161, in _execute_task_with_callbacks
    result = self._execute_task(context, task_orig)
             ^^^^^^^^^^^^^^^^^^^^^^^^^^^^^^^^^^^^^^
  File "/home/mohammed/venv/lib/python3.11/site-packages/airflow/models/taskinstance.py", line 3185, in _execute_task
    return _execute_task(self, context, task_orig)
           ^^^^^^^^^^^^^^^^^^^^^^^^^^^^^^^^^^^^^^^
  File "/home/mohammed/venv/lib/python3.11/site-packages/airflow/models/taskinstance.py", line 768, in _execute_task
    result = _execute_callable(context=context, **execute_callable_kwargs)
             ^^^^^^^^^^^^^^^^^^^^^^^^^^^^^^^^^^^^^^^^^^^^^^^^^^^^^^^^^^^^^
  File "/home/mohammed/venv/lib/python3.11/site-packages/airflow/models/taskinstance.py", line 734, in _execute_callable
    return ExecutionCallableRunner(
           ^^^^^^^^^^^^^^^^^^^^^^^^
  File "/home/mohammed/venv/lib/python3.11/site-packages/airflow/utils/operator_helpers.py", line 252, in run
    return self.func(*args, **kwargs)
           ^^^^^^^^^^^^^^^^^^^^^^^^^^
  File "/home/mohammed/venv/lib/python3.11/site-packages/airflow/models/baseoperator.py", line 424, in wrapper
    return func(self, *args, **kwargs)
           ^^^^^^^^^^^^^^^^^^^^^^^^^^^
  File "/home/mohammed/venv/lib/python3.11/site-packages/airflow/operators/bash.py", line 276, in execute
    raise AirflowException(
airflow.exceptions.AirflowException: Bash command failed. The command returned a non-zero exit code 1.
[2025-03-17T00:25:27.471+0000] {local_task_job_runner.py:266} INFO - Task exited with return code 1
[2025-03-17T00:25:28.219+0000] {taskinstance.py:3901} INFO - 0 downstream tasks scheduled from follow-on schedule check
[2025-03-17T00:25:28.242+0000] {local_task_job_runner.py:245} INFO - ::endgroup::
