[2025-03-28T23:05:01.971+0000] {local_task_job_runner.py:123} INFO - ::group::Pre task execution logs
[2025-03-28T23:05:02.037+0000] {taskinstance.py:2614} INFO - Dependencies all met for dep_context=non-requeueable deps ti=<TaskInstance: bank_reviews_etl_and_analysis_pipeline.dbt_run_decisionnal manual__2025-03-28T23:04:58.742177+00:00 [queued]>
[2025-03-28T23:05:02.054+0000] {taskinstance.py:2614} INFO - Dependencies all met for dep_context=requeueable deps ti=<TaskInstance: bank_reviews_etl_and_analysis_pipeline.dbt_run_decisionnal manual__2025-03-28T23:04:58.742177+00:00 [queued]>
[2025-03-28T23:05:02.055+0000] {taskinstance.py:2867} INFO - Starting attempt 1 of 2
[2025-03-28T23:05:02.089+0000] {taskinstance.py:2890} INFO - Executing <Task(BashOperator): dbt_run_decisionnal> on 2025-03-28 23:04:58.742177+00:00
[2025-03-28T23:05:02.098+0000] {standard_task_runner.py:72} INFO - Started process 596933 to run task
[2025-03-28T23:05:02.109+0000] {standard_task_runner.py:104} INFO - Running: ['airflow', 'tasks', 'run', 'bank_reviews_etl_and_analysis_pipeline', 'dbt_run_decisionnal', 'manual__2025-03-28T23:04:58.742177+00:00', '--job-id', '2487', '--raw', '--subdir', 'DAGS_FOLDER/dag_load_reviews.py', '--cfg-path', '/tmp/tmpnojayim4']
[2025-03-28T23:05:02.114+0000] {standard_task_runner.py:105} INFO - Job 2487: Subtask dbt_run_decisionnal
[2025-03-28T23:05:02.339+0000] {task_command.py:467} INFO - Running <TaskInstance: bank_reviews_etl_and_analysis_pipeline.dbt_run_decisionnal manual__2025-03-28T23:04:58.742177+00:00 [running]> on host DESKTOP-IM7V4RI.
[2025-03-28T23:05:02.668+0000] {taskinstance.py:3134} INFO - Exporting env vars: AIRFLOW_CTX_DAG_OWNER='mohammed' AIRFLOW_CTX_DAG_ID='bank_reviews_etl_and_analysis_pipeline' AIRFLOW_CTX_TASK_ID='dbt_run_decisionnal' AIRFLOW_CTX_EXECUTION_DATE='2025-03-28T23:04:58.742177+00:00' AIRFLOW_CTX_TRY_NUMBER='1' AIRFLOW_CTX_DAG_RUN_ID='manual__2025-03-28T23:04:58.742177+00:00'
[2025-03-28T23:05:02.670+0000] {logging_mixin.py:190} INFO - Task instance is in running state
[2025-03-28T23:05:02.671+0000] {logging_mixin.py:190} INFO -  Previous state of the Task instance: queued
[2025-03-28T23:05:02.671+0000] {logging_mixin.py:190} INFO - Current task name:dbt_run_decisionnal state:running start_date:2025-03-28 23:05:02.037962+00:00
[2025-03-28T23:05:02.672+0000] {logging_mixin.py:190} INFO - Dag name:bank_reviews_etl_and_analysis_pipeline and current dag run status:running
[2025-03-28T23:05:02.672+0000] {taskinstance.py:732} INFO - ::endgroup::
[2025-03-28T23:05:02.676+0000] {subprocess.py:78} INFO - Tmp dir root location: /tmp
[2025-03-28T23:05:02.679+0000] {subprocess.py:88} INFO - Running command: ['/usr/bin/bash', '-c', 'cd /home/mohammed/.dbt/dbt_projects/bank_reviews_decisionnal && dbt run']
[2025-03-28T23:05:02.707+0000] {subprocess.py:99} INFO - Output:
[2025-03-28T23:05:06.478+0000] {subprocess.py:106} INFO - [0m23:05:06  Running with dbt=1.9.3
[2025-03-28T23:05:07.091+0000] {subprocess.py:106} INFO - [0m23:05:07  Registered adapter: postgres=1.9.0
[2025-03-28T23:05:07.746+0000] {subprocess.py:106} INFO - [0m23:05:07  [[33mWARNING[0m]: Configuration paths exist in your dbt_project.yml file which do not apply to any resources.
[2025-03-28T23:05:07.747+0000] {subprocess.py:106} INFO - There are 1 unused configuration paths:
[2025-03-28T23:05:07.748+0000] {subprocess.py:106} INFO - - models.bank_reviews_decisionnal.decisionnal
[2025-03-28T23:05:10.659+0000] {subprocess.py:106} INFO - [0m23:05:10  Found 5 models, 2 sources, 547 macros
[2025-03-28T23:05:10.663+0000] {subprocess.py:106} INFO - [0m23:05:10
[2025-03-28T23:05:10.664+0000] {subprocess.py:106} INFO - [0m23:05:10  Concurrency: 4 threads (target='dev')
[2025-03-28T23:05:10.664+0000] {subprocess.py:106} INFO - [0m23:05:10
[2025-03-28T23:05:10.981+0000] {subprocess.py:106} INFO - [0m23:05:10  1 of 5 START sql table model decisionnal.dim_bank .............................. [RUN]
[2025-03-28T23:05:10.984+0000] {subprocess.py:106} INFO - [0m23:05:10  2 of 5 START sql table model decisionnal.dim_branch ............................ [RUN]
[2025-03-28T23:05:10.985+0000] {subprocess.py:106} INFO - [0m23:05:10  3 of 5 START sql table model decisionnal.dim_location .......................... [RUN]
[2025-03-28T23:05:10.987+0000] {subprocess.py:106} INFO - [0m23:05:10  4 of 5 START sql table model decisionnal.dim_sentiment ......................... [RUN]
[2025-03-28T23:05:11.759+0000] {subprocess.py:106} INFO - [0m23:05:11  2 of 5 OK created sql table model decisionnal.dim_branch ....................... [[32mSELECT 298[0m in 0.75s]
[2025-03-28T23:05:11.778+0000] {subprocess.py:106} INFO - [0m23:05:11  3 of 5 OK created sql table model decisionnal.dim_location ..................... [[32mSELECT 298[0m in 0.76s]
[2025-03-28T23:05:11.782+0000] {subprocess.py:106} INFO - [0m23:05:11  4 of 5 OK created sql table model decisionnal.dim_sentiment .................... [[32mSELECT 2591[0m in 0.77s]
[2025-03-28T23:05:11.791+0000] {subprocess.py:106} INFO - [0m23:05:11  1 of 5 OK created sql table model decisionnal.dim_bank ......................... [[32mSELECT 299[0m in 0.78s]
[2025-03-28T23:05:11.817+0000] {subprocess.py:106} INFO - [0m23:05:11  5 of 5 START sql table model decisionnal.fact_reviews .......................... [RUN]
[2025-03-28T23:05:11.931+0000] {subprocess.py:106} INFO - [0m23:05:11  5 of 5 ERROR creating sql table model decisionnal.fact_reviews ................. [[31mERROR[0m in 0.11s]
[2025-03-28T23:05:11.988+0000] {subprocess.py:106} INFO - [0m23:05:11
[2025-03-28T23:05:11.990+0000] {subprocess.py:106} INFO - [0m23:05:11  Finished running 5 table models in 0 hours 0 minutes and 1.32 seconds (1.32s).
[2025-03-28T23:05:12.070+0000] {subprocess.py:106} INFO - [0m23:05:12
[2025-03-28T23:05:12.071+0000] {subprocess.py:106} INFO - [0m23:05:12  [31mCompleted with 1 error, 0 partial successes, and 0 warnings:[0m
[2025-03-28T23:05:12.072+0000] {subprocess.py:106} INFO - [0m23:05:12
[2025-03-28T23:05:12.073+0000] {subprocess.py:106} INFO - [0m23:05:12    Database Error in model fact_reviews (models/fact_reviews.sql)
[2025-03-28T23:05:12.074+0000] {subprocess.py:106} INFO -   column cr.topics does not exist
[2025-03-28T23:05:12.074+0000] {subprocess.py:106} INFO -   LINE 23:     cr.topics,
[2025-03-28T23:05:12.074+0000] {subprocess.py:106} INFO -                ^
[2025-03-28T23:05:12.074+0000] {subprocess.py:106} INFO -   HINT:  Perhaps you meant to reference the column "cr.topic".
[2025-03-28T23:05:12.074+0000] {subprocess.py:106} INFO -   compiled code at target/run/bank_reviews_decisionnal/models/fact_reviews.sql
[2025-03-28T23:05:12.075+0000] {subprocess.py:106} INFO - [0m23:05:12
[2025-03-28T23:05:12.075+0000] {subprocess.py:106} INFO - [0m23:05:12  Done. PASS=4 WARN=0 ERROR=1 SKIP=0 TOTAL=5
[2025-03-28T23:05:13.676+0000] {subprocess.py:110} INFO - Command exited with return code 1
[2025-03-28T23:05:13.739+0000] {taskinstance.py:3313} ERROR - Task failed with exception
Traceback (most recent call last):
  File "/home/mohammed/venv/lib/python3.11/site-packages/airflow/models/taskinstance.py", line 768, in _execute_task
    result = _execute_callable(context=context, **execute_callable_kwargs)
             ^^^^^^^^^^^^^^^^^^^^^^^^^^^^^^^^^^^^^^^^^^^^^^^^^^^^^^^^^^^^^
  File "/home/mohammed/venv/lib/python3.11/site-packages/airflow/models/taskinstance.py", line 734, in _execute_callable
    return ExecutionCallableRunner(
           ^^^^^^^^^^^^^^^^^^^^^^^^
  File "/home/mohammed/venv/lib/python3.11/site-packages/airflow/utils/operator_helpers.py", line 252, in run
    return self.func(*args, **kwargs)
           ^^^^^^^^^^^^^^^^^^^^^^^^^^
  File "/home/mohammed/venv/lib/python3.11/site-packages/airflow/models/baseoperator.py", line 424, in wrapper
    return func(self, *args, **kwargs)
           ^^^^^^^^^^^^^^^^^^^^^^^^^^^
  File "/home/mohammed/venv/lib/python3.11/site-packages/airflow/operators/bash.py", line 276, in execute
    raise AirflowException(
airflow.exceptions.AirflowException: Bash command failed. The command returned a non-zero exit code 1.
[2025-03-28T23:05:13.756+0000] {logging_mixin.py:190} INFO - Task instance in failure state
[2025-03-28T23:05:13.756+0000] {logging_mixin.py:190} INFO - Task start:2025-03-28 23:05:02.037962+00:00 end:2025-03-28 23:05:13.754123+00:00 duration:11.716161
[2025-03-28T23:05:13.757+0000] {logging_mixin.py:190} INFO - Task:<Task(BashOperator): dbt_run_decisionnal> dag:<DAG: bank_reviews_etl_and_analysis_pipeline> dagrun:<DagRun bank_reviews_etl_and_analysis_pipeline @ 2025-03-28 23:04:58.742177+00:00: manual__2025-03-28T23:04:58.742177+00:00, state:running, queued_at: 2025-03-28 23:04:59.117459+00:00. externally triggered: True>
[2025-03-28T23:05:13.758+0000] {logging_mixin.py:190} INFO - Failure caused by Bash command failed. The command returned a non-zero exit code 1.
[2025-03-28T23:05:13.759+0000] {taskinstance.py:1226} INFO - Marking task as UP_FOR_RETRY. dag_id=bank_reviews_etl_and_analysis_pipeline, task_id=dbt_run_decisionnal, run_id=manual__2025-03-28T23:04:58.742177+00:00, execution_date=20250328T230458, start_date=20250328T230502, end_date=20250328T230513
[2025-03-28T23:05:13.897+0000] {taskinstance.py:341} INFO - ::group::Post task execution logs
[2025-03-28T23:05:13.898+0000] {standard_task_runner.py:124} ERROR - Failed to execute job 2487 for task dbt_run_decisionnal (Bash command failed. The command returned a non-zero exit code 1.; 596933)
Traceback (most recent call last):
  File "/home/mohammed/venv/lib/python3.11/site-packages/airflow/task/task_runner/standard_task_runner.py", line 117, in _start_by_fork
    ret = args.func(args, dag=self.dag)
          ^^^^^^^^^^^^^^^^^^^^^^^^^^^^^
  File "/home/mohammed/venv/lib/python3.11/site-packages/airflow/cli/cli_config.py", line 49, in command
    return func(*args, **kwargs)
           ^^^^^^^^^^^^^^^^^^^^^
  File "/home/mohammed/venv/lib/python3.11/site-packages/airflow/utils/cli.py", line 116, in wrapper
    return f(*args, **kwargs)
           ^^^^^^^^^^^^^^^^^^
  File "/home/mohammed/venv/lib/python3.11/site-packages/airflow/cli/commands/task_command.py", line 483, in task_run
    task_return_code = _run_task_by_selected_method(args, _dag, ti)
                       ^^^^^^^^^^^^^^^^^^^^^^^^^^^^^^^^^^^^^^^^^^^^
  File "/home/mohammed/venv/lib/python3.11/site-packages/airflow/cli/commands/task_command.py", line 256, in _run_task_by_selected_method
    return _run_raw_task(args, ti)
           ^^^^^^^^^^^^^^^^^^^^^^^
  File "/home/mohammed/venv/lib/python3.11/site-packages/airflow/cli/commands/task_command.py", line 341, in _run_raw_task
    return ti._run_raw_task(
           ^^^^^^^^^^^^^^^^^
  File "/home/mohammed/venv/lib/python3.11/site-packages/airflow/utils/session.py", line 97, in wrapper
    return func(*args, session=session, **kwargs)
           ^^^^^^^^^^^^^^^^^^^^^^^^^^^^^^^^^^^^^^
  File "/home/mohammed/venv/lib/python3.11/site-packages/airflow/models/taskinstance.py", line 3006, in _run_raw_task
    return _run_raw_task(
           ^^^^^^^^^^^^^^
  File "/home/mohammed/venv/lib/python3.11/site-packages/airflow/models/taskinstance.py", line 274, in _run_raw_task
    TaskInstance._execute_task_with_callbacks(
  File "/home/mohammed/venv/lib/python3.11/site-packages/airflow/models/taskinstance.py", line 3161, in _execute_task_with_callbacks
    result = self._execute_task(context, task_orig)
             ^^^^^^^^^^^^^^^^^^^^^^^^^^^^^^^^^^^^^^
  File "/home/mohammed/venv/lib/python3.11/site-packages/airflow/models/taskinstance.py", line 3185, in _execute_task
    return _execute_task(self, context, task_orig)
           ^^^^^^^^^^^^^^^^^^^^^^^^^^^^^^^^^^^^^^^
  File "/home/mohammed/venv/lib/python3.11/site-packages/airflow/models/taskinstance.py", line 768, in _execute_task
    result = _execute_callable(context=context, **execute_callable_kwargs)
             ^^^^^^^^^^^^^^^^^^^^^^^^^^^^^^^^^^^^^^^^^^^^^^^^^^^^^^^^^^^^^
  File "/home/mohammed/venv/lib/python3.11/site-packages/airflow/models/taskinstance.py", line 734, in _execute_callable
    return ExecutionCallableRunner(
           ^^^^^^^^^^^^^^^^^^^^^^^^
  File "/home/mohammed/venv/lib/python3.11/site-packages/airflow/utils/operator_helpers.py", line 252, in run
    return self.func(*args, **kwargs)
           ^^^^^^^^^^^^^^^^^^^^^^^^^^
  File "/home/mohammed/venv/lib/python3.11/site-packages/airflow/models/baseoperator.py", line 424, in wrapper
    return func(self, *args, **kwargs)
           ^^^^^^^^^^^^^^^^^^^^^^^^^^^
  File "/home/mohammed/venv/lib/python3.11/site-packages/airflow/operators/bash.py", line 276, in execute
    raise AirflowException(
airflow.exceptions.AirflowException: Bash command failed. The command returned a non-zero exit code 1.
[2025-03-28T23:05:13.942+0000] {local_task_job_runner.py:266} INFO - Task exited with return code 1
[2025-03-28T23:05:13.991+0000] {taskinstance.py:3901} INFO - 0 downstream tasks scheduled from follow-on schedule check
[2025-03-28T23:05:13.998+0000] {local_task_job_runner.py:245} INFO - ::endgroup::
