[2025-03-28T22:55:07.920+0000] {local_task_job_runner.py:123} INFO - ::group::Pre task execution logs
[2025-03-28T22:55:08.024+0000] {taskinstance.py:2614} INFO - Dependencies all met for dep_context=non-requeueable deps ti=<TaskInstance: bank_reviews_etl_and_analysis_pipeline.dbt_run_decisionnal scheduled__2024-09-08T00:00:00+00:00 [queued]>
[2025-03-28T22:55:08.101+0000] {taskinstance.py:2614} INFO - Dependencies all met for dep_context=requeueable deps ti=<TaskInstance: bank_reviews_etl_and_analysis_pipeline.dbt_run_decisionnal scheduled__2024-09-08T00:00:00+00:00 [queued]>
[2025-03-28T22:55:08.102+0000] {taskinstance.py:2867} INFO - Starting attempt 2 of 2
[2025-03-28T22:55:08.198+0000] {taskinstance.py:2890} INFO - Executing <Task(BashOperator): dbt_run_decisionnal> on 2024-09-08 00:00:00+00:00
[2025-03-28T22:55:08.229+0000] {standard_task_runner.py:72} INFO - Started process 587174 to run task
[2025-03-28T22:55:08.234+0000] {standard_task_runner.py:104} INFO - Running: ['airflow', 'tasks', 'run', 'bank_reviews_etl_and_analysis_pipeline', 'dbt_run_decisionnal', 'scheduled__2024-09-08T00:00:00+00:00', '--job-id', '2436', '--raw', '--subdir', 'DAGS_FOLDER/dag_load_reviews.py', '--cfg-path', '/tmp/tmpbr96v1lb']
[2025-03-28T22:55:08.261+0000] {standard_task_runner.py:105} INFO - Job 2436: Subtask dbt_run_decisionnal
[2025-03-28T22:55:08.671+0000] {task_command.py:467} INFO - Running <TaskInstance: bank_reviews_etl_and_analysis_pipeline.dbt_run_decisionnal scheduled__2024-09-08T00:00:00+00:00 [running]> on host DESKTOP-IM7V4RI.
[2025-03-28T22:55:09.215+0000] {taskinstance.py:3134} INFO - Exporting env vars: AIRFLOW_CTX_DAG_OWNER='mohammed' AIRFLOW_CTX_DAG_ID='bank_reviews_etl_and_analysis_pipeline' AIRFLOW_CTX_TASK_ID='dbt_run_decisionnal' AIRFLOW_CTX_EXECUTION_DATE='2024-09-08T00:00:00+00:00' AIRFLOW_CTX_TRY_NUMBER='2' AIRFLOW_CTX_DAG_RUN_ID='scheduled__2024-09-08T00:00:00+00:00'
[2025-03-28T22:55:09.218+0000] {logging_mixin.py:190} INFO - Task instance is in running state
[2025-03-28T22:55:09.219+0000] {logging_mixin.py:190} INFO -  Previous state of the Task instance: queued
[2025-03-28T22:55:09.220+0000] {logging_mixin.py:190} INFO - Current task name:dbt_run_decisionnal state:running start_date:2025-03-28 22:55:08.024565+00:00
[2025-03-28T22:55:09.220+0000] {logging_mixin.py:190} INFO - Dag name:bank_reviews_etl_and_analysis_pipeline and current dag run status:running
[2025-03-28T22:55:09.221+0000] {taskinstance.py:732} INFO - ::endgroup::
[2025-03-28T22:55:09.224+0000] {subprocess.py:78} INFO - Tmp dir root location: /tmp
[2025-03-28T22:55:09.235+0000] {subprocess.py:88} INFO - Running command: ['/usr/bin/bash', '-c', 'cd /home/mohammed/.dbt/dbt_projects/bank_reviews_decisionnal && dbt run']
[2025-03-28T22:55:09.329+0000] {subprocess.py:99} INFO - Output:
[2025-03-28T22:55:22.376+0000] {subprocess.py:106} INFO - [0m22:55:22  Running with dbt=1.9.3
[2025-03-28T22:55:24.572+0000] {subprocess.py:106} INFO - [0m22:55:24  Registered adapter: postgres=1.9.0
[2025-03-28T22:55:29.296+0000] {subprocess.py:106} INFO - [0m22:55:29  [[33mWARNING[0m]: Configuration paths exist in your dbt_project.yml file which do not apply to any resources.
[2025-03-28T22:55:29.297+0000] {subprocess.py:106} INFO - There are 1 unused configuration paths:
[2025-03-28T22:55:29.298+0000] {subprocess.py:106} INFO - - models.bank_reviews_decisionnal.decisionnal
[2025-03-28T22:55:30.493+0000] {subprocess.py:106} INFO - [0m22:55:30  Found 5 models, 2 sources, 547 macros
[2025-03-28T22:55:30.504+0000] {subprocess.py:106} INFO - [0m22:55:30
[2025-03-28T22:55:30.514+0000] {subprocess.py:106} INFO - [0m22:55:30  Concurrency: 4 threads (target='dev')
[2025-03-28T22:55:30.520+0000] {subprocess.py:106} INFO - [0m22:55:30
[2025-03-28T22:55:31.684+0000] {subprocess.py:106} INFO - [0m22:55:31  1 of 5 START sql table model decisionnal.dim_bank .............................. [RUN]
[2025-03-28T22:55:31.702+0000] {subprocess.py:106} INFO - [0m22:55:31  2 of 5 START sql table model decisionnal.dim_branch ............................ [RUN]
[2025-03-28T22:55:31.713+0000] {subprocess.py:106} INFO - [0m22:55:31  3 of 5 START sql table model decisionnal.dim_location .......................... [RUN]
[2025-03-28T22:55:31.718+0000] {subprocess.py:106} INFO - [0m22:55:31  4 of 5 START sql table model decisionnal.dim_sentiment ......................... [RUN]
[2025-03-28T22:55:33.445+0000] {subprocess.py:106} INFO - [0m22:55:33  3 of 5 OK created sql table model decisionnal.dim_location ..................... [[32mSELECT 298[0m in 1.70s]
[2025-03-28T22:55:33.566+0000] {subprocess.py:106} INFO - [0m22:55:33  4 of 5 OK created sql table model decisionnal.dim_sentiment .................... [[32mSELECT 2591[0m in 1.84s]
[2025-03-28T22:55:33.684+0000] {subprocess.py:106} INFO - [0m22:55:33  1 of 5 OK created sql table model decisionnal.dim_bank ......................... [[32mSELECT 299[0m in 1.99s]
[2025-03-28T22:55:33.713+0000] {subprocess.py:106} INFO - [0m22:55:33  2 of 5 OK created sql table model decisionnal.dim_branch ....................... [[32mSELECT 298[0m in 1.99s]
[2025-03-28T22:55:33.729+0000] {subprocess.py:106} INFO - [0m22:55:33  5 of 5 START sql table model decisionnal.fact_reviews .......................... [RUN]
[2025-03-28T22:55:33.974+0000] {subprocess.py:106} INFO - [0m22:55:33  5 of 5 ERROR creating sql table model decisionnal.fact_reviews ................. [[31mERROR[0m in 0.25s]
[2025-03-28T22:55:34.105+0000] {subprocess.py:106} INFO - [0m22:55:34
[2025-03-28T22:55:34.117+0000] {subprocess.py:106} INFO - [0m22:55:34  Finished running 5 table models in 0 hours 0 minutes and 3.58 seconds (3.58s).
[2025-03-28T22:55:34.449+0000] {subprocess.py:106} INFO - [0m22:55:34
[2025-03-28T22:55:34.455+0000] {subprocess.py:106} INFO - [0m22:55:34  [31mCompleted with 1 error, 0 partial successes, and 0 warnings:[0m
[2025-03-28T22:55:34.458+0000] {subprocess.py:106} INFO - [0m22:55:34
[2025-03-28T22:55:34.461+0000] {subprocess.py:106} INFO - [0m22:55:34    Database Error in model fact_reviews (models/fact_reviews.sql)
[2025-03-28T22:55:34.463+0000] {subprocess.py:106} INFO -   column cr.topics does not exist
[2025-03-28T22:55:34.463+0000] {subprocess.py:106} INFO -   LINE 24:     cr.topics,
[2025-03-28T22:55:34.464+0000] {subprocess.py:106} INFO -                ^
[2025-03-28T22:55:34.464+0000] {subprocess.py:106} INFO -   HINT:  Perhaps you meant to reference the column "cr.topic".
[2025-03-28T22:55:34.465+0000] {subprocess.py:106} INFO -   compiled code at target/run/bank_reviews_decisionnal/models/fact_reviews.sql
[2025-03-28T22:55:34.469+0000] {subprocess.py:106} INFO - [0m22:55:34
[2025-03-28T22:55:34.472+0000] {subprocess.py:106} INFO - [0m22:55:34  Done. PASS=4 WARN=0 ERROR=1 SKIP=0 TOTAL=5
[2025-03-28T22:55:40.527+0000] {subprocess.py:110} INFO - Command exited with return code 1
[2025-03-28T22:55:41.238+0000] {taskinstance.py:3313} ERROR - Task failed with exception
Traceback (most recent call last):
  File "/home/mohammed/venv/lib/python3.11/site-packages/airflow/models/taskinstance.py", line 768, in _execute_task
    result = _execute_callable(context=context, **execute_callable_kwargs)
             ^^^^^^^^^^^^^^^^^^^^^^^^^^^^^^^^^^^^^^^^^^^^^^^^^^^^^^^^^^^^^
  File "/home/mohammed/venv/lib/python3.11/site-packages/airflow/models/taskinstance.py", line 734, in _execute_callable
    return ExecutionCallableRunner(
           ^^^^^^^^^^^^^^^^^^^^^^^^
  File "/home/mohammed/venv/lib/python3.11/site-packages/airflow/utils/operator_helpers.py", line 252, in run
    return self.func(*args, **kwargs)
           ^^^^^^^^^^^^^^^^^^^^^^^^^^
  File "/home/mohammed/venv/lib/python3.11/site-packages/airflow/models/baseoperator.py", line 424, in wrapper
    return func(self, *args, **kwargs)
           ^^^^^^^^^^^^^^^^^^^^^^^^^^^
  File "/home/mohammed/venv/lib/python3.11/site-packages/airflow/operators/bash.py", line 276, in execute
    raise AirflowException(
airflow.exceptions.AirflowException: Bash command failed. The command returned a non-zero exit code 1.
[2025-03-28T22:55:41.345+0000] {logging_mixin.py:190} INFO - Task instance in failure state
[2025-03-28T22:55:41.346+0000] {logging_mixin.py:190} INFO - Task start:2025-03-28 22:55:08.024565+00:00 end:2025-03-28 22:55:41.334763+00:00 duration:33.310198
[2025-03-28T22:55:41.346+0000] {logging_mixin.py:190} INFO - Task:<Task(BashOperator): dbt_run_decisionnal> dag:<DAG: bank_reviews_etl_and_analysis_pipeline> dagrun:<DagRun bank_reviews_etl_and_analysis_pipeline @ 2024-09-08 00:00:00+00:00: scheduled__2024-09-08T00:00:00+00:00, state:running, queued_at: 2025-03-28 22:49:31.826881+00:00. externally triggered: False>
[2025-03-28T22:55:41.347+0000] {logging_mixin.py:190} INFO - Failure caused by Bash command failed. The command returned a non-zero exit code 1.
[2025-03-28T22:55:41.348+0000] {taskinstance.py:1226} INFO - Marking task as FAILED. dag_id=bank_reviews_etl_and_analysis_pipeline, task_id=dbt_run_decisionnal, run_id=scheduled__2024-09-08T00:00:00+00:00, execution_date=20240908T000000, start_date=20250328T225508, end_date=20250328T225541
[2025-03-28T22:55:42.024+0000] {taskinstance.py:341} INFO - ::group::Post task execution logs
[2025-03-28T22:55:42.038+0000] {standard_task_runner.py:124} ERROR - Failed to execute job 2436 for task dbt_run_decisionnal (Bash command failed. The command returned a non-zero exit code 1.; 587174)
Traceback (most recent call last):
  File "/home/mohammed/venv/lib/python3.11/site-packages/airflow/task/task_runner/standard_task_runner.py", line 117, in _start_by_fork
    ret = args.func(args, dag=self.dag)
          ^^^^^^^^^^^^^^^^^^^^^^^^^^^^^
  File "/home/mohammed/venv/lib/python3.11/site-packages/airflow/cli/cli_config.py", line 49, in command
    return func(*args, **kwargs)
           ^^^^^^^^^^^^^^^^^^^^^
  File "/home/mohammed/venv/lib/python3.11/site-packages/airflow/utils/cli.py", line 116, in wrapper
    return f(*args, **kwargs)
           ^^^^^^^^^^^^^^^^^^
  File "/home/mohammed/venv/lib/python3.11/site-packages/airflow/cli/commands/task_command.py", line 483, in task_run
    task_return_code = _run_task_by_selected_method(args, _dag, ti)
                       ^^^^^^^^^^^^^^^^^^^^^^^^^^^^^^^^^^^^^^^^^^^^
  File "/home/mohammed/venv/lib/python3.11/site-packages/airflow/cli/commands/task_command.py", line 256, in _run_task_by_selected_method
    return _run_raw_task(args, ti)
           ^^^^^^^^^^^^^^^^^^^^^^^
  File "/home/mohammed/venv/lib/python3.11/site-packages/airflow/cli/commands/task_command.py", line 341, in _run_raw_task
    return ti._run_raw_task(
           ^^^^^^^^^^^^^^^^^
  File "/home/mohammed/venv/lib/python3.11/site-packages/airflow/utils/session.py", line 97, in wrapper
    return func(*args, session=session, **kwargs)
           ^^^^^^^^^^^^^^^^^^^^^^^^^^^^^^^^^^^^^^
  File "/home/mohammed/venv/lib/python3.11/site-packages/airflow/models/taskinstance.py", line 3006, in _run_raw_task
    return _run_raw_task(
           ^^^^^^^^^^^^^^
  File "/home/mohammed/venv/lib/python3.11/site-packages/airflow/models/taskinstance.py", line 274, in _run_raw_task
    TaskInstance._execute_task_with_callbacks(
  File "/home/mohammed/venv/lib/python3.11/site-packages/airflow/models/taskinstance.py", line 3161, in _execute_task_with_callbacks
    result = self._execute_task(context, task_orig)
             ^^^^^^^^^^^^^^^^^^^^^^^^^^^^^^^^^^^^^^
  File "/home/mohammed/venv/lib/python3.11/site-packages/airflow/models/taskinstance.py", line 3185, in _execute_task
    return _execute_task(self, context, task_orig)
           ^^^^^^^^^^^^^^^^^^^^^^^^^^^^^^^^^^^^^^^
  File "/home/mohammed/venv/lib/python3.11/site-packages/airflow/models/taskinstance.py", line 768, in _execute_task
    result = _execute_callable(context=context, **execute_callable_kwargs)
             ^^^^^^^^^^^^^^^^^^^^^^^^^^^^^^^^^^^^^^^^^^^^^^^^^^^^^^^^^^^^^
  File "/home/mohammed/venv/lib/python3.11/site-packages/airflow/models/taskinstance.py", line 734, in _execute_callable
    return ExecutionCallableRunner(
           ^^^^^^^^^^^^^^^^^^^^^^^^
  File "/home/mohammed/venv/lib/python3.11/site-packages/airflow/utils/operator_helpers.py", line 252, in run
    return self.func(*args, **kwargs)
           ^^^^^^^^^^^^^^^^^^^^^^^^^^
  File "/home/mohammed/venv/lib/python3.11/site-packages/airflow/models/baseoperator.py", line 424, in wrapper
    return func(self, *args, **kwargs)
           ^^^^^^^^^^^^^^^^^^^^^^^^^^^
  File "/home/mohammed/venv/lib/python3.11/site-packages/airflow/operators/bash.py", line 276, in execute
    raise AirflowException(
airflow.exceptions.AirflowException: Bash command failed. The command returned a non-zero exit code 1.
[2025-03-28T22:55:42.138+0000] {local_task_job_runner.py:266} INFO - Task exited with return code 1
[2025-03-28T22:55:42.226+0000] {taskinstance.py:3901} INFO - 0 downstream tasks scheduled from follow-on schedule check
[2025-03-28T22:55:42.360+0000] {local_task_job_runner.py:245} INFO - ::endgroup::
