[2025-03-17T01:01:12.079+0000] {local_task_job_runner.py:123} INFO - ::group::Pre task execution logs
[2025-03-17T01:01:12.128+0000] {taskinstance.py:2614} INFO - Dependencies all met for dep_context=non-requeueable deps ti=<TaskInstance: load_reviews_pipeline.dbt_run scheduled__2024-10-11T00:00:00+00:00 [queued]>
[2025-03-17T01:01:12.140+0000] {taskinstance.py:2614} INFO - Dependencies all met for dep_context=requeueable deps ti=<TaskInstance: load_reviews_pipeline.dbt_run scheduled__2024-10-11T00:00:00+00:00 [queued]>
[2025-03-17T01:01:12.141+0000] {taskinstance.py:2867} INFO - Starting attempt 1 of 2
[2025-03-17T01:01:12.173+0000] {taskinstance.py:2890} INFO - Executing <Task(BashOperator): dbt_run> on 2024-10-11 00:00:00+00:00
[2025-03-17T01:01:12.184+0000] {standard_task_runner.py:72} INFO - Started process 302820 to run task
[2025-03-17T01:01:12.192+0000] {standard_task_runner.py:104} INFO - Running: ['airflow', 'tasks', 'run', 'load_reviews_pipeline', 'dbt_run', 'scheduled__2024-10-11T00:00:00+00:00', '--job-id', '453', '--raw', '--subdir', 'DAGS_FOLDER/dag_load_reviews.py', '--cfg-path', '/tmp/tmprtw0jw2f']
[2025-03-17T01:01:12.194+0000] {standard_task_runner.py:105} INFO - Job 453: Subtask dbt_run
[2025-03-17T01:01:12.337+0000] {task_command.py:467} INFO - Running <TaskInstance: load_reviews_pipeline.dbt_run scheduled__2024-10-11T00:00:00+00:00 [running]> on host DESKTOP-IM7V4RI.
[2025-03-17T01:01:12.594+0000] {taskinstance.py:3134} INFO - Exporting env vars: AIRFLOW_CTX_DAG_OWNER='mohammed' AIRFLOW_CTX_DAG_ID='load_reviews_pipeline' AIRFLOW_CTX_TASK_ID='dbt_run' AIRFLOW_CTX_EXECUTION_DATE='2024-10-11T00:00:00+00:00' AIRFLOW_CTX_TRY_NUMBER='1' AIRFLOW_CTX_DAG_RUN_ID='scheduled__2024-10-11T00:00:00+00:00'
[2025-03-17T01:01:12.595+0000] {logging_mixin.py:190} INFO - Task instance is in running state
[2025-03-17T01:01:12.596+0000] {logging_mixin.py:190} INFO -  Previous state of the Task instance: queued
[2025-03-17T01:01:12.596+0000] {logging_mixin.py:190} INFO - Current task name:dbt_run state:running start_date:2025-03-17 01:01:12.128900+00:00
[2025-03-17T01:01:12.596+0000] {logging_mixin.py:190} INFO - Dag name:load_reviews_pipeline and current dag run status:running
[2025-03-17T01:01:12.596+0000] {taskinstance.py:732} INFO - ::endgroup::
[2025-03-17T01:01:12.597+0000] {subprocess.py:78} INFO - Tmp dir root location: /tmp
[2025-03-17T01:01:12.599+0000] {subprocess.py:88} INFO - Running command: ['/usr/bin/bash', '-c', 'cd /home/mohammed/.dbt/bank_reviews_project && dbt run']
[2025-03-17T01:01:12.616+0000] {subprocess.py:99} INFO - Output:
[2025-03-17T01:01:16.336+0000] {subprocess.py:106} INFO - [0m01:01:16  Running with dbt=1.9.3
[2025-03-17T01:01:17.095+0000] {subprocess.py:106} INFO - [0m01:01:17  Registered adapter: postgres=1.9.0
[2025-03-17T01:01:18.361+0000] {subprocess.py:106} INFO - [0m01:01:18  Found 10 models, 4 data tests, 2 sources, 433 macros
[2025-03-17T01:01:18.375+0000] {subprocess.py:106} INFO - [0m01:01:18
[2025-03-17T01:01:18.377+0000] {subprocess.py:106} INFO - [0m01:01:18  Concurrency: 4 threads (target='dev')
[2025-03-17T01:01:18.379+0000] {subprocess.py:106} INFO - [0m01:01:18
[2025-03-17T01:01:18.766+0000] {subprocess.py:106} INFO - [0m01:01:18  1 of 10 START sql view model public.clean_reviews .............................. [RUN]
[2025-03-17T01:01:18.792+0000] {subprocess.py:106} INFO - [0m01:01:18  2 of 10 START sql table model public.my_first_dbt_model ........................ [RUN]
[2025-03-17T01:01:18.794+0000] {subprocess.py:106} INFO - [0m01:01:18  3 of 10 START sql view model public.remove_duplicates .......................... [RUN]
[2025-03-17T01:01:18.797+0000] {subprocess.py:106} INFO - [0m01:01:18  4 of 10 START sql view model public.stg_clean_reviews .......................... [RUN]
[2025-03-17T01:01:18.363+0000] {subprocess.py:106} INFO - [0m01:01:18  2 of 10 ERROR creating sql table model public.my_first_dbt_model ............... [[31mERROR[0m in -0.45s]
[2025-03-17T01:01:18.364+0000] {subprocess.py:106} INFO - [0m01:01:18  1 of 10 ERROR creating sql view model public.clean_reviews ..................... [[31mERROR[0m in -0.41s]
[2025-03-17T01:01:18.367+0000] {subprocess.py:106} INFO - [0m01:01:18  3 of 10 ERROR creating sql view model public.remove_duplicates ................. [[31mERROR[0m in -0.44s]
[2025-03-17T01:01:18.372+0000] {subprocess.py:106} INFO - [0m01:01:18  4 of 10 ERROR creating sql view model public.stg_clean_reviews ................. [[31mERROR[0m in -0.46s]
[2025-03-17T01:01:18.382+0000] {subprocess.py:106} INFO - [0m01:01:18  5 of 10 SKIP relation public.my_second_dbt_model ............................... [[33mSKIP[0m]
[2025-03-17T01:01:18.392+0000] {subprocess.py:106} INFO - [0m01:01:18  6 of 10 SKIP relation public.dim_bank .......................................... [[33mSKIP[0m]
[2025-03-17T01:01:18.395+0000] {subprocess.py:106} INFO - [0m01:01:18  7 of 10 SKIP relation public.dim_branch ........................................ [[33mSKIP[0m]
[2025-03-17T01:01:18.396+0000] {subprocess.py:106} INFO - [0m01:01:18  8 of 10 SKIP relation public.dim_location ...................................... [[33mSKIP[0m]
[2025-03-17T01:01:18.398+0000] {subprocess.py:106} INFO - [0m01:01:18  9 of 10 SKIP relation public.dim_sentiment ..................................... [[33mSKIP[0m]
[2025-03-17T01:01:18.406+0000] {subprocess.py:106} INFO - [0m01:01:18  10 of 10 SKIP relation public.fact_reviews ..................................... [[33mSKIP[0m]
[2025-03-17T01:01:18.440+0000] {subprocess.py:106} INFO - [0m01:01:18
[2025-03-17T01:01:18.441+0000] {subprocess.py:106} INFO - [0m01:01:18  Finished running 1 table model, 9 view models in 0 hours 0 minutes and 0.06 seconds (0.06s).
[2025-03-17T01:01:18.614+0000] {subprocess.py:106} INFO - [0m01:01:18
[2025-03-17T01:01:18.615+0000] {subprocess.py:106} INFO - [0m01:01:18  [31mCompleted with 4 errors, 0 partial successes, and 0 warnings:[0m
[2025-03-17T01:01:18.616+0000] {subprocess.py:106} INFO - [0m01:01:18
[2025-03-17T01:01:18.617+0000] {subprocess.py:106} INFO - [0m01:01:18    Database Error in model my_first_dbt_model (models/example/my_first_dbt_model.sql)
[2025-03-17T01:01:18.617+0000] {subprocess.py:106} INFO -   relation "my_first_dbt_model__dbt_backup" already exists
[2025-03-17T01:01:18.617+0000] {subprocess.py:106} INFO -   compiled code at target/run/bank_reviews_project/models/example/my_first_dbt_model.sql
[2025-03-17T01:01:18.618+0000] {subprocess.py:106} INFO - [0m01:01:18
[2025-03-17T01:01:18.618+0000] {subprocess.py:106} INFO - [0m01:01:18    Database Error in model remove_duplicates (models/remove_duplicates.sql)
[2025-03-17T01:01:18.619+0000] {subprocess.py:106} INFO -   relation "remove_duplicates__dbt_backup" already exists
[2025-03-17T01:01:18.619+0000] {subprocess.py:106} INFO -   compiled code at target/run/bank_reviews_project/models/remove_duplicates.sql
[2025-03-17T01:01:18.619+0000] {subprocess.py:106} INFO - [0m01:01:18
[2025-03-17T01:01:18.620+0000] {subprocess.py:106} INFO - [0m01:01:18    Database Error in model clean_reviews (models/clean_reviews.sql)
[2025-03-17T01:01:18.620+0000] {subprocess.py:106} INFO -   relation "clean_reviews__dbt_backup" already exists
[2025-03-17T01:01:18.620+0000] {subprocess.py:106} INFO -   compiled code at target/run/bank_reviews_project/models/clean_reviews.sql
[2025-03-17T01:01:18.621+0000] {subprocess.py:106} INFO - [0m01:01:18
[2025-03-17T01:01:18.621+0000] {subprocess.py:106} INFO - [0m01:01:18    Database Error in model stg_clean_reviews (models/stg_clean_reviews.sql)
[2025-03-17T01:01:18.621+0000] {subprocess.py:106} INFO -   relation "stg_clean_reviews__dbt_backup" already exists
[2025-03-17T01:01:18.621+0000] {subprocess.py:106} INFO -   compiled code at target/run/bank_reviews_project/models/stg_clean_reviews.sql
[2025-03-17T01:01:18.622+0000] {subprocess.py:106} INFO - [0m01:01:18
[2025-03-17T01:01:18.622+0000] {subprocess.py:106} INFO - [0m01:01:18  Done. PASS=0 WARN=0 ERROR=4 SKIP=6 TOTAL=10
[2025-03-17T01:01:20.653+0000] {subprocess.py:110} INFO - Command exited with return code 1
[2025-03-17T01:01:20.692+0000] {taskinstance.py:3313} ERROR - Task failed with exception
Traceback (most recent call last):
  File "/home/mohammed/venv/lib/python3.11/site-packages/airflow/models/taskinstance.py", line 768, in _execute_task
    result = _execute_callable(context=context, **execute_callable_kwargs)
             ^^^^^^^^^^^^^^^^^^^^^^^^^^^^^^^^^^^^^^^^^^^^^^^^^^^^^^^^^^^^^
  File "/home/mohammed/venv/lib/python3.11/site-packages/airflow/models/taskinstance.py", line 734, in _execute_callable
    return ExecutionCallableRunner(
           ^^^^^^^^^^^^^^^^^^^^^^^^
  File "/home/mohammed/venv/lib/python3.11/site-packages/airflow/utils/operator_helpers.py", line 252, in run
    return self.func(*args, **kwargs)
           ^^^^^^^^^^^^^^^^^^^^^^^^^^
  File "/home/mohammed/venv/lib/python3.11/site-packages/airflow/models/baseoperator.py", line 424, in wrapper
    return func(self, *args, **kwargs)
           ^^^^^^^^^^^^^^^^^^^^^^^^^^^
  File "/home/mohammed/venv/lib/python3.11/site-packages/airflow/operators/bash.py", line 276, in execute
    raise AirflowException(
airflow.exceptions.AirflowException: Bash command failed. The command returned a non-zero exit code 1.
[2025-03-17T01:01:20.705+0000] {logging_mixin.py:190} INFO - Task instance in failure state
[2025-03-17T01:01:20.706+0000] {logging_mixin.py:190} INFO - Task start:2025-03-17 01:01:12.128900+00:00 end:2025-03-17 01:01:20.704080+00:00 duration:8.57518
[2025-03-17T01:01:20.706+0000] {logging_mixin.py:190} INFO - Task:<Task(BashOperator): dbt_run> dag:<DAG: load_reviews_pipeline> dagrun:<DagRun load_reviews_pipeline @ 2024-10-11 00:00:00+00:00: scheduled__2024-10-11T00:00:00+00:00, state:running, queued_at: 2025-03-17 01:01:10.380761+00:00. externally triggered: False>
[2025-03-17T01:01:20.706+0000] {logging_mixin.py:190} INFO - Failure caused by Bash command failed. The command returned a non-zero exit code 1.
[2025-03-17T01:01:20.706+0000] {taskinstance.py:1226} INFO - Marking task as UP_FOR_RETRY. dag_id=load_reviews_pipeline, task_id=dbt_run, run_id=scheduled__2024-10-11T00:00:00+00:00, execution_date=20241011T000000, start_date=20250317T010112, end_date=20250317T010120
[2025-03-17T01:01:20.971+0000] {taskinstance.py:341} INFO - ::group::Post task execution logs
[2025-03-17T01:01:20.972+0000] {standard_task_runner.py:124} ERROR - Failed to execute job 453 for task dbt_run (Bash command failed. The command returned a non-zero exit code 1.; 302820)
Traceback (most recent call last):
  File "/home/mohammed/venv/lib/python3.11/site-packages/airflow/task/task_runner/standard_task_runner.py", line 117, in _start_by_fork
    ret = args.func(args, dag=self.dag)
          ^^^^^^^^^^^^^^^^^^^^^^^^^^^^^
  File "/home/mohammed/venv/lib/python3.11/site-packages/airflow/cli/cli_config.py", line 49, in command
    return func(*args, **kwargs)
           ^^^^^^^^^^^^^^^^^^^^^
  File "/home/mohammed/venv/lib/python3.11/site-packages/airflow/utils/cli.py", line 116, in wrapper
    return f(*args, **kwargs)
           ^^^^^^^^^^^^^^^^^^
  File "/home/mohammed/venv/lib/python3.11/site-packages/airflow/cli/commands/task_command.py", line 483, in task_run
    task_return_code = _run_task_by_selected_method(args, _dag, ti)
                       ^^^^^^^^^^^^^^^^^^^^^^^^^^^^^^^^^^^^^^^^^^^^
  File "/home/mohammed/venv/lib/python3.11/site-packages/airflow/cli/commands/task_command.py", line 256, in _run_task_by_selected_method
    return _run_raw_task(args, ti)
           ^^^^^^^^^^^^^^^^^^^^^^^
  File "/home/mohammed/venv/lib/python3.11/site-packages/airflow/cli/commands/task_command.py", line 341, in _run_raw_task
    return ti._run_raw_task(
           ^^^^^^^^^^^^^^^^^
  File "/home/mohammed/venv/lib/python3.11/site-packages/airflow/utils/session.py", line 97, in wrapper
    return func(*args, session=session, **kwargs)
           ^^^^^^^^^^^^^^^^^^^^^^^^^^^^^^^^^^^^^^
  File "/home/mohammed/venv/lib/python3.11/site-packages/airflow/models/taskinstance.py", line 3006, in _run_raw_task
    return _run_raw_task(
           ^^^^^^^^^^^^^^
  File "/home/mohammed/venv/lib/python3.11/site-packages/airflow/models/taskinstance.py", line 274, in _run_raw_task
    TaskInstance._execute_task_with_callbacks(
  File "/home/mohammed/venv/lib/python3.11/site-packages/airflow/models/taskinstance.py", line 3161, in _execute_task_with_callbacks
    result = self._execute_task(context, task_orig)
             ^^^^^^^^^^^^^^^^^^^^^^^^^^^^^^^^^^^^^^
  File "/home/mohammed/venv/lib/python3.11/site-packages/airflow/models/taskinstance.py", line 3185, in _execute_task
    return _execute_task(self, context, task_orig)
           ^^^^^^^^^^^^^^^^^^^^^^^^^^^^^^^^^^^^^^^
  File "/home/mohammed/venv/lib/python3.11/site-packages/airflow/models/taskinstance.py", line 768, in _execute_task
    result = _execute_callable(context=context, **execute_callable_kwargs)
             ^^^^^^^^^^^^^^^^^^^^^^^^^^^^^^^^^^^^^^^^^^^^^^^^^^^^^^^^^^^^^
  File "/home/mohammed/venv/lib/python3.11/site-packages/airflow/models/taskinstance.py", line 734, in _execute_callable
    return ExecutionCallableRunner(
           ^^^^^^^^^^^^^^^^^^^^^^^^
  File "/home/mohammed/venv/lib/python3.11/site-packages/airflow/utils/operator_helpers.py", line 252, in run
    return self.func(*args, **kwargs)
           ^^^^^^^^^^^^^^^^^^^^^^^^^^
  File "/home/mohammed/venv/lib/python3.11/site-packages/airflow/models/baseoperator.py", line 424, in wrapper
    return func(self, *args, **kwargs)
           ^^^^^^^^^^^^^^^^^^^^^^^^^^^
  File "/home/mohammed/venv/lib/python3.11/site-packages/airflow/operators/bash.py", line 276, in execute
    raise AirflowException(
airflow.exceptions.AirflowException: Bash command failed. The command returned a non-zero exit code 1.
[2025-03-17T01:01:20.995+0000] {local_task_job_runner.py:266} INFO - Task exited with return code 1
[2025-03-17T01:01:21.036+0000] {taskinstance.py:3901} INFO - 0 downstream tasks scheduled from follow-on schedule check
[2025-03-17T01:01:21.045+0000] {local_task_job_runner.py:245} INFO - ::endgroup::
