[2025-03-28T22:55:11.849+0000] {local_task_job_runner.py:123} INFO - ::group::Pre task execution logs
[2025-03-28T22:55:11.946+0000] {taskinstance.py:2614} INFO - Dependencies all met for dep_context=non-requeueable deps ti=<TaskInstance: bank_reviews_etl_and_analysis_pipeline.dbt_run_decisionnal scheduled__2024-09-22T00:00:00+00:00 [queued]>
[2025-03-28T22:55:11.987+0000] {taskinstance.py:2614} INFO - Dependencies all met for dep_context=requeueable deps ti=<TaskInstance: bank_reviews_etl_and_analysis_pipeline.dbt_run_decisionnal scheduled__2024-09-22T00:00:00+00:00 [queued]>
[2025-03-28T22:55:11.990+0000] {taskinstance.py:2867} INFO - Starting attempt 2 of 2
[2025-03-28T22:55:12.164+0000] {taskinstance.py:2890} INFO - Executing <Task(BashOperator): dbt_run_decisionnal> on 2024-09-22 00:00:00+00:00
[2025-03-28T22:55:12.345+0000] {standard_task_runner.py:72} INFO - Started process 587300 to run task
[2025-03-28T22:55:12.354+0000] {standard_task_runner.py:104} INFO - Running: ['airflow', 'tasks', 'run', 'bank_reviews_etl_and_analysis_pipeline', 'dbt_run_decisionnal', 'scheduled__2024-09-22T00:00:00+00:00', '--job-id', '2442', '--raw', '--subdir', 'DAGS_FOLDER/dag_load_reviews.py', '--cfg-path', '/tmp/tmpf1isdce2']
[2025-03-28T22:55:12.356+0000] {standard_task_runner.py:105} INFO - Job 2442: Subtask dbt_run_decisionnal
[2025-03-28T22:55:13.137+0000] {task_command.py:467} INFO - Running <TaskInstance: bank_reviews_etl_and_analysis_pipeline.dbt_run_decisionnal scheduled__2024-09-22T00:00:00+00:00 [running]> on host DESKTOP-IM7V4RI.
[2025-03-28T22:55:14.375+0000] {taskinstance.py:3134} INFO - Exporting env vars: AIRFLOW_CTX_DAG_OWNER='mohammed' AIRFLOW_CTX_DAG_ID='bank_reviews_etl_and_analysis_pipeline' AIRFLOW_CTX_TASK_ID='dbt_run_decisionnal' AIRFLOW_CTX_EXECUTION_DATE='2024-09-22T00:00:00+00:00' AIRFLOW_CTX_TRY_NUMBER='2' AIRFLOW_CTX_DAG_RUN_ID='scheduled__2024-09-22T00:00:00+00:00'
[2025-03-28T22:55:14.380+0000] {logging_mixin.py:190} INFO - Task instance is in running state
[2025-03-28T22:55:14.381+0000] {logging_mixin.py:190} INFO -  Previous state of the Task instance: queued
[2025-03-28T22:55:14.382+0000] {logging_mixin.py:190} INFO - Current task name:dbt_run_decisionnal state:running start_date:2025-03-28 22:55:11.947241+00:00
[2025-03-28T22:55:14.382+0000] {logging_mixin.py:190} INFO - Dag name:bank_reviews_etl_and_analysis_pipeline and current dag run status:running
[2025-03-28T22:55:14.383+0000] {taskinstance.py:732} INFO - ::endgroup::
[2025-03-28T22:55:14.384+0000] {subprocess.py:78} INFO - Tmp dir root location: /tmp
[2025-03-28T22:55:14.401+0000] {subprocess.py:88} INFO - Running command: ['/usr/bin/bash', '-c', 'cd /home/mohammed/.dbt/dbt_projects/bank_reviews_decisionnal && dbt run']
[2025-03-28T22:55:14.460+0000] {subprocess.py:99} INFO - Output:
[2025-03-28T22:55:28.018+0000] {subprocess.py:106} INFO - [0m22:55:28  Running with dbt=1.9.3
[2025-03-28T22:55:30.161+0000] {subprocess.py:106} INFO - [0m22:55:30  Registered adapter: postgres=1.9.0
[2025-03-28T22:55:31.924+0000] {subprocess.py:106} INFO - [0m22:55:31  [[33mWARNING[0m]: Configuration paths exist in your dbt_project.yml file which do not apply to any resources.
[2025-03-28T22:55:31.924+0000] {subprocess.py:106} INFO - There are 1 unused configuration paths:
[2025-03-28T22:55:31.925+0000] {subprocess.py:106} INFO - - models.bank_reviews_decisionnal.decisionnal
[2025-03-28T22:55:32.863+0000] {subprocess.py:106} INFO - [0m22:55:32  Found 5 models, 2 sources, 547 macros
[2025-03-28T22:55:32.869+0000] {subprocess.py:106} INFO - [0m22:55:32
[2025-03-28T22:55:32.871+0000] {subprocess.py:106} INFO - [0m22:55:32  Concurrency: 4 threads (target='dev')
[2025-03-28T22:55:32.889+0000] {subprocess.py:106} INFO - [0m22:55:32
[2025-03-28T22:55:33.849+0000] {subprocess.py:106} INFO - [0m22:55:33  1 of 5 START sql table model decisionnal.dim_bank .............................. [RUN]
[2025-03-28T22:55:33.871+0000] {subprocess.py:106} INFO - [0m22:55:33  2 of 5 START sql table model decisionnal.dim_branch ............................ [RUN]
[2025-03-28T22:55:33.871+0000] {subprocess.py:106} INFO - [0m22:55:33  3 of 5 START sql table model decisionnal.dim_location .......................... [RUN]
[2025-03-28T22:55:33.880+0000] {subprocess.py:106} INFO - [0m22:55:33  4 of 5 START sql table model decisionnal.dim_sentiment ......................... [RUN]
[2025-03-28T22:55:38.095+0000] {subprocess.py:106} INFO - [0m22:55:38  2 of 5 ERROR creating sql table model decisionnal.dim_branch ................... [[31mERROR[0m in 4.22s]
[2025-03-28T22:55:38.846+0000] {subprocess.py:106} INFO - [0m22:55:38  4 of 5 OK created sql table model decisionnal.dim_sentiment .................... [[32mSELECT 2591[0m in 4.96s]
[2025-03-28T22:55:38.867+0000] {subprocess.py:106} INFO - [0m22:55:38  1 of 5 ERROR creating sql table model decisionnal.dim_bank ..................... [[31mERROR[0m in 5.01s]
[2025-03-28T22:55:39.462+0000] {subprocess.py:106} INFO - [0m22:55:39  3 of 5 OK created sql table model decisionnal.dim_location ..................... [[32mSELECT 298[0m in 5.58s]
[2025-03-28T22:55:39.472+0000] {subprocess.py:106} INFO - [0m22:55:39  5 of 5 SKIP relation decisionnal.fact_reviews .................................. [[33mSKIP[0m]
[2025-03-28T22:55:39.575+0000] {subprocess.py:106} INFO - [0m22:55:39
[2025-03-28T22:55:39.577+0000] {subprocess.py:106} INFO - [0m22:55:39  Finished running 5 table models in 0 hours 0 minutes and 6.68 seconds (6.68s).
[2025-03-28T22:55:39.753+0000] {subprocess.py:106} INFO - [0m22:55:39
[2025-03-28T22:55:39.760+0000] {subprocess.py:106} INFO - [0m22:55:39  [31mCompleted with 2 errors, 0 partial successes, and 0 warnings:[0m
[2025-03-28T22:55:39.762+0000] {subprocess.py:106} INFO - [0m22:55:39
[2025-03-28T22:55:39.764+0000] {subprocess.py:106} INFO - [0m22:55:39    Database Error in model dim_branch (models/dim_branch.sql)
[2025-03-28T22:55:39.765+0000] {subprocess.py:106} INFO -   relation "dim_branch__dbt_backup" already exists
[2025-03-28T22:55:39.766+0000] {subprocess.py:106} INFO -   compiled code at target/run/bank_reviews_decisionnal/models/dim_branch.sql
[2025-03-28T22:55:39.768+0000] {subprocess.py:106} INFO - [0m22:55:39
[2025-03-28T22:55:39.773+0000] {subprocess.py:106} INFO - [0m22:55:39    Database Error in model dim_bank (models/dim_bank.sql)
[2025-03-28T22:55:39.774+0000] {subprocess.py:106} INFO -   relation "dim_bank__dbt_backup" already exists
[2025-03-28T22:55:39.774+0000] {subprocess.py:106} INFO -   compiled code at target/run/bank_reviews_decisionnal/models/dim_bank.sql
[2025-03-28T22:55:39.776+0000] {subprocess.py:106} INFO - [0m22:55:39
[2025-03-28T22:55:39.778+0000] {subprocess.py:106} INFO - [0m22:55:39  Done. PASS=2 WARN=0 ERROR=2 SKIP=1 TOTAL=5
[2025-03-28T22:55:41.314+0000] {subprocess.py:110} INFO - Command exited with return code 1
[2025-03-28T22:55:41.444+0000] {taskinstance.py:3313} ERROR - Task failed with exception
Traceback (most recent call last):
  File "/home/mohammed/venv/lib/python3.11/site-packages/airflow/models/taskinstance.py", line 768, in _execute_task
    result = _execute_callable(context=context, **execute_callable_kwargs)
             ^^^^^^^^^^^^^^^^^^^^^^^^^^^^^^^^^^^^^^^^^^^^^^^^^^^^^^^^^^^^^
  File "/home/mohammed/venv/lib/python3.11/site-packages/airflow/models/taskinstance.py", line 734, in _execute_callable
    return ExecutionCallableRunner(
           ^^^^^^^^^^^^^^^^^^^^^^^^
  File "/home/mohammed/venv/lib/python3.11/site-packages/airflow/utils/operator_helpers.py", line 252, in run
    return self.func(*args, **kwargs)
           ^^^^^^^^^^^^^^^^^^^^^^^^^^
  File "/home/mohammed/venv/lib/python3.11/site-packages/airflow/models/baseoperator.py", line 424, in wrapper
    return func(self, *args, **kwargs)
           ^^^^^^^^^^^^^^^^^^^^^^^^^^^
  File "/home/mohammed/venv/lib/python3.11/site-packages/airflow/operators/bash.py", line 276, in execute
    raise AirflowException(
airflow.exceptions.AirflowException: Bash command failed. The command returned a non-zero exit code 1.
[2025-03-28T22:55:41.468+0000] {logging_mixin.py:190} INFO - Task instance in failure state
[2025-03-28T22:55:41.469+0000] {logging_mixin.py:190} INFO - Task start:2025-03-28 22:55:11.947241+00:00 end:2025-03-28 22:55:41.452094+00:00 duration:29.504853
[2025-03-28T22:55:41.482+0000] {logging_mixin.py:190} INFO - Task:<Task(BashOperator): dbt_run_decisionnal> dag:<DAG: bank_reviews_etl_and_analysis_pipeline> dagrun:<DagRun bank_reviews_etl_and_analysis_pipeline @ 2024-09-22 00:00:00+00:00: scheduled__2024-09-22T00:00:00+00:00, state:running, queued_at: 2025-03-28 22:49:32.396237+00:00. externally triggered: False>
[2025-03-28T22:55:41.483+0000] {logging_mixin.py:190} INFO - Failure caused by Bash command failed. The command returned a non-zero exit code 1.
[2025-03-28T22:55:41.484+0000] {taskinstance.py:1226} INFO - Marking task as FAILED. dag_id=bank_reviews_etl_and_analysis_pipeline, task_id=dbt_run_decisionnal, run_id=scheduled__2024-09-22T00:00:00+00:00, execution_date=20240922T000000, start_date=20250328T225511, end_date=20250328T225541
[2025-03-28T22:55:41.829+0000] {taskinstance.py:341} INFO - ::group::Post task execution logs
[2025-03-28T22:55:41.830+0000] {standard_task_runner.py:124} ERROR - Failed to execute job 2442 for task dbt_run_decisionnal (Bash command failed. The command returned a non-zero exit code 1.; 587300)
Traceback (most recent call last):
  File "/home/mohammed/venv/lib/python3.11/site-packages/airflow/task/task_runner/standard_task_runner.py", line 117, in _start_by_fork
    ret = args.func(args, dag=self.dag)
          ^^^^^^^^^^^^^^^^^^^^^^^^^^^^^
  File "/home/mohammed/venv/lib/python3.11/site-packages/airflow/cli/cli_config.py", line 49, in command
    return func(*args, **kwargs)
           ^^^^^^^^^^^^^^^^^^^^^
  File "/home/mohammed/venv/lib/python3.11/site-packages/airflow/utils/cli.py", line 116, in wrapper
    return f(*args, **kwargs)
           ^^^^^^^^^^^^^^^^^^
  File "/home/mohammed/venv/lib/python3.11/site-packages/airflow/cli/commands/task_command.py", line 483, in task_run
    task_return_code = _run_task_by_selected_method(args, _dag, ti)
                       ^^^^^^^^^^^^^^^^^^^^^^^^^^^^^^^^^^^^^^^^^^^^
  File "/home/mohammed/venv/lib/python3.11/site-packages/airflow/cli/commands/task_command.py", line 256, in _run_task_by_selected_method
    return _run_raw_task(args, ti)
           ^^^^^^^^^^^^^^^^^^^^^^^
  File "/home/mohammed/venv/lib/python3.11/site-packages/airflow/cli/commands/task_command.py", line 341, in _run_raw_task
    return ti._run_raw_task(
           ^^^^^^^^^^^^^^^^^
  File "/home/mohammed/venv/lib/python3.11/site-packages/airflow/utils/session.py", line 97, in wrapper
    return func(*args, session=session, **kwargs)
           ^^^^^^^^^^^^^^^^^^^^^^^^^^^^^^^^^^^^^^
  File "/home/mohammed/venv/lib/python3.11/site-packages/airflow/models/taskinstance.py", line 3006, in _run_raw_task
    return _run_raw_task(
           ^^^^^^^^^^^^^^
  File "/home/mohammed/venv/lib/python3.11/site-packages/airflow/models/taskinstance.py", line 274, in _run_raw_task
    TaskInstance._execute_task_with_callbacks(
  File "/home/mohammed/venv/lib/python3.11/site-packages/airflow/models/taskinstance.py", line 3161, in _execute_task_with_callbacks
    result = self._execute_task(context, task_orig)
             ^^^^^^^^^^^^^^^^^^^^^^^^^^^^^^^^^^^^^^
  File "/home/mohammed/venv/lib/python3.11/site-packages/airflow/models/taskinstance.py", line 3185, in _execute_task
    return _execute_task(self, context, task_orig)
           ^^^^^^^^^^^^^^^^^^^^^^^^^^^^^^^^^^^^^^^
  File "/home/mohammed/venv/lib/python3.11/site-packages/airflow/models/taskinstance.py", line 768, in _execute_task
    result = _execute_callable(context=context, **execute_callable_kwargs)
             ^^^^^^^^^^^^^^^^^^^^^^^^^^^^^^^^^^^^^^^^^^^^^^^^^^^^^^^^^^^^^
  File "/home/mohammed/venv/lib/python3.11/site-packages/airflow/models/taskinstance.py", line 734, in _execute_callable
    return ExecutionCallableRunner(
           ^^^^^^^^^^^^^^^^^^^^^^^^
  File "/home/mohammed/venv/lib/python3.11/site-packages/airflow/utils/operator_helpers.py", line 252, in run
    return self.func(*args, **kwargs)
           ^^^^^^^^^^^^^^^^^^^^^^^^^^
  File "/home/mohammed/venv/lib/python3.11/site-packages/airflow/models/baseoperator.py", line 424, in wrapper
    return func(self, *args, **kwargs)
           ^^^^^^^^^^^^^^^^^^^^^^^^^^^
  File "/home/mohammed/venv/lib/python3.11/site-packages/airflow/operators/bash.py", line 276, in execute
    raise AirflowException(
airflow.exceptions.AirflowException: Bash command failed. The command returned a non-zero exit code 1.
[2025-03-28T22:55:41.921+0000] {local_task_job_runner.py:266} INFO - Task exited with return code 1
[2025-03-28T22:55:42.082+0000] {taskinstance.py:3901} INFO - 0 downstream tasks scheduled from follow-on schedule check
[2025-03-28T22:55:42.107+0000] {local_task_job_runner.py:245} INFO - ::endgroup::
