[2025-03-17T01:17:48.222+0000] {local_task_job_runner.py:123} INFO - ::group::Pre task execution logs
[2025-03-17T01:17:48.246+0000] {taskinstance.py:2614} INFO - Dependencies all met for dep_context=non-requeueable deps ti=<TaskInstance: load_reviews_pipeline.dbt_run scheduled__2025-02-17T00:00:00+00:00 [queued]>
[2025-03-17T01:17:48.253+0000] {taskinstance.py:2614} INFO - Dependencies all met for dep_context=requeueable deps ti=<TaskInstance: load_reviews_pipeline.dbt_run scheduled__2025-02-17T00:00:00+00:00 [queued]>
[2025-03-17T01:17:48.253+0000] {taskinstance.py:2867} INFO - Starting attempt 1 of 2
[2025-03-17T01:17:48.268+0000] {taskinstance.py:2890} INFO - Executing <Task(BashOperator): dbt_run> on 2025-02-17 00:00:00+00:00
[2025-03-17T01:17:48.273+0000] {standard_task_runner.py:72} INFO - Started process 327659 to run task
[2025-03-17T01:17:48.277+0000] {standard_task_runner.py:104} INFO - Running: ['airflow', 'tasks', 'run', 'load_reviews_pipeline', 'dbt_run', 'scheduled__2025-02-17T00:00:00+00:00', '--job-id', '626', '--raw', '--subdir', 'DAGS_FOLDER/dag_load_reviews.py', '--cfg-path', '/tmp/tmpbobwobs3']
[2025-03-17T01:17:48.279+0000] {standard_task_runner.py:105} INFO - Job 626: Subtask dbt_run
[2025-03-17T01:17:48.369+0000] {task_command.py:467} INFO - Running <TaskInstance: load_reviews_pipeline.dbt_run scheduled__2025-02-17T00:00:00+00:00 [running]> on host DESKTOP-IM7V4RI.
[2025-03-17T01:17:48.492+0000] {taskinstance.py:3134} INFO - Exporting env vars: AIRFLOW_CTX_DAG_OWNER='mohammed' AIRFLOW_CTX_DAG_ID='load_reviews_pipeline' AIRFLOW_CTX_TASK_ID='dbt_run' AIRFLOW_CTX_EXECUTION_DATE='2025-02-17T00:00:00+00:00' AIRFLOW_CTX_TRY_NUMBER='1' AIRFLOW_CTX_DAG_RUN_ID='scheduled__2025-02-17T00:00:00+00:00'
[2025-03-17T01:17:48.494+0000] {logging_mixin.py:190} INFO - Task instance is in running state
[2025-03-17T01:17:48.494+0000] {logging_mixin.py:190} INFO -  Previous state of the Task instance: queued
[2025-03-17T01:17:48.494+0000] {logging_mixin.py:190} INFO - Current task name:dbt_run state:running start_date:2025-03-17 01:17:48.246419+00:00
[2025-03-17T01:17:48.494+0000] {logging_mixin.py:190} INFO - Dag name:load_reviews_pipeline and current dag run status:running
[2025-03-17T01:17:48.495+0000] {taskinstance.py:732} INFO - ::endgroup::
[2025-03-17T01:17:48.495+0000] {subprocess.py:78} INFO - Tmp dir root location: /tmp
[2025-03-17T01:17:48.497+0000] {subprocess.py:88} INFO - Running command: ['/usr/bin/bash', '-c', 'cd /home/mohammed/.dbt/bank_reviews_project && dbt run']
[2025-03-17T01:17:48.510+0000] {subprocess.py:99} INFO - Output:
[2025-03-17T01:17:50.062+0000] {subprocess.py:106} INFO - [0m01:17:50  Running with dbt=1.9.3
[2025-03-17T01:17:50.377+0000] {subprocess.py:106} INFO - [0m01:17:50  Registered adapter: postgres=1.9.0
[2025-03-17T01:17:50.841+0000] {subprocess.py:106} INFO - [0m01:17:50  Found 10 models, 4 data tests, 2 sources, 433 macros
[2025-03-17T01:17:50.847+0000] {subprocess.py:106} INFO - [0m01:17:50
[2025-03-17T01:17:50.848+0000] {subprocess.py:106} INFO - [0m01:17:50  Concurrency: 4 threads (target='dev')
[2025-03-17T01:17:50.848+0000] {subprocess.py:106} INFO - [0m01:17:50
[2025-03-17T01:17:51.026+0000] {subprocess.py:106} INFO - [0m01:17:51  1 of 10 START sql view model public.clean_reviews .............................. [RUN]
[2025-03-17T01:17:51.028+0000] {subprocess.py:106} INFO - [0m01:17:51  2 of 10 START sql table model public.my_first_dbt_model ........................ [RUN]
[2025-03-17T01:17:51.030+0000] {subprocess.py:106} INFO - [0m01:17:51  3 of 10 START sql view model public.remove_duplicates .......................... [RUN]
[2025-03-17T01:17:51.033+0000] {subprocess.py:106} INFO - [0m01:17:51  4 of 10 START sql view model public.stg_clean_reviews .......................... [RUN]
[2025-03-17T01:17:51.285+0000] {subprocess.py:106} INFO - [0m01:17:51  1 of 10 ERROR creating sql view model public.clean_reviews ..................... [[31mERROR[0m in 0.24s]
[2025-03-17T01:17:51.296+0000] {subprocess.py:106} INFO - [0m01:17:51  4 of 10 ERROR creating sql view model public.stg_clean_reviews ................. [[31mERROR[0m in 0.25s]
[2025-03-17T01:17:51.361+0000] {subprocess.py:106} INFO - [0m01:17:51  5 of 10 SKIP relation public.dim_bank .......................................... [[33mSKIP[0m]
[2025-03-17T01:17:51.362+0000] {subprocess.py:106} INFO - [0m01:17:51  6 of 10 SKIP relation public.dim_branch ........................................ [[33mSKIP[0m]
[2025-03-17T01:17:51.379+0000] {subprocess.py:106} INFO - [0m01:17:51  7 of 10 SKIP relation public.dim_location ...................................... [[33mSKIP[0m]
[2025-03-17T01:17:51.382+0000] {subprocess.py:106} INFO - [0m01:17:51  8 of 10 SKIP relation public.dim_sentiment ..................................... [[33mSKIP[0m]
[2025-03-17T01:17:51.409+0000] {subprocess.py:106} INFO - [0m01:17:51  9 of 10 SKIP relation public.fact_reviews ...................................... [[33mSKIP[0m]
[2025-03-17T01:17:51.426+0000] {subprocess.py:106} INFO - [0m01:17:51  2 of 10 OK created sql table model public.my_first_dbt_model ................... [[32mSELECT 2[0m in 0.39s]
[2025-03-17T01:17:51.442+0000] {subprocess.py:106} INFO - [0m01:17:51  10 of 10 START sql view model public.my_second_dbt_model ....................... [RUN]
[2025-03-17T01:17:51.548+0000] {subprocess.py:106} INFO - [0m01:17:51  3 of 10 OK created sql view model public.remove_duplicates ..................... [[32mCREATE VIEW[0m in 0.43s]
[2025-03-17T01:17:51.589+0000] {subprocess.py:106} INFO - [0m01:17:51  10 of 10 OK created sql view model public.my_second_dbt_model .................. [[32mCREATE VIEW[0m in 0.14s]
[2025-03-17T01:17:51.613+0000] {subprocess.py:106} INFO - [0m01:17:51
[2025-03-17T01:17:51.613+0000] {subprocess.py:106} INFO - [0m01:17:51  Finished running 1 table model, 9 view models in 0 hours 0 minutes and 0.76 seconds (0.76s).
[2025-03-17T01:17:51.650+0000] {subprocess.py:106} INFO - [0m01:17:51
[2025-03-17T01:17:51.650+0000] {subprocess.py:106} INFO - [0m01:17:51  [31mCompleted with 2 errors, 0 partial successes, and 0 warnings:[0m
[2025-03-17T01:17:51.651+0000] {subprocess.py:106} INFO - [0m01:17:51
[2025-03-17T01:17:51.651+0000] {subprocess.py:106} INFO - [0m01:17:51    Database Error in model clean_reviews (models/clean_reviews.sql)
[2025-03-17T01:17:51.651+0000] {subprocess.py:106} INFO -   syntax error at or near "external"
[2025-03-17T01:17:51.651+0000] {subprocess.py:106} INFO -   LINE 2: drop external if exists "project_data_wherhouse"."public"."c...
[2025-03-17T01:17:51.652+0000] {subprocess.py:106} INFO -                ^
[2025-03-17T01:17:51.652+0000] {subprocess.py:106} INFO - [0m01:17:51
[2025-03-17T01:17:51.652+0000] {subprocess.py:106} INFO - [0m01:17:51    Database Error in model stg_clean_reviews (models/stg_clean_reviews.sql)
[2025-03-17T01:17:51.652+0000] {subprocess.py:106} INFO -   syntax error at or near "external"
[2025-03-17T01:17:51.652+0000] {subprocess.py:106} INFO -   LINE 2: drop external if exists "project_data_wherhouse"."public"."s...
[2025-03-17T01:17:51.652+0000] {subprocess.py:106} INFO -                ^
[2025-03-17T01:17:51.653+0000] {subprocess.py:106} INFO - [0m01:17:51
[2025-03-17T01:17:51.653+0000] {subprocess.py:106} INFO - [0m01:17:51  Done. PASS=3 WARN=0 ERROR=2 SKIP=5 TOTAL=10
[2025-03-17T01:17:53.011+0000] {subprocess.py:110} INFO - Command exited with return code 1
[2025-03-17T01:17:53.032+0000] {taskinstance.py:3313} ERROR - Task failed with exception
Traceback (most recent call last):
  File "/home/mohammed/venv/lib/python3.11/site-packages/airflow/models/taskinstance.py", line 768, in _execute_task
    result = _execute_callable(context=context, **execute_callable_kwargs)
             ^^^^^^^^^^^^^^^^^^^^^^^^^^^^^^^^^^^^^^^^^^^^^^^^^^^^^^^^^^^^^
  File "/home/mohammed/venv/lib/python3.11/site-packages/airflow/models/taskinstance.py", line 734, in _execute_callable
    return ExecutionCallableRunner(
           ^^^^^^^^^^^^^^^^^^^^^^^^
  File "/home/mohammed/venv/lib/python3.11/site-packages/airflow/utils/operator_helpers.py", line 252, in run
    return self.func(*args, **kwargs)
           ^^^^^^^^^^^^^^^^^^^^^^^^^^
  File "/home/mohammed/venv/lib/python3.11/site-packages/airflow/models/baseoperator.py", line 424, in wrapper
    return func(self, *args, **kwargs)
           ^^^^^^^^^^^^^^^^^^^^^^^^^^^
  File "/home/mohammed/venv/lib/python3.11/site-packages/airflow/operators/bash.py", line 276, in execute
    raise AirflowException(
airflow.exceptions.AirflowException: Bash command failed. The command returned a non-zero exit code 1.
[2025-03-17T01:17:53.041+0000] {logging_mixin.py:190} INFO - Task instance in failure state
[2025-03-17T01:17:53.041+0000] {logging_mixin.py:190} INFO - Task start:2025-03-17 01:17:48.246419+00:00 end:2025-03-17 01:17:53.040244+00:00 duration:4.793825
[2025-03-17T01:17:53.041+0000] {logging_mixin.py:190} INFO - Task:<Task(BashOperator): dbt_run> dag:<DAG: load_reviews_pipeline> dagrun:<DagRun load_reviews_pipeline @ 2025-02-17 00:00:00+00:00: scheduled__2025-02-17T00:00:00+00:00, state:running, queued_at: 2025-03-17 01:17:47.426612+00:00. externally triggered: False>
[2025-03-17T01:17:53.041+0000] {logging_mixin.py:190} INFO - Failure caused by Bash command failed. The command returned a non-zero exit code 1.
[2025-03-17T01:17:53.042+0000] {taskinstance.py:1226} INFO - Marking task as UP_FOR_RETRY. dag_id=load_reviews_pipeline, task_id=dbt_run, run_id=scheduled__2025-02-17T00:00:00+00:00, execution_date=20250217T000000, start_date=20250317T011748, end_date=20250317T011753
[2025-03-17T01:17:53.106+0000] {taskinstance.py:341} INFO - ::group::Post task execution logs
[2025-03-17T01:17:53.106+0000] {standard_task_runner.py:124} ERROR - Failed to execute job 626 for task dbt_run (Bash command failed. The command returned a non-zero exit code 1.; 327659)
Traceback (most recent call last):
  File "/home/mohammed/venv/lib/python3.11/site-packages/airflow/task/task_runner/standard_task_runner.py", line 117, in _start_by_fork
    ret = args.func(args, dag=self.dag)
          ^^^^^^^^^^^^^^^^^^^^^^^^^^^^^
  File "/home/mohammed/venv/lib/python3.11/site-packages/airflow/cli/cli_config.py", line 49, in command
    return func(*args, **kwargs)
           ^^^^^^^^^^^^^^^^^^^^^
  File "/home/mohammed/venv/lib/python3.11/site-packages/airflow/utils/cli.py", line 116, in wrapper
    return f(*args, **kwargs)
           ^^^^^^^^^^^^^^^^^^
  File "/home/mohammed/venv/lib/python3.11/site-packages/airflow/cli/commands/task_command.py", line 483, in task_run
    task_return_code = _run_task_by_selected_method(args, _dag, ti)
                       ^^^^^^^^^^^^^^^^^^^^^^^^^^^^^^^^^^^^^^^^^^^^
  File "/home/mohammed/venv/lib/python3.11/site-packages/airflow/cli/commands/task_command.py", line 256, in _run_task_by_selected_method
    return _run_raw_task(args, ti)
           ^^^^^^^^^^^^^^^^^^^^^^^
  File "/home/mohammed/venv/lib/python3.11/site-packages/airflow/cli/commands/task_command.py", line 341, in _run_raw_task
    return ti._run_raw_task(
           ^^^^^^^^^^^^^^^^^
  File "/home/mohammed/venv/lib/python3.11/site-packages/airflow/utils/session.py", line 97, in wrapper
    return func(*args, session=session, **kwargs)
           ^^^^^^^^^^^^^^^^^^^^^^^^^^^^^^^^^^^^^^
  File "/home/mohammed/venv/lib/python3.11/site-packages/airflow/models/taskinstance.py", line 3006, in _run_raw_task
    return _run_raw_task(
           ^^^^^^^^^^^^^^
  File "/home/mohammed/venv/lib/python3.11/site-packages/airflow/models/taskinstance.py", line 274, in _run_raw_task
    TaskInstance._execute_task_with_callbacks(
  File "/home/mohammed/venv/lib/python3.11/site-packages/airflow/models/taskinstance.py", line 3161, in _execute_task_with_callbacks
    result = self._execute_task(context, task_orig)
             ^^^^^^^^^^^^^^^^^^^^^^^^^^^^^^^^^^^^^^
  File "/home/mohammed/venv/lib/python3.11/site-packages/airflow/models/taskinstance.py", line 3185, in _execute_task
    return _execute_task(self, context, task_orig)
           ^^^^^^^^^^^^^^^^^^^^^^^^^^^^^^^^^^^^^^^
  File "/home/mohammed/venv/lib/python3.11/site-packages/airflow/models/taskinstance.py", line 768, in _execute_task
    result = _execute_callable(context=context, **execute_callable_kwargs)
             ^^^^^^^^^^^^^^^^^^^^^^^^^^^^^^^^^^^^^^^^^^^^^^^^^^^^^^^^^^^^^
  File "/home/mohammed/venv/lib/python3.11/site-packages/airflow/models/taskinstance.py", line 734, in _execute_callable
    return ExecutionCallableRunner(
           ^^^^^^^^^^^^^^^^^^^^^^^^
  File "/home/mohammed/venv/lib/python3.11/site-packages/airflow/utils/operator_helpers.py", line 252, in run
    return self.func(*args, **kwargs)
           ^^^^^^^^^^^^^^^^^^^^^^^^^^
  File "/home/mohammed/venv/lib/python3.11/site-packages/airflow/models/baseoperator.py", line 424, in wrapper
    return func(self, *args, **kwargs)
           ^^^^^^^^^^^^^^^^^^^^^^^^^^^
  File "/home/mohammed/venv/lib/python3.11/site-packages/airflow/operators/bash.py", line 276, in execute
    raise AirflowException(
airflow.exceptions.AirflowException: Bash command failed. The command returned a non-zero exit code 1.
[2025-03-17T01:17:53.143+0000] {local_task_job_runner.py:266} INFO - Task exited with return code 1
[2025-03-17T01:17:53.171+0000] {taskinstance.py:3901} INFO - 0 downstream tasks scheduled from follow-on schedule check
[2025-03-17T01:17:53.176+0000] {local_task_job_runner.py:245} INFO - ::endgroup::
