[2025-03-18T17:10:41.386+0000] {local_task_job_runner.py:123} INFO - ::group::Pre task execution logs
[2025-03-18T17:10:41.530+0000] {taskinstance.py:2614} INFO - Dependencies all met for dep_context=non-requeueable deps ti=<TaskInstance: load_dbt_clean_reviews_pipeline.dbt_run scheduled__2024-04-04T00:00:00+00:00 [queued]>
[2025-03-18T17:10:41.571+0000] {taskinstance.py:2614} INFO - Dependencies all met for dep_context=requeueable deps ti=<TaskInstance: load_dbt_clean_reviews_pipeline.dbt_run scheduled__2024-04-04T00:00:00+00:00 [queued]>
[2025-03-18T17:10:41.573+0000] {taskinstance.py:2867} INFO - Starting attempt 2 of 2
[2025-03-18T17:10:41.653+0000] {taskinstance.py:2890} INFO - Executing <Task(BashOperator): dbt_run> on 2024-04-04 00:00:00+00:00
[2025-03-18T17:10:41.690+0000] {standard_task_runner.py:72} INFO - Started process 54843 to run task
[2025-03-18T17:10:41.709+0000] {standard_task_runner.py:104} INFO - Running: ['airflow', 'tasks', 'run', 'load_dbt_clean_reviews_pipeline', 'dbt_run', 'scheduled__2024-04-04T00:00:00+00:00', '--job-id', '784', '--raw', '--subdir', 'DAGS_FOLDER/dag_load_reviews.py', '--cfg-path', '/tmp/tmp2wxszv00']
[2025-03-18T17:10:41.712+0000] {standard_task_runner.py:105} INFO - Job 784: Subtask dbt_run
[2025-03-18T17:10:42.015+0000] {task_command.py:467} INFO - Running <TaskInstance: load_dbt_clean_reviews_pipeline.dbt_run scheduled__2024-04-04T00:00:00+00:00 [running]> on host DESKTOP-IM7V4RI.
[2025-03-18T17:10:42.386+0000] {taskinstance.py:3134} INFO - Exporting env vars: AIRFLOW_CTX_DAG_OWNER='mohammed' AIRFLOW_CTX_DAG_ID='load_dbt_clean_reviews_pipeline' AIRFLOW_CTX_TASK_ID='dbt_run' AIRFLOW_CTX_EXECUTION_DATE='2024-04-04T00:00:00+00:00' AIRFLOW_CTX_TRY_NUMBER='2' AIRFLOW_CTX_DAG_RUN_ID='scheduled__2024-04-04T00:00:00+00:00'
[2025-03-18T17:10:42.394+0000] {logging_mixin.py:190} INFO - Task instance is in running state
[2025-03-18T17:10:42.394+0000] {logging_mixin.py:190} INFO -  Previous state of the Task instance: queued
[2025-03-18T17:10:42.395+0000] {logging_mixin.py:190} INFO - Current task name:dbt_run state:running start_date:2025-03-18 17:10:41.531819+00:00
[2025-03-18T17:10:42.396+0000] {logging_mixin.py:190} INFO - Dag name:load_dbt_clean_reviews_pipeline and current dag run status:running
[2025-03-18T17:10:42.396+0000] {taskinstance.py:732} INFO - ::endgroup::
[2025-03-18T17:10:42.398+0000] {subprocess.py:78} INFO - Tmp dir root location: /tmp
[2025-03-18T17:10:42.401+0000] {subprocess.py:88} INFO - Running command: ['/usr/bin/bash', '-c', 'cd /home/mohammed/.dbt/dbt_projects/bank_reviews_transactional && dbt run']
[2025-03-18T17:10:42.431+0000] {subprocess.py:99} INFO - Output:
[2025-03-18T17:10:48.917+0000] {subprocess.py:106} INFO - [0m17:10:48  Running with dbt=1.9.3
[2025-03-18T17:10:50.136+0000] {subprocess.py:106} INFO - [0m17:10:50  Registered adapter: postgres=1.9.0
[2025-03-18T17:10:53.878+0000] {subprocess.py:106} INFO - [0m17:10:53  [[33mWARNING[0m]: Configuration paths exist in your dbt_project.yml file which do not apply to any resources.
[2025-03-18T17:10:53.879+0000] {subprocess.py:106} INFO - There are 1 unused configuration paths:
[2025-03-18T17:10:53.879+0000] {subprocess.py:106} INFO - - models.bank_reviews_transactional.transactional
[2025-03-18T17:10:56.210+0000] {subprocess.py:106} INFO - [0m17:10:56  Found 3 models, 4 data tests, 1 source, 433 macros
[2025-03-18T17:10:56.289+0000] {subprocess.py:106} INFO - [0m17:10:56
[2025-03-18T17:10:56.292+0000] {subprocess.py:106} INFO - [0m17:10:56  Concurrency: 4 threads (target='dev')
[2025-03-18T17:10:56.295+0000] {subprocess.py:106} INFO - [0m17:10:56
[2025-03-18T17:10:58.955+0000] {subprocess.py:106} INFO - [0m17:10:58  1 of 3 START sql table model transactional.clean_reviews ....................... [RUN]
[2025-03-18T17:10:59.017+0000] {subprocess.py:106} INFO - [0m17:10:59  2 of 3 START sql table model transactional.my_first_dbt_model .................. [RUN]
[2025-03-18T17:11:01.334+0000] {subprocess.py:106} INFO - [0m17:11:01  1 of 3 ERROR creating sql table model transactional.clean_reviews .............. [[31mERROR[0m in 2.25s]
[2025-03-18T17:11:01.397+0000] {subprocess.py:106} INFO - [0m17:11:01  2 of 3 ERROR creating sql table model transactional.my_first_dbt_model ......... [[31mERROR[0m in 2.32s]
[2025-03-18T17:11:01.426+0000] {subprocess.py:106} INFO - [0m17:11:01  3 of 3 SKIP relation transactional.my_second_dbt_model ......................... [[33mSKIP[0m]
[2025-03-18T17:11:01.923+0000] {subprocess.py:106} INFO - [0m17:11:01
[2025-03-18T17:11:01.925+0000] {subprocess.py:106} INFO - [0m17:11:01  Finished running 2 table models, 1 view model in 0 hours 0 minutes and 5.63 seconds (5.63s).
[2025-03-18T17:11:02.405+0000] {subprocess.py:106} INFO - [0m17:11:02
[2025-03-18T17:11:02.408+0000] {subprocess.py:106} INFO - [0m17:11:02  [31mCompleted with 2 errors, 0 partial successes, and 0 warnings:[0m
[2025-03-18T17:11:02.414+0000] {subprocess.py:106} INFO - [0m17:11:02
[2025-03-18T17:11:02.419+0000] {subprocess.py:106} INFO - [0m17:11:02    Database Error in model my_first_dbt_model (models/example/my_first_dbt_model.sql)
[2025-03-18T17:11:02.419+0000] {subprocess.py:106} INFO -   syntax error at or near "external"
[2025-03-18T17:11:02.420+0000] {subprocess.py:106} INFO -   LINE 2: drop external if exists "project_data_wherhouse"."transactio...
[2025-03-18T17:11:02.420+0000] {subprocess.py:106} INFO -                ^
[2025-03-18T17:11:02.422+0000] {subprocess.py:106} INFO - [0m17:11:02
[2025-03-18T17:11:02.426+0000] {subprocess.py:106} INFO - [0m17:11:02    Database Error in model clean_reviews (models/clean_reviews.sql)
[2025-03-18T17:11:02.429+0000] {subprocess.py:106} INFO -   column r.bank_name does not exist
[2025-03-18T17:11:02.429+0000] {subprocess.py:106} INFO -   LINE 141:         r.bank_name,
[2025-03-18T17:11:02.430+0000] {subprocess.py:106} INFO -                     ^
[2025-03-18T17:11:02.430+0000] {subprocess.py:106} INFO -   HINT:  Perhaps you meant to reference the column "c.bank_name".
[2025-03-18T17:11:02.431+0000] {subprocess.py:106} INFO -   compiled code at target/run/bank_reviews_transactional/models/clean_reviews.sql
[2025-03-18T17:11:02.435+0000] {subprocess.py:106} INFO - [0m17:11:02
[2025-03-18T17:11:02.437+0000] {subprocess.py:106} INFO - [0m17:11:02  Done. PASS=0 WARN=0 ERROR=2 SKIP=1 TOTAL=3
[2025-03-18T17:11:10.189+0000] {subprocess.py:110} INFO - Command exited with return code 1
[2025-03-18T17:11:10.817+0000] {taskinstance.py:3313} ERROR - Task failed with exception
Traceback (most recent call last):
  File "/home/mohammed/venv/lib/python3.11/site-packages/airflow/models/taskinstance.py", line 768, in _execute_task
    result = _execute_callable(context=context, **execute_callable_kwargs)
             ^^^^^^^^^^^^^^^^^^^^^^^^^^^^^^^^^^^^^^^^^^^^^^^^^^^^^^^^^^^^^
  File "/home/mohammed/venv/lib/python3.11/site-packages/airflow/models/taskinstance.py", line 734, in _execute_callable
    return ExecutionCallableRunner(
           ^^^^^^^^^^^^^^^^^^^^^^^^
  File "/home/mohammed/venv/lib/python3.11/site-packages/airflow/utils/operator_helpers.py", line 252, in run
    return self.func(*args, **kwargs)
           ^^^^^^^^^^^^^^^^^^^^^^^^^^
  File "/home/mohammed/venv/lib/python3.11/site-packages/airflow/models/baseoperator.py", line 424, in wrapper
    return func(self, *args, **kwargs)
           ^^^^^^^^^^^^^^^^^^^^^^^^^^^
  File "/home/mohammed/venv/lib/python3.11/site-packages/airflow/operators/bash.py", line 276, in execute
    raise AirflowException(
airflow.exceptions.AirflowException: Bash command failed. The command returned a non-zero exit code 1.
[2025-03-18T17:11:10.868+0000] {logging_mixin.py:190} INFO - Task instance in failure state
[2025-03-18T17:11:10.869+0000] {logging_mixin.py:190} INFO - Task start:2025-03-18 17:10:41.531819+00:00 end:2025-03-18 17:11:10.855754+00:00 duration:29.323935
[2025-03-18T17:11:10.870+0000] {logging_mixin.py:190} INFO - Task:<Task(BashOperator): dbt_run> dag:<DAG: load_dbt_clean_reviews_pipeline> dagrun:<DagRun load_dbt_clean_reviews_pipeline @ 2024-04-04 00:00:00+00:00: scheduled__2024-04-04T00:00:00+00:00, state:running, queued_at: 2025-03-18 17:04:52.525926+00:00. externally triggered: False>
[2025-03-18T17:11:10.871+0000] {logging_mixin.py:190} INFO - Failure caused by Bash command failed. The command returned a non-zero exit code 1.
[2025-03-18T17:11:10.872+0000] {taskinstance.py:1226} INFO - Marking task as FAILED. dag_id=load_dbt_clean_reviews_pipeline, task_id=dbt_run, run_id=scheduled__2024-04-04T00:00:00+00:00, execution_date=20240404T000000, start_date=20250318T171041, end_date=20250318T171110
[2025-03-18T17:11:11.686+0000] {taskinstance.py:341} INFO - ::group::Post task execution logs
[2025-03-18T17:11:11.688+0000] {standard_task_runner.py:124} ERROR - Failed to execute job 784 for task dbt_run (Bash command failed. The command returned a non-zero exit code 1.; 54843)
Traceback (most recent call last):
  File "/home/mohammed/venv/lib/python3.11/site-packages/airflow/task/task_runner/standard_task_runner.py", line 117, in _start_by_fork
    ret = args.func(args, dag=self.dag)
          ^^^^^^^^^^^^^^^^^^^^^^^^^^^^^
  File "/home/mohammed/venv/lib/python3.11/site-packages/airflow/cli/cli_config.py", line 49, in command
    return func(*args, **kwargs)
           ^^^^^^^^^^^^^^^^^^^^^
  File "/home/mohammed/venv/lib/python3.11/site-packages/airflow/utils/cli.py", line 116, in wrapper
    return f(*args, **kwargs)
           ^^^^^^^^^^^^^^^^^^
  File "/home/mohammed/venv/lib/python3.11/site-packages/airflow/cli/commands/task_command.py", line 483, in task_run
    task_return_code = _run_task_by_selected_method(args, _dag, ti)
                       ^^^^^^^^^^^^^^^^^^^^^^^^^^^^^^^^^^^^^^^^^^^^
  File "/home/mohammed/venv/lib/python3.11/site-packages/airflow/cli/commands/task_command.py", line 256, in _run_task_by_selected_method
    return _run_raw_task(args, ti)
           ^^^^^^^^^^^^^^^^^^^^^^^
  File "/home/mohammed/venv/lib/python3.11/site-packages/airflow/cli/commands/task_command.py", line 341, in _run_raw_task
    return ti._run_raw_task(
           ^^^^^^^^^^^^^^^^^
  File "/home/mohammed/venv/lib/python3.11/site-packages/airflow/utils/session.py", line 97, in wrapper
    return func(*args, session=session, **kwargs)
           ^^^^^^^^^^^^^^^^^^^^^^^^^^^^^^^^^^^^^^
  File "/home/mohammed/venv/lib/python3.11/site-packages/airflow/models/taskinstance.py", line 3006, in _run_raw_task
    return _run_raw_task(
           ^^^^^^^^^^^^^^
  File "/home/mohammed/venv/lib/python3.11/site-packages/airflow/models/taskinstance.py", line 274, in _run_raw_task
    TaskInstance._execute_task_with_callbacks(
  File "/home/mohammed/venv/lib/python3.11/site-packages/airflow/models/taskinstance.py", line 3161, in _execute_task_with_callbacks
    result = self._execute_task(context, task_orig)
             ^^^^^^^^^^^^^^^^^^^^^^^^^^^^^^^^^^^^^^
  File "/home/mohammed/venv/lib/python3.11/site-packages/airflow/models/taskinstance.py", line 3185, in _execute_task
    return _execute_task(self, context, task_orig)
           ^^^^^^^^^^^^^^^^^^^^^^^^^^^^^^^^^^^^^^^
  File "/home/mohammed/venv/lib/python3.11/site-packages/airflow/models/taskinstance.py", line 768, in _execute_task
    result = _execute_callable(context=context, **execute_callable_kwargs)
             ^^^^^^^^^^^^^^^^^^^^^^^^^^^^^^^^^^^^^^^^^^^^^^^^^^^^^^^^^^^^^
  File "/home/mohammed/venv/lib/python3.11/site-packages/airflow/models/taskinstance.py", line 734, in _execute_callable
    return ExecutionCallableRunner(
           ^^^^^^^^^^^^^^^^^^^^^^^^
  File "/home/mohammed/venv/lib/python3.11/site-packages/airflow/utils/operator_helpers.py", line 252, in run
    return self.func(*args, **kwargs)
           ^^^^^^^^^^^^^^^^^^^^^^^^^^
  File "/home/mohammed/venv/lib/python3.11/site-packages/airflow/models/baseoperator.py", line 424, in wrapper
    return func(self, *args, **kwargs)
           ^^^^^^^^^^^^^^^^^^^^^^^^^^^
  File "/home/mohammed/venv/lib/python3.11/site-packages/airflow/operators/bash.py", line 276, in execute
    raise AirflowException(
airflow.exceptions.AirflowException: Bash command failed. The command returned a non-zero exit code 1.
[2025-03-18T17:11:11.859+0000] {local_task_job_runner.py:266} INFO - Task exited with return code 1
[2025-03-18T17:11:12.028+0000] {taskinstance.py:3901} INFO - 0 downstream tasks scheduled from follow-on schedule check
[2025-03-18T17:11:12.046+0000] {local_task_job_runner.py:245} INFO - ::endgroup::
