[2025-03-28T22:56:04.664+0000] {local_task_job_runner.py:123} INFO - ::group::Pre task execution logs
[2025-03-28T22:56:04.886+0000] {taskinstance.py:2614} INFO - Dependencies all met for dep_context=non-requeueable deps ti=<TaskInstance: bank_reviews_etl_and_analysis_pipeline.dbt_run_decisionnal scheduled__2024-11-10T00:00:00+00:00 [queued]>
[2025-03-28T22:56:04.917+0000] {taskinstance.py:2614} INFO - Dependencies all met for dep_context=requeueable deps ti=<TaskInstance: bank_reviews_etl_and_analysis_pipeline.dbt_run_decisionnal scheduled__2024-11-10T00:00:00+00:00 [queued]>
[2025-03-28T22:56:04.918+0000] {taskinstance.py:2867} INFO - Starting attempt 1 of 2
[2025-03-28T22:56:05.061+0000] {taskinstance.py:2890} INFO - Executing <Task(BashOperator): dbt_run_decisionnal> on 2024-11-10 00:00:00+00:00
[2025-03-28T22:56:05.151+0000] {standard_task_runner.py:72} INFO - Started process 588739 to run task
[2025-03-28T22:56:05.177+0000] {standard_task_runner.py:104} INFO - Running: ['airflow', 'tasks', 'run', 'bank_reviews_etl_and_analysis_pipeline', 'dbt_run_decisionnal', 'scheduled__2024-11-10T00:00:00+00:00', '--job-id', '2453', '--raw', '--subdir', 'DAGS_FOLDER/dag_load_reviews.py', '--cfg-path', '/tmp/tmp4dqwh3up']
[2025-03-28T22:56:05.179+0000] {standard_task_runner.py:105} INFO - Job 2453: Subtask dbt_run_decisionnal
[2025-03-28T22:56:05.734+0000] {task_command.py:467} INFO - Running <TaskInstance: bank_reviews_etl_and_analysis_pipeline.dbt_run_decisionnal scheduled__2024-11-10T00:00:00+00:00 [running]> on host DESKTOP-IM7V4RI.
[2025-03-28T22:56:06.740+0000] {taskinstance.py:3134} INFO - Exporting env vars: AIRFLOW_CTX_DAG_OWNER='mohammed' AIRFLOW_CTX_DAG_ID='bank_reviews_etl_and_analysis_pipeline' AIRFLOW_CTX_TASK_ID='dbt_run_decisionnal' AIRFLOW_CTX_EXECUTION_DATE='2024-11-10T00:00:00+00:00' AIRFLOW_CTX_TRY_NUMBER='1' AIRFLOW_CTX_DAG_RUN_ID='scheduled__2024-11-10T00:00:00+00:00'
[2025-03-28T22:56:06.753+0000] {logging_mixin.py:190} INFO - Task instance is in running state
[2025-03-28T22:56:06.754+0000] {logging_mixin.py:190} INFO -  Previous state of the Task instance: queued
[2025-03-28T22:56:06.773+0000] {logging_mixin.py:190} INFO - Current task name:dbt_run_decisionnal state:running start_date:2025-03-28 22:56:04.887564+00:00
[2025-03-28T22:56:06.774+0000] {logging_mixin.py:190} INFO - Dag name:bank_reviews_etl_and_analysis_pipeline and current dag run status:running
[2025-03-28T22:56:06.775+0000] {taskinstance.py:732} INFO - ::endgroup::
[2025-03-28T22:56:06.776+0000] {subprocess.py:78} INFO - Tmp dir root location: /tmp
[2025-03-28T22:56:06.783+0000] {subprocess.py:88} INFO - Running command: ['/usr/bin/bash', '-c', 'cd /home/mohammed/.dbt/dbt_projects/bank_reviews_decisionnal && dbt run']
[2025-03-28T22:56:06.822+0000] {subprocess.py:99} INFO - Output:
[2025-03-28T22:56:25.701+0000] {subprocess.py:106} INFO - [0m22:56:25  Running with dbt=1.9.3
[2025-03-28T22:56:27.720+0000] {subprocess.py:106} INFO - [0m22:56:27  Registered adapter: postgres=1.9.0
[2025-03-28T22:56:30.066+0000] {subprocess.py:106} INFO - [0m22:56:30  [[33mWARNING[0m]: Configuration paths exist in your dbt_project.yml file which do not apply to any resources.
[2025-03-28T22:56:30.067+0000] {subprocess.py:106} INFO - There are 1 unused configuration paths:
[2025-03-28T22:56:30.067+0000] {subprocess.py:106} INFO - - models.bank_reviews_decisionnal.decisionnal
[2025-03-28T22:56:31.619+0000] {subprocess.py:106} INFO - [0m22:56:31  Found 5 models, 2 sources, 547 macros
[2025-03-28T22:56:31.657+0000] {subprocess.py:106} INFO - [0m22:56:31
[2025-03-28T22:56:31.658+0000] {subprocess.py:106} INFO - [0m22:56:31  Concurrency: 4 threads (target='dev')
[2025-03-28T22:56:31.660+0000] {subprocess.py:106} INFO - [0m22:56:31
[2025-03-28T22:56:33.612+0000] {subprocess.py:106} INFO - [0m22:56:33  1 of 5 START sql table model decisionnal.dim_bank .............................. [RUN]
[2025-03-28T22:56:33.634+0000] {subprocess.py:106} INFO - [0m22:56:33  2 of 5 START sql table model decisionnal.dim_branch ............................ [RUN]
[2025-03-28T22:56:33.648+0000] {subprocess.py:106} INFO - [0m22:56:33  3 of 5 START sql table model decisionnal.dim_location .......................... [RUN]
[2025-03-28T22:56:33.666+0000] {subprocess.py:106} INFO - [0m22:56:33  4 of 5 START sql table model decisionnal.dim_sentiment ......................... [RUN]
[2025-03-28T22:56:35.827+0000] {subprocess.py:106} INFO - [0m22:56:35  2 of 5 OK created sql table model decisionnal.dim_branch ....................... [[32mSELECT 298[0m in 2.19s]
[2025-03-28T22:56:39.064+0000] {subprocess.py:106} INFO - [0m22:56:39  1 of 5 ERROR creating sql table model decisionnal.dim_bank ..................... [[31mERROR[0m in 5.43s]
[2025-03-28T22:56:39.071+0000] {subprocess.py:106} INFO - [0m22:56:39  3 of 5 OK created sql table model decisionnal.dim_location ..................... [[32mSELECT 298[0m in 5.42s]
[2025-03-28T22:56:39.159+0000] {subprocess.py:106} INFO - [0m22:56:39  4 of 5 OK created sql table model decisionnal.dim_sentiment .................... [[32mSELECT 2591[0m in 5.48s]
[2025-03-28T22:56:39.174+0000] {subprocess.py:106} INFO - [0m22:56:39  5 of 5 SKIP relation decisionnal.fact_reviews .................................. [[33mSKIP[0m]
[2025-03-28T22:56:39.322+0000] {subprocess.py:106} INFO - [0m22:56:39
[2025-03-28T22:56:39.324+0000] {subprocess.py:106} INFO - [0m22:56:39  Finished running 5 table models in 0 hours 0 minutes and 7.66 seconds (7.66s).
[2025-03-28T22:56:39.573+0000] {subprocess.py:106} INFO - [0m22:56:39
[2025-03-28T22:56:39.598+0000] {subprocess.py:106} INFO - [0m22:56:39  [31mCompleted with 1 error, 0 partial successes, and 0 warnings:[0m
[2025-03-28T22:56:39.600+0000] {subprocess.py:106} INFO - [0m22:56:39
[2025-03-28T22:56:39.602+0000] {subprocess.py:106} INFO - [0m22:56:39    Database Error in model dim_bank (models/dim_bank.sql)
[2025-03-28T22:56:39.603+0000] {subprocess.py:106} INFO -   relation "dim_bank__dbt_backup" already exists
[2025-03-28T22:56:39.603+0000] {subprocess.py:106} INFO -   compiled code at target/run/bank_reviews_decisionnal/models/dim_bank.sql
[2025-03-28T22:56:39.606+0000] {subprocess.py:106} INFO - [0m22:56:39
[2025-03-28T22:56:39.608+0000] {subprocess.py:106} INFO - [0m22:56:39  Done. PASS=3 WARN=0 ERROR=1 SKIP=1 TOTAL=5
[2025-03-28T22:56:42.878+0000] {subprocess.py:110} INFO - Command exited with return code 1
[2025-03-28T22:56:43.033+0000] {taskinstance.py:3313} ERROR - Task failed with exception
Traceback (most recent call last):
  File "/home/mohammed/venv/lib/python3.11/site-packages/airflow/models/taskinstance.py", line 768, in _execute_task
    result = _execute_callable(context=context, **execute_callable_kwargs)
             ^^^^^^^^^^^^^^^^^^^^^^^^^^^^^^^^^^^^^^^^^^^^^^^^^^^^^^^^^^^^^
  File "/home/mohammed/venv/lib/python3.11/site-packages/airflow/models/taskinstance.py", line 734, in _execute_callable
    return ExecutionCallableRunner(
           ^^^^^^^^^^^^^^^^^^^^^^^^
  File "/home/mohammed/venv/lib/python3.11/site-packages/airflow/utils/operator_helpers.py", line 252, in run
    return self.func(*args, **kwargs)
           ^^^^^^^^^^^^^^^^^^^^^^^^^^
  File "/home/mohammed/venv/lib/python3.11/site-packages/airflow/models/baseoperator.py", line 424, in wrapper
    return func(self, *args, **kwargs)
           ^^^^^^^^^^^^^^^^^^^^^^^^^^^
  File "/home/mohammed/venv/lib/python3.11/site-packages/airflow/operators/bash.py", line 276, in execute
    raise AirflowException(
airflow.exceptions.AirflowException: Bash command failed. The command returned a non-zero exit code 1.
[2025-03-28T22:56:43.099+0000] {logging_mixin.py:190} INFO - Task instance in failure state
[2025-03-28T22:56:43.100+0000] {logging_mixin.py:190} INFO - Task start:2025-03-28 22:56:04.887564+00:00 end:2025-03-28 22:56:43.095390+00:00 duration:38.207826
[2025-03-28T22:56:43.101+0000] {logging_mixin.py:190} INFO - Task:<Task(BashOperator): dbt_run_decisionnal> dag:<DAG: bank_reviews_etl_and_analysis_pipeline> dagrun:<DagRun bank_reviews_etl_and_analysis_pipeline @ 2024-11-10 00:00:00+00:00: scheduled__2024-11-10T00:00:00+00:00, state:running, queued_at: 2025-03-28 22:55:58.516938+00:00. externally triggered: False>
[2025-03-28T22:56:43.102+0000] {logging_mixin.py:190} INFO - Failure caused by Bash command failed. The command returned a non-zero exit code 1.
[2025-03-28T22:56:43.103+0000] {taskinstance.py:1226} INFO - Marking task as UP_FOR_RETRY. dag_id=bank_reviews_etl_and_analysis_pipeline, task_id=dbt_run_decisionnal, run_id=scheduled__2024-11-10T00:00:00+00:00, execution_date=20241110T000000, start_date=20250328T225604, end_date=20250328T225643
[2025-03-28T22:56:43.668+0000] {taskinstance.py:341} INFO - ::group::Post task execution logs
[2025-03-28T22:56:43.669+0000] {standard_task_runner.py:124} ERROR - Failed to execute job 2453 for task dbt_run_decisionnal (Bash command failed. The command returned a non-zero exit code 1.; 588739)
Traceback (most recent call last):
  File "/home/mohammed/venv/lib/python3.11/site-packages/airflow/task/task_runner/standard_task_runner.py", line 117, in _start_by_fork
    ret = args.func(args, dag=self.dag)
          ^^^^^^^^^^^^^^^^^^^^^^^^^^^^^
  File "/home/mohammed/venv/lib/python3.11/site-packages/airflow/cli/cli_config.py", line 49, in command
    return func(*args, **kwargs)
           ^^^^^^^^^^^^^^^^^^^^^
  File "/home/mohammed/venv/lib/python3.11/site-packages/airflow/utils/cli.py", line 116, in wrapper
    return f(*args, **kwargs)
           ^^^^^^^^^^^^^^^^^^
  File "/home/mohammed/venv/lib/python3.11/site-packages/airflow/cli/commands/task_command.py", line 483, in task_run
    task_return_code = _run_task_by_selected_method(args, _dag, ti)
                       ^^^^^^^^^^^^^^^^^^^^^^^^^^^^^^^^^^^^^^^^^^^^
  File "/home/mohammed/venv/lib/python3.11/site-packages/airflow/cli/commands/task_command.py", line 256, in _run_task_by_selected_method
    return _run_raw_task(args, ti)
           ^^^^^^^^^^^^^^^^^^^^^^^
  File "/home/mohammed/venv/lib/python3.11/site-packages/airflow/cli/commands/task_command.py", line 341, in _run_raw_task
    return ti._run_raw_task(
           ^^^^^^^^^^^^^^^^^
  File "/home/mohammed/venv/lib/python3.11/site-packages/airflow/utils/session.py", line 97, in wrapper
    return func(*args, session=session, **kwargs)
           ^^^^^^^^^^^^^^^^^^^^^^^^^^^^^^^^^^^^^^
  File "/home/mohammed/venv/lib/python3.11/site-packages/airflow/models/taskinstance.py", line 3006, in _run_raw_task
    return _run_raw_task(
           ^^^^^^^^^^^^^^
  File "/home/mohammed/venv/lib/python3.11/site-packages/airflow/models/taskinstance.py", line 274, in _run_raw_task
    TaskInstance._execute_task_with_callbacks(
  File "/home/mohammed/venv/lib/python3.11/site-packages/airflow/models/taskinstance.py", line 3161, in _execute_task_with_callbacks
    result = self._execute_task(context, task_orig)
             ^^^^^^^^^^^^^^^^^^^^^^^^^^^^^^^^^^^^^^
  File "/home/mohammed/venv/lib/python3.11/site-packages/airflow/models/taskinstance.py", line 3185, in _execute_task
    return _execute_task(self, context, task_orig)
           ^^^^^^^^^^^^^^^^^^^^^^^^^^^^^^^^^^^^^^^
  File "/home/mohammed/venv/lib/python3.11/site-packages/airflow/models/taskinstance.py", line 768, in _execute_task
    result = _execute_callable(context=context, **execute_callable_kwargs)
             ^^^^^^^^^^^^^^^^^^^^^^^^^^^^^^^^^^^^^^^^^^^^^^^^^^^^^^^^^^^^^
  File "/home/mohammed/venv/lib/python3.11/site-packages/airflow/models/taskinstance.py", line 734, in _execute_callable
    return ExecutionCallableRunner(
           ^^^^^^^^^^^^^^^^^^^^^^^^
  File "/home/mohammed/venv/lib/python3.11/site-packages/airflow/utils/operator_helpers.py", line 252, in run
    return self.func(*args, **kwargs)
           ^^^^^^^^^^^^^^^^^^^^^^^^^^
  File "/home/mohammed/venv/lib/python3.11/site-packages/airflow/models/baseoperator.py", line 424, in wrapper
    return func(self, *args, **kwargs)
           ^^^^^^^^^^^^^^^^^^^^^^^^^^^
  File "/home/mohammed/venv/lib/python3.11/site-packages/airflow/operators/bash.py", line 276, in execute
    raise AirflowException(
airflow.exceptions.AirflowException: Bash command failed. The command returned a non-zero exit code 1.
[2025-03-28T22:56:43.717+0000] {local_task_job_runner.py:266} INFO - Task exited with return code 1
[2025-03-28T22:56:43.793+0000] {taskinstance.py:3901} INFO - 0 downstream tasks scheduled from follow-on schedule check
[2025-03-28T22:56:43.817+0000] {local_task_job_runner.py:245} INFO - ::endgroup::
