[2025-03-17T00:23:56.541+0000] {local_task_job_runner.py:123} INFO - ::group::Pre task execution logs
[2025-03-17T00:23:56.606+0000] {taskinstance.py:2614} INFO - Dependencies all met for dep_context=non-requeueable deps ti=<TaskInstance: load_reviews_pipeline.dbt_run manual__2025-03-17T00:13:25.141677+00:00 [queued]>
[2025-03-17T00:23:56.635+0000] {taskinstance.py:2614} INFO - Dependencies all met for dep_context=requeueable deps ti=<TaskInstance: load_reviews_pipeline.dbt_run manual__2025-03-17T00:13:25.141677+00:00 [queued]>
[2025-03-17T00:23:56.635+0000] {taskinstance.py:2867} INFO - Starting attempt 2 of 2
[2025-03-17T00:23:56.673+0000] {taskinstance.py:2890} INFO - Executing <Task(BashOperator): dbt_run> on 2025-03-17 00:13:25.141677+00:00
[2025-03-17T00:23:56.683+0000] {standard_task_runner.py:72} INFO - Started process 257668 to run task
[2025-03-17T00:23:56.688+0000] {standard_task_runner.py:104} INFO - Running: ['airflow', 'tasks', 'run', 'load_reviews_pipeline', 'dbt_run', 'manual__2025-03-17T00:13:25.141677+00:00', '--job-id', '195', '--raw', '--subdir', 'DAGS_FOLDER/dag_load_reviews.py', '--cfg-path', '/tmp/tmp6we1xxfe']
[2025-03-17T00:23:56.689+0000] {standard_task_runner.py:105} INFO - Job 195: Subtask dbt_run
[2025-03-17T00:23:56.778+0000] {task_command.py:467} INFO - Running <TaskInstance: load_reviews_pipeline.dbt_run manual__2025-03-17T00:13:25.141677+00:00 [running]> on host DESKTOP-IM7V4RI.
[2025-03-17T00:23:57.018+0000] {taskinstance.py:3134} INFO - Exporting env vars: AIRFLOW_CTX_DAG_OWNER='mohammed' AIRFLOW_CTX_DAG_ID='load_reviews_pipeline' AIRFLOW_CTX_TASK_ID='dbt_run' AIRFLOW_CTX_EXECUTION_DATE='2025-03-17T00:13:25.141677+00:00' AIRFLOW_CTX_TRY_NUMBER='2' AIRFLOW_CTX_DAG_RUN_ID='manual__2025-03-17T00:13:25.141677+00:00'
[2025-03-17T00:23:57.029+0000] {logging_mixin.py:190} INFO - Task instance is in running state
[2025-03-17T00:23:57.030+0000] {logging_mixin.py:190} INFO -  Previous state of the Task instance: queued
[2025-03-17T00:23:57.030+0000] {logging_mixin.py:190} INFO - Current task name:dbt_run state:running start_date:2025-03-17 00:23:56.607028+00:00
[2025-03-17T00:23:57.030+0000] {logging_mixin.py:190} INFO - Dag name:load_reviews_pipeline and current dag run status:running
[2025-03-17T00:23:57.031+0000] {taskinstance.py:732} INFO - ::endgroup::
[2025-03-17T00:23:57.037+0000] {subprocess.py:78} INFO - Tmp dir root location: /tmp
[2025-03-17T00:23:57.044+0000] {subprocess.py:88} INFO - Running command: ['/usr/bin/bash', '-c', 'cd /home/mohammed/.dbt/bank_reviews_project && dbt run']
[2025-03-17T00:23:57.070+0000] {subprocess.py:99} INFO - Output:
[2025-03-17T00:24:00.670+0000] {subprocess.py:106} INFO - [0m00:24:00  Running with dbt=1.9.3
[2025-03-17T00:24:01.000+0000] {subprocess.py:106} INFO - [0m00:24:01  Registered adapter: postgres=1.9.0
[2025-03-17T00:24:01.759+0000] {subprocess.py:106} INFO - [0m00:24:01  Found 6 models, 4 data tests, 2 sources, 433 macros
[2025-03-17T00:24:01.762+0000] {subprocess.py:106} INFO - [0m00:24:01
[2025-03-17T00:24:01.762+0000] {subprocess.py:106} INFO - [0m00:24:01  Concurrency: 4 threads (target='dev')
[2025-03-17T00:24:01.762+0000] {subprocess.py:106} INFO - [0m00:24:01
[2025-03-17T00:24:01.928+0000] {subprocess.py:106} INFO - [0m00:24:01  1 of 6 START sql view model public.clean_reviews ............................... [RUN]
[2025-03-17T00:24:01.929+0000] {subprocess.py:106} INFO - [0m00:24:01  2 of 6 START sql table model public.my_first_dbt_model ......................... [RUN]
[2025-03-17T00:24:01.933+0000] {subprocess.py:106} INFO - [0m00:24:01  3 of 6 START sql view model public.remove_duplicates ........................... [RUN]
[2025-03-17T00:24:01.934+0000] {subprocess.py:106} INFO - [0m00:24:01  4 of 6 START sql view model public.stg_clean_reviews ........................... [RUN]
[2025-03-17T00:24:02.323+0000] {subprocess.py:106} INFO - [0m00:24:02  4 of 6 OK created sql view model public.stg_clean_reviews ...................... [[32mCREATE VIEW[0m in 0.37s]
[2025-03-17T00:24:02.346+0000] {subprocess.py:106} INFO - [0m00:24:02  5 of 6 START sql view model public.dwh_model ................................... [RUN]
[2025-03-17T00:24:02.381+0000] {subprocess.py:106} INFO - [0m00:24:02  3 of 6 OK created sql view model public.remove_duplicates ...................... [[32mCREATE VIEW[0m in 0.43s]
[2025-03-17T00:24:02.382+0000] {subprocess.py:106} INFO - [0m00:24:02  1 of 6 OK created sql view model public.clean_reviews .......................... [[32mCREATE VIEW[0m in 0.44s]
[2025-03-17T00:24:02.389+0000] {subprocess.py:106} INFO - [0m00:24:02  2 of 6 OK created sql table model public.my_first_dbt_model .................... [[32mSELECT 2[0m in 0.45s]
[2025-03-17T00:24:02.397+0000] {subprocess.py:106} INFO - [0m00:24:02  6 of 6 START sql view model public.my_second_dbt_model ......................... [RUN]
[2025-03-17T00:24:02.448+0000] {subprocess.py:106} INFO - [0m00:24:02  5 of 6 ERROR creating sql view model public.dwh_model .......................... [[31mERROR[0m in 0.10s]
[2025-03-17T00:24:02.519+0000] {subprocess.py:106} INFO - [0m00:24:02  6 of 6 OK created sql view model public.my_second_dbt_model .................... [[32mCREATE VIEW[0m in 0.12s]
[2025-03-17T00:24:02.553+0000] {subprocess.py:106} INFO - [0m00:24:02
[2025-03-17T00:24:02.554+0000] {subprocess.py:106} INFO - [0m00:24:02  Finished running 1 table model, 5 view models in 0 hours 0 minutes and 0.79 seconds (0.79s).
[2025-03-17T00:24:02.611+0000] {subprocess.py:106} INFO - [0m00:24:02
[2025-03-17T00:24:02.612+0000] {subprocess.py:106} INFO - [0m00:24:02  [31mCompleted with 1 error, 0 partial successes, and 0 warnings:[0m
[2025-03-17T00:24:02.612+0000] {subprocess.py:106} INFO - [0m00:24:02
[2025-03-17T00:24:02.613+0000] {subprocess.py:106} INFO - [0m00:24:02    Database Error in model dwh_model (models/dwh_model.sql)
[2025-03-17T00:24:02.613+0000] {subprocess.py:106} INFO -   syntax error at or near ";"
[2025-03-17T00:24:02.613+0000] {subprocess.py:106} INFO -   LINE 52: SELECT * FROM fact_reviews;
[2025-03-17T00:24:02.614+0000] {subprocess.py:106} INFO -                                      ^
[2025-03-17T00:24:02.614+0000] {subprocess.py:106} INFO -   compiled code at target/run/bank_reviews_project/models/dwh_model.sql
[2025-03-17T00:24:02.614+0000] {subprocess.py:106} INFO - [0m00:24:02
[2025-03-17T00:24:02.614+0000] {subprocess.py:106} INFO - [0m00:24:02  Done. PASS=5 WARN=0 ERROR=1 SKIP=0 TOTAL=6
[2025-03-17T00:24:06.201+0000] {subprocess.py:110} INFO - Command exited with return code 1
[2025-03-17T00:24:06.227+0000] {taskinstance.py:3313} ERROR - Task failed with exception
Traceback (most recent call last):
  File "/home/mohammed/venv/lib/python3.11/site-packages/airflow/models/taskinstance.py", line 768, in _execute_task
    result = _execute_callable(context=context, **execute_callable_kwargs)
             ^^^^^^^^^^^^^^^^^^^^^^^^^^^^^^^^^^^^^^^^^^^^^^^^^^^^^^^^^^^^^
  File "/home/mohammed/venv/lib/python3.11/site-packages/airflow/models/taskinstance.py", line 734, in _execute_callable
    return ExecutionCallableRunner(
           ^^^^^^^^^^^^^^^^^^^^^^^^
  File "/home/mohammed/venv/lib/python3.11/site-packages/airflow/utils/operator_helpers.py", line 252, in run
    return self.func(*args, **kwargs)
           ^^^^^^^^^^^^^^^^^^^^^^^^^^
  File "/home/mohammed/venv/lib/python3.11/site-packages/airflow/models/baseoperator.py", line 424, in wrapper
    return func(self, *args, **kwargs)
           ^^^^^^^^^^^^^^^^^^^^^^^^^^^
  File "/home/mohammed/venv/lib/python3.11/site-packages/airflow/operators/bash.py", line 276, in execute
    raise AirflowException(
airflow.exceptions.AirflowException: Bash command failed. The command returned a non-zero exit code 1.
[2025-03-17T00:24:06.234+0000] {logging_mixin.py:190} INFO - Task instance in failure state
[2025-03-17T00:24:06.234+0000] {logging_mixin.py:190} INFO - Task start:2025-03-17 00:23:56.607028+00:00 end:2025-03-17 00:24:06.233008+00:00 duration:9.62598
[2025-03-17T00:24:06.235+0000] {logging_mixin.py:190} INFO - Task:<Task(BashOperator): dbt_run> dag:<DAG: load_reviews_pipeline> dagrun:<DagRun load_reviews_pipeline @ 2025-03-17 00:13:25.141677+00:00: manual__2025-03-17T00:13:25.141677+00:00, state:running, queued_at: 2025-03-17 00:13:25.552819+00:00. externally triggered: True>
[2025-03-17T00:24:06.235+0000] {logging_mixin.py:190} INFO - Failure caused by Bash command failed. The command returned a non-zero exit code 1.
[2025-03-17T00:24:06.235+0000] {taskinstance.py:1226} INFO - Marking task as FAILED. dag_id=load_reviews_pipeline, task_id=dbt_run, run_id=manual__2025-03-17T00:13:25.141677+00:00, execution_date=20250317T001325, start_date=20250317T002356, end_date=20250317T002406
[2025-03-17T00:24:06.305+0000] {taskinstance.py:341} INFO - ::group::Post task execution logs
[2025-03-17T00:24:06.306+0000] {standard_task_runner.py:124} ERROR - Failed to execute job 195 for task dbt_run (Bash command failed. The command returned a non-zero exit code 1.; 257668)
Traceback (most recent call last):
  File "/home/mohammed/venv/lib/python3.11/site-packages/airflow/task/task_runner/standard_task_runner.py", line 117, in _start_by_fork
    ret = args.func(args, dag=self.dag)
          ^^^^^^^^^^^^^^^^^^^^^^^^^^^^^
  File "/home/mohammed/venv/lib/python3.11/site-packages/airflow/cli/cli_config.py", line 49, in command
    return func(*args, **kwargs)
           ^^^^^^^^^^^^^^^^^^^^^
  File "/home/mohammed/venv/lib/python3.11/site-packages/airflow/utils/cli.py", line 116, in wrapper
    return f(*args, **kwargs)
           ^^^^^^^^^^^^^^^^^^
  File "/home/mohammed/venv/lib/python3.11/site-packages/airflow/cli/commands/task_command.py", line 483, in task_run
    task_return_code = _run_task_by_selected_method(args, _dag, ti)
                       ^^^^^^^^^^^^^^^^^^^^^^^^^^^^^^^^^^^^^^^^^^^^
  File "/home/mohammed/venv/lib/python3.11/site-packages/airflow/cli/commands/task_command.py", line 256, in _run_task_by_selected_method
    return _run_raw_task(args, ti)
           ^^^^^^^^^^^^^^^^^^^^^^^
  File "/home/mohammed/venv/lib/python3.11/site-packages/airflow/cli/commands/task_command.py", line 341, in _run_raw_task
    return ti._run_raw_task(
           ^^^^^^^^^^^^^^^^^
  File "/home/mohammed/venv/lib/python3.11/site-packages/airflow/utils/session.py", line 97, in wrapper
    return func(*args, session=session, **kwargs)
           ^^^^^^^^^^^^^^^^^^^^^^^^^^^^^^^^^^^^^^
  File "/home/mohammed/venv/lib/python3.11/site-packages/airflow/models/taskinstance.py", line 3006, in _run_raw_task
    return _run_raw_task(
           ^^^^^^^^^^^^^^
  File "/home/mohammed/venv/lib/python3.11/site-packages/airflow/models/taskinstance.py", line 274, in _run_raw_task
    TaskInstance._execute_task_with_callbacks(
  File "/home/mohammed/venv/lib/python3.11/site-packages/airflow/models/taskinstance.py", line 3161, in _execute_task_with_callbacks
    result = self._execute_task(context, task_orig)
             ^^^^^^^^^^^^^^^^^^^^^^^^^^^^^^^^^^^^^^
  File "/home/mohammed/venv/lib/python3.11/site-packages/airflow/models/taskinstance.py", line 3185, in _execute_task
    return _execute_task(self, context, task_orig)
           ^^^^^^^^^^^^^^^^^^^^^^^^^^^^^^^^^^^^^^^
  File "/home/mohammed/venv/lib/python3.11/site-packages/airflow/models/taskinstance.py", line 768, in _execute_task
    result = _execute_callable(context=context, **execute_callable_kwargs)
             ^^^^^^^^^^^^^^^^^^^^^^^^^^^^^^^^^^^^^^^^^^^^^^^^^^^^^^^^^^^^^
  File "/home/mohammed/venv/lib/python3.11/site-packages/airflow/models/taskinstance.py", line 734, in _execute_callable
    return ExecutionCallableRunner(
           ^^^^^^^^^^^^^^^^^^^^^^^^
  File "/home/mohammed/venv/lib/python3.11/site-packages/airflow/utils/operator_helpers.py", line 252, in run
    return self.func(*args, **kwargs)
           ^^^^^^^^^^^^^^^^^^^^^^^^^^
  File "/home/mohammed/venv/lib/python3.11/site-packages/airflow/models/baseoperator.py", line 424, in wrapper
    return func(self, *args, **kwargs)
           ^^^^^^^^^^^^^^^^^^^^^^^^^^^
  File "/home/mohammed/venv/lib/python3.11/site-packages/airflow/operators/bash.py", line 276, in execute
    raise AirflowException(
airflow.exceptions.AirflowException: Bash command failed. The command returned a non-zero exit code 1.
[2025-03-17T00:24:06.330+0000] {local_task_job_runner.py:266} INFO - Task exited with return code 1
[2025-03-17T00:24:06.354+0000] {taskinstance.py:3901} INFO - 0 downstream tasks scheduled from follow-on schedule check
[2025-03-17T00:24:06.360+0000] {local_task_job_runner.py:245} INFO - ::endgroup::
