[2025-03-28T22:40:32.705+0000] {local_task_job_runner.py:123} INFO - ::group::Pre task execution logs
[2025-03-28T22:40:38.326+0000] {taskinstance.py:2614} INFO - Dependencies all met for dep_context=non-requeueable deps ti=<TaskInstance: bank_reviews_etl_and_analysis_pipeline.dbt_run_decisionnal scheduled__2024-06-09T00:00:00+00:00 [queued]>
[2025-03-28T22:40:39.058+0000] {taskinstance.py:2614} INFO - Dependencies all met for dep_context=requeueable deps ti=<TaskInstance: bank_reviews_etl_and_analysis_pipeline.dbt_run_decisionnal scheduled__2024-06-09T00:00:00+00:00 [queued]>
[2025-03-28T22:40:39.059+0000] {taskinstance.py:2867} INFO - Starting attempt 1 of 2
[2025-03-28T22:40:41.576+0000] {taskinstance.py:2890} INFO - Executing <Task(BashOperator): dbt_run_decisionnal> on 2024-06-09 00:00:00+00:00
[2025-03-28T22:40:44.547+0000] {standard_task_runner.py:72} INFO - Started process 573721 to run task
[2025-03-28T22:40:47.742+0000] {standard_task_runner.py:104} INFO - Running: ['airflow', 'tasks', 'run', 'bank_reviews_etl_and_analysis_pipeline', 'dbt_run_decisionnal', 'scheduled__2024-06-09T00:00:00+00:00', '--job-id', '2399', '--raw', '--subdir', 'DAGS_FOLDER/dag_load_reviews.py', '--cfg-path', '/tmp/tmpcn0as3rm']
[2025-03-28T22:40:48.270+0000] {standard_task_runner.py:105} INFO - Job 2399: Subtask dbt_run_decisionnal
[2025-03-28T22:40:57.005+0000] {job.py:229} INFO - Heartbeat recovered after 36.36 seconds
[2025-03-28T22:41:01.586+0000] {task_command.py:467} INFO - Running <TaskInstance: bank_reviews_etl_and_analysis_pipeline.dbt_run_decisionnal scheduled__2024-06-09T00:00:00+00:00 [running]> on host DESKTOP-IM7V4RI.
[2025-03-28T22:41:06.202+0000] {taskinstance.py:3134} INFO - Exporting env vars: AIRFLOW_CTX_DAG_OWNER='mohammed' AIRFLOW_CTX_DAG_ID='bank_reviews_etl_and_analysis_pipeline' AIRFLOW_CTX_TASK_ID='dbt_run_decisionnal' AIRFLOW_CTX_EXECUTION_DATE='2024-06-09T00:00:00+00:00' AIRFLOW_CTX_TRY_NUMBER='1' AIRFLOW_CTX_DAG_RUN_ID='scheduled__2024-06-09T00:00:00+00:00'
[2025-03-28T22:41:06.475+0000] {logging_mixin.py:190} INFO - Task instance is in running state
[2025-03-28T22:41:06.476+0000] {logging_mixin.py:190} INFO -  Previous state of the Task instance: queued
[2025-03-28T22:41:06.477+0000] {logging_mixin.py:190} INFO - Current task name:dbt_run_decisionnal state:running start_date:2025-03-28 22:40:38.416984+00:00
[2025-03-28T22:41:06.478+0000] {logging_mixin.py:190} INFO - Dag name:bank_reviews_etl_and_analysis_pipeline and current dag run status:running
[2025-03-28T22:41:06.479+0000] {taskinstance.py:732} INFO - ::endgroup::
[2025-03-28T22:41:06.938+0000] {subprocess.py:78} INFO - Tmp dir root location: /tmp
[2025-03-28T22:41:07.014+0000] {subprocess.py:88} INFO - Running command: ['/usr/bin/bash', '-c', 'cd /home/mohammed/.dbt/dbt_projects/bank_reviews_decisionnal && dbt run']
[2025-03-28T22:41:07.176+0000] {subprocess.py:99} INFO - Output:
[2025-03-28T22:41:24.283+0000] {job.py:229} INFO - Heartbeat recovered after 11.02 seconds
[2025-03-28T22:42:11.185+0000] {job.py:229} INFO - Heartbeat recovered after 12.89 seconds
[2025-03-28T22:42:40.357+0000] {subprocess.py:106} INFO - [0m22:42:40  Running with dbt=1.9.3
[2025-03-28T22:42:47.795+0000] {subprocess.py:106} INFO - [0m22:42:47  Registered adapter: postgres=1.9.0
[2025-03-28T22:42:51.667+0000] {subprocess.py:106} INFO - [0m22:42:51  [[33mWARNING[0m]: Configuration paths exist in your dbt_project.yml file which do not apply to any resources.
[2025-03-28T22:42:51.712+0000] {subprocess.py:106} INFO - There are 1 unused configuration paths:
[2025-03-28T22:42:51.714+0000] {subprocess.py:106} INFO - - models.bank_reviews_decisionnal.decisionnal
[2025-03-28T22:42:54.947+0000] {subprocess.py:106} INFO - [0m22:42:54  Found 5 models, 2 sources, 547 macros
[2025-03-28T22:42:55.000+0000] {subprocess.py:106} INFO - [0m22:42:55
[2025-03-28T22:42:55.004+0000] {subprocess.py:106} INFO - [0m22:42:55  Concurrency: 4 threads (target='dev')
[2025-03-28T22:42:55.005+0000] {subprocess.py:106} INFO - [0m22:42:55
[2025-03-28T22:43:08.465+0000] {job.py:229} INFO - Heartbeat recovered after 14.43 seconds
[2025-03-28T22:43:09.078+0000] {subprocess.py:106} INFO - [0m22:43:09  1 of 5 START sql view model decisionnal.dim_bank ............................... [RUN]
[2025-03-28T22:43:09.088+0000] {subprocess.py:106} INFO - [0m22:43:09  2 of 5 START sql view model decisionnal.dim_branch ............................. [RUN]
[2025-03-28T22:43:09.089+0000] {subprocess.py:106} INFO - [0m22:43:09  3 of 5 START sql view model decisionnal.dim_location ........................... [RUN]
[2025-03-28T22:43:09.091+0000] {subprocess.py:106} INFO - [0m22:43:09  4 of 5 START sql view model decisionnal.dim_sentiment .......................... [RUN]
[2025-03-28T22:43:41.366+0000] {job.py:229} INFO - Heartbeat recovered after 32.94 seconds
[2025-03-28T22:43:42.364+0000] {subprocess.py:106} INFO - [0m22:43:42  1 of 5 OK created sql view model decisionnal.dim_bank .......................... [[32mCREATE VIEW[0m in 33.16s]
[2025-03-28T22:43:45.989+0000] {subprocess.py:106} INFO - [0m22:43:45  3 of 5 ERROR creating sql view model decisionnal.dim_location .................. [[31mERROR[0m in 36.88s]
[2025-03-28T22:43:47.437+0000] {subprocess.py:106} INFO - [0m22:43:47  4 of 5 ERROR creating sql view model decisionnal.dim_sentiment ................. [[31mERROR[0m in 38.32s]
[2025-03-28T22:43:47.820+0000] {subprocess.py:106} INFO - [0m22:43:47  2 of 5 ERROR creating sql view model decisionnal.dim_branch .................... [[31mERROR[0m in 38.66s]
[2025-03-28T22:43:47.830+0000] {subprocess.py:106} INFO - [0m22:43:47  5 of 5 SKIP relation decisionnal.fact_reviews .................................. [[33mSKIP[0m]
[2025-03-28T22:43:47.941+0000] {subprocess.py:106} INFO - [0m22:43:47
[2025-03-28T22:43:47.943+0000] {subprocess.py:106} INFO - [0m22:43:47  Finished running 5 view models in 0 hours 0 minutes and 52.93 seconds (52.93s).
[2025-03-28T22:43:48.105+0000] {subprocess.py:106} INFO - [0m22:43:48
[2025-03-28T22:43:48.108+0000] {subprocess.py:106} INFO - [0m22:43:48  [31mCompleted with 3 errors, 0 partial successes, and 0 warnings:[0m
[2025-03-28T22:43:48.110+0000] {subprocess.py:106} INFO - [0m22:43:48
[2025-03-28T22:43:48.111+0000] {subprocess.py:106} INFO - [0m22:43:48    Database Error in model dim_location (models/dim_location.sql)
[2025-03-28T22:43:48.111+0000] {subprocess.py:106} INFO -   relation "dim_location" already exists
[2025-03-28T22:43:48.112+0000] {subprocess.py:106} INFO -   compiled code at target/run/bank_reviews_decisionnal/models/dim_location.sql
[2025-03-28T22:43:48.113+0000] {subprocess.py:106} INFO - [0m22:43:48
[2025-03-28T22:43:48.116+0000] {subprocess.py:106} INFO - [0m22:43:48    Database Error in model dim_sentiment (models/dim_sentiment.sql)
[2025-03-28T22:43:48.116+0000] {subprocess.py:106} INFO -   relation "dim_sentiment" already exists
[2025-03-28T22:43:48.117+0000] {subprocess.py:106} INFO -   compiled code at target/run/bank_reviews_decisionnal/models/dim_sentiment.sql
[2025-03-28T22:43:48.117+0000] {subprocess.py:106} INFO - [0m22:43:48
[2025-03-28T22:43:48.123+0000] {subprocess.py:106} INFO - [0m22:43:48    Database Error in model dim_branch (models/dim_branch.sql)
[2025-03-28T22:43:48.123+0000] {subprocess.py:106} INFO -   relation "dim_branch" already exists
[2025-03-28T22:43:48.124+0000] {subprocess.py:106} INFO -   compiled code at target/run/bank_reviews_decisionnal/models/dim_branch.sql
[2025-03-28T22:43:48.124+0000] {subprocess.py:106} INFO - [0m22:43:48
[2025-03-28T22:43:48.127+0000] {subprocess.py:106} INFO - [0m22:43:48  Done. PASS=1 WARN=0 ERROR=3 SKIP=1 TOTAL=5
[2025-03-28T22:43:52.132+0000] {subprocess.py:110} INFO - Command exited with return code 1
[2025-03-28T22:43:53.751+0000] {taskinstance.py:3313} ERROR - Task failed with exception
Traceback (most recent call last):
  File "/home/mohammed/venv/lib/python3.11/site-packages/airflow/models/taskinstance.py", line 768, in _execute_task
    result = _execute_callable(context=context, **execute_callable_kwargs)
             ^^^^^^^^^^^^^^^^^^^^^^^^^^^^^^^^^^^^^^^^^^^^^^^^^^^^^^^^^^^^^
  File "/home/mohammed/venv/lib/python3.11/site-packages/airflow/models/taskinstance.py", line 734, in _execute_callable
    return ExecutionCallableRunner(
           ^^^^^^^^^^^^^^^^^^^^^^^^
  File "/home/mohammed/venv/lib/python3.11/site-packages/airflow/utils/operator_helpers.py", line 252, in run
    return self.func(*args, **kwargs)
           ^^^^^^^^^^^^^^^^^^^^^^^^^^
  File "/home/mohammed/venv/lib/python3.11/site-packages/airflow/models/baseoperator.py", line 424, in wrapper
    return func(self, *args, **kwargs)
           ^^^^^^^^^^^^^^^^^^^^^^^^^^^
  File "/home/mohammed/venv/lib/python3.11/site-packages/airflow/operators/bash.py", line 276, in execute
    raise AirflowException(
airflow.exceptions.AirflowException: Bash command failed. The command returned a non-zero exit code 1.
[2025-03-28T22:43:54.387+0000] {logging_mixin.py:190} INFO - Task instance in failure state
[2025-03-28T22:43:54.391+0000] {logging_mixin.py:190} INFO - Task start:2025-03-28 22:40:38.416984+00:00 end:2025-03-28 22:43:54.259801+00:00 duration:195.842817
[2025-03-28T22:43:54.434+0000] {logging_mixin.py:190} INFO - Task:<Task(BashOperator): dbt_run_decisionnal> dag:<DAG: bank_reviews_etl_and_analysis_pipeline> dagrun:<DagRun bank_reviews_etl_and_analysis_pipeline @ 2024-06-09 00:00:00+00:00: scheduled__2024-06-09T00:00:00+00:00, state:running, queued_at: 2025-03-28 22:40:01.327771+00:00. externally triggered: False>
[2025-03-28T22:43:54.466+0000] {logging_mixin.py:190} INFO - Failure caused by Bash command failed. The command returned a non-zero exit code 1.
[2025-03-28T22:43:54.469+0000] {taskinstance.py:1226} INFO - Marking task as UP_FOR_RETRY. dag_id=bank_reviews_etl_and_analysis_pipeline, task_id=dbt_run_decisionnal, run_id=scheduled__2024-06-09T00:00:00+00:00, execution_date=20240609T000000, start_date=20250328T224038, end_date=20250328T224354
[2025-03-28T22:43:55.623+0000] {taskinstance.py:341} INFO - ::group::Post task execution logs
[2025-03-28T22:43:55.729+0000] {standard_task_runner.py:124} ERROR - Failed to execute job 2399 for task dbt_run_decisionnal (Bash command failed. The command returned a non-zero exit code 1.; 573721)
Traceback (most recent call last):
  File "/home/mohammed/venv/lib/python3.11/site-packages/airflow/task/task_runner/standard_task_runner.py", line 117, in _start_by_fork
    ret = args.func(args, dag=self.dag)
          ^^^^^^^^^^^^^^^^^^^^^^^^^^^^^
  File "/home/mohammed/venv/lib/python3.11/site-packages/airflow/cli/cli_config.py", line 49, in command
    return func(*args, **kwargs)
           ^^^^^^^^^^^^^^^^^^^^^
  File "/home/mohammed/venv/lib/python3.11/site-packages/airflow/utils/cli.py", line 116, in wrapper
    return f(*args, **kwargs)
           ^^^^^^^^^^^^^^^^^^
  File "/home/mohammed/venv/lib/python3.11/site-packages/airflow/cli/commands/task_command.py", line 483, in task_run
    task_return_code = _run_task_by_selected_method(args, _dag, ti)
                       ^^^^^^^^^^^^^^^^^^^^^^^^^^^^^^^^^^^^^^^^^^^^
  File "/home/mohammed/venv/lib/python3.11/site-packages/airflow/cli/commands/task_command.py", line 256, in _run_task_by_selected_method
    return _run_raw_task(args, ti)
           ^^^^^^^^^^^^^^^^^^^^^^^
  File "/home/mohammed/venv/lib/python3.11/site-packages/airflow/cli/commands/task_command.py", line 341, in _run_raw_task
    return ti._run_raw_task(
           ^^^^^^^^^^^^^^^^^
  File "/home/mohammed/venv/lib/python3.11/site-packages/airflow/utils/session.py", line 97, in wrapper
    return func(*args, session=session, **kwargs)
           ^^^^^^^^^^^^^^^^^^^^^^^^^^^^^^^^^^^^^^
  File "/home/mohammed/venv/lib/python3.11/site-packages/airflow/models/taskinstance.py", line 3006, in _run_raw_task
    return _run_raw_task(
           ^^^^^^^^^^^^^^
  File "/home/mohammed/venv/lib/python3.11/site-packages/airflow/models/taskinstance.py", line 274, in _run_raw_task
    TaskInstance._execute_task_with_callbacks(
  File "/home/mohammed/venv/lib/python3.11/site-packages/airflow/models/taskinstance.py", line 3161, in _execute_task_with_callbacks
    result = self._execute_task(context, task_orig)
             ^^^^^^^^^^^^^^^^^^^^^^^^^^^^^^^^^^^^^^
  File "/home/mohammed/venv/lib/python3.11/site-packages/airflow/models/taskinstance.py", line 3185, in _execute_task
    return _execute_task(self, context, task_orig)
           ^^^^^^^^^^^^^^^^^^^^^^^^^^^^^^^^^^^^^^^
  File "/home/mohammed/venv/lib/python3.11/site-packages/airflow/models/taskinstance.py", line 768, in _execute_task
    result = _execute_callable(context=context, **execute_callable_kwargs)
             ^^^^^^^^^^^^^^^^^^^^^^^^^^^^^^^^^^^^^^^^^^^^^^^^^^^^^^^^^^^^^
  File "/home/mohammed/venv/lib/python3.11/site-packages/airflow/models/taskinstance.py", line 734, in _execute_callable
    return ExecutionCallableRunner(
           ^^^^^^^^^^^^^^^^^^^^^^^^
  File "/home/mohammed/venv/lib/python3.11/site-packages/airflow/utils/operator_helpers.py", line 252, in run
    return self.func(*args, **kwargs)
           ^^^^^^^^^^^^^^^^^^^^^^^^^^
  File "/home/mohammed/venv/lib/python3.11/site-packages/airflow/models/baseoperator.py", line 424, in wrapper
    return func(self, *args, **kwargs)
           ^^^^^^^^^^^^^^^^^^^^^^^^^^^
  File "/home/mohammed/venv/lib/python3.11/site-packages/airflow/operators/bash.py", line 276, in execute
    raise AirflowException(
airflow.exceptions.AirflowException: Bash command failed. The command returned a non-zero exit code 1.
[2025-03-28T22:43:55.934+0000] {local_task_job_runner.py:266} INFO - Task exited with return code 1
[2025-03-28T22:43:57.186+0000] {taskinstance.py:3901} INFO - 0 downstream tasks scheduled from follow-on schedule check
[2025-03-28T22:43:57.228+0000] {local_task_job_runner.py:245} INFO - ::endgroup::
