[2025-03-29T01:47:06.885+0000] {local_task_job_runner.py:123} INFO - ::group::Pre task execution logs
[2025-03-29T01:47:06.931+0000] {taskinstance.py:2614} INFO - Dependencies all met for dep_context=non-requeueable deps ti=<TaskInstance: bank_reviews_etl_and_analysis_pipeline.dbt_run_decisionnal manual__2025-03-29T01:47:02.953474+00:00 [queued]>
[2025-03-29T01:47:06.949+0000] {taskinstance.py:2614} INFO - Dependencies all met for dep_context=requeueable deps ti=<TaskInstance: bank_reviews_etl_and_analysis_pipeline.dbt_run_decisionnal manual__2025-03-29T01:47:02.953474+00:00 [queued]>
[2025-03-29T01:47:06.949+0000] {taskinstance.py:2867} INFO - Starting attempt 1 of 2
[2025-03-29T01:47:06.980+0000] {taskinstance.py:2890} INFO - Executing <Task(BashOperator): dbt_run_decisionnal> on 2025-03-29 01:47:02.953474+00:00
[2025-03-29T01:47:06.997+0000] {standard_task_runner.py:72} INFO - Started process 672534 to run task
[2025-03-29T01:47:07.004+0000] {standard_task_runner.py:104} INFO - Running: ['airflow', 'tasks', 'run', 'bank_reviews_etl_and_analysis_pipeline', 'dbt_run_decisionnal', 'manual__2025-03-29T01:47:02.953474+00:00', '--job-id', '2492', '--raw', '--subdir', 'DAGS_FOLDER/dag_load_reviews.py', '--cfg-path', '/tmp/tmptx80elop']
[2025-03-29T01:47:07.006+0000] {standard_task_runner.py:105} INFO - Job 2492: Subtask dbt_run_decisionnal
[2025-03-29T01:47:07.147+0000] {task_command.py:467} INFO - Running <TaskInstance: bank_reviews_etl_and_analysis_pipeline.dbt_run_decisionnal manual__2025-03-29T01:47:02.953474+00:00 [running]> on host DESKTOP-IM7V4RI.
[2025-03-29T01:47:07.384+0000] {taskinstance.py:3134} INFO - Exporting env vars: AIRFLOW_CTX_DAG_OWNER='mohammed' AIRFLOW_CTX_DAG_ID='bank_reviews_etl_and_analysis_pipeline' AIRFLOW_CTX_TASK_ID='dbt_run_decisionnal' AIRFLOW_CTX_EXECUTION_DATE='2025-03-29T01:47:02.953474+00:00' AIRFLOW_CTX_TRY_NUMBER='1' AIRFLOW_CTX_DAG_RUN_ID='manual__2025-03-29T01:47:02.953474+00:00'
[2025-03-29T01:47:07.386+0000] {logging_mixin.py:190} INFO - Task instance is in running state
[2025-03-29T01:47:07.387+0000] {logging_mixin.py:190} INFO -  Previous state of the Task instance: queued
[2025-03-29T01:47:07.387+0000] {logging_mixin.py:190} INFO - Current task name:dbt_run_decisionnal state:running start_date:2025-03-29 01:47:06.932427+00:00
[2025-03-29T01:47:07.388+0000] {logging_mixin.py:190} INFO - Dag name:bank_reviews_etl_and_analysis_pipeline and current dag run status:running
[2025-03-29T01:47:07.389+0000] {taskinstance.py:732} INFO - ::endgroup::
[2025-03-29T01:47:07.391+0000] {subprocess.py:78} INFO - Tmp dir root location: /tmp
[2025-03-29T01:47:07.394+0000] {subprocess.py:88} INFO - Running command: ['/usr/bin/bash', '-c', 'cd /home/mohammed/.dbt/dbt_projects/bank_reviews_decisionnal && dbt run --full-refresh']
[2025-03-29T01:47:07.435+0000] {subprocess.py:99} INFO - Output:
[2025-03-29T01:47:11.024+0000] {subprocess.py:106} INFO - [0m01:47:11  Running with dbt=1.9.3
[2025-03-29T01:47:11.540+0000] {subprocess.py:106} INFO - [0m01:47:11  Registered adapter: postgres=1.9.0
[2025-03-29T01:47:12.381+0000] {subprocess.py:106} INFO - [0m01:47:12  [[33mWARNING[0m]: Configuration paths exist in your dbt_project.yml file which do not apply to any resources.
[2025-03-29T01:47:12.381+0000] {subprocess.py:106} INFO - There are 1 unused configuration paths:
[2025-03-29T01:47:12.382+0000] {subprocess.py:106} INFO - - models.bank_reviews_decisionnal.decisionnal
[2025-03-29T01:47:12.585+0000] {subprocess.py:106} INFO - [0m01:47:12  Found 5 models, 2 sources, 547 macros
[2025-03-29T01:47:12.589+0000] {subprocess.py:106} INFO - [0m01:47:12
[2025-03-29T01:47:12.590+0000] {subprocess.py:106} INFO - [0m01:47:12  Concurrency: 4 threads (target='dev')
[2025-03-29T01:47:12.591+0000] {subprocess.py:106} INFO - [0m01:47:12
[2025-03-29T01:47:12.933+0000] {subprocess.py:106} INFO - [0m01:47:12  1 of 5 START sql table model decisionnal.dim_bank .............................. [RUN]
[2025-03-29T01:47:12.935+0000] {subprocess.py:106} INFO - [0m01:47:12  2 of 5 START sql table model decisionnal.dim_branch ............................ [RUN]
[2025-03-29T01:47:12.942+0000] {subprocess.py:106} INFO - [0m01:47:12  3 of 5 START sql table model decisionnal.dim_location .......................... [RUN]
[2025-03-29T01:47:12.945+0000] {subprocess.py:106} INFO - [0m01:47:12  4 of 5 START sql table model decisionnal.dim_sentiment ......................... [RUN]
[2025-03-29T01:47:13.904+0000] {subprocess.py:106} INFO - [0m01:47:13  2 of 5 OK created sql table model decisionnal.dim_branch ....................... [[32mSELECT 298[0m in 0.95s]
[2025-03-29T01:47:13.907+0000] {subprocess.py:106} INFO - [0m01:47:13  4 of 5 OK created sql table model decisionnal.dim_sentiment .................... [[32mSELECT 2591[0m in 0.94s]
[2025-03-29T01:47:13.911+0000] {subprocess.py:106} INFO - [0m01:47:13  1 of 5 OK created sql table model decisionnal.dim_bank ......................... [[32mSELECT 299[0m in 0.96s]
[2025-03-29T01:47:13.914+0000] {subprocess.py:106} INFO - [0m01:47:13  3 of 5 OK created sql table model decisionnal.dim_location ..................... [[32mSELECT 298[0m in 0.96s]
[2025-03-29T01:47:13.925+0000] {subprocess.py:106} INFO - [0m01:47:13  5 of 5 START sql table model decisionnal.fact_reviews .......................... [RUN]
[2025-03-29T01:47:14.036+0000] {subprocess.py:106} INFO - [0m01:47:14  5 of 5 ERROR creating sql table model decisionnal.fact_reviews ................. [[31mERROR[0m in 0.11s]
[2025-03-29T01:47:14.091+0000] {subprocess.py:106} INFO - [0m01:47:14
[2025-03-29T01:47:14.092+0000] {subprocess.py:106} INFO - [0m01:47:14  Finished running 5 table models in 0 hours 0 minutes and 1.50 seconds (1.50s).
[2025-03-29T01:47:14.188+0000] {subprocess.py:106} INFO - [0m01:47:14
[2025-03-29T01:47:14.189+0000] {subprocess.py:106} INFO - [0m01:47:14  [31mCompleted with 1 error, 0 partial successes, and 0 warnings:[0m
[2025-03-29T01:47:14.191+0000] {subprocess.py:106} INFO - [0m01:47:14
[2025-03-29T01:47:14.193+0000] {subprocess.py:106} INFO - [0m01:47:14    Database Error in model fact_reviews (models/fact_reviews.sql)
[2025-03-29T01:47:14.194+0000] {subprocess.py:106} INFO -   column "review_text" specified more than once
[2025-03-29T01:47:14.194+0000] {subprocess.py:106} INFO -   compiled code at target/run/bank_reviews_decisionnal/models/fact_reviews.sql
[2025-03-29T01:47:14.195+0000] {subprocess.py:106} INFO - [0m01:47:14
[2025-03-29T01:47:14.196+0000] {subprocess.py:106} INFO - [0m01:47:14  Done. PASS=4 WARN=0 ERROR=1 SKIP=0 TOTAL=5
[2025-03-29T01:47:16.338+0000] {subprocess.py:110} INFO - Command exited with return code 1
[2025-03-29T01:47:16.392+0000] {taskinstance.py:3313} ERROR - Task failed with exception
Traceback (most recent call last):
  File "/home/mohammed/venv/lib/python3.11/site-packages/airflow/models/taskinstance.py", line 768, in _execute_task
    result = _execute_callable(context=context, **execute_callable_kwargs)
             ^^^^^^^^^^^^^^^^^^^^^^^^^^^^^^^^^^^^^^^^^^^^^^^^^^^^^^^^^^^^^
  File "/home/mohammed/venv/lib/python3.11/site-packages/airflow/models/taskinstance.py", line 734, in _execute_callable
    return ExecutionCallableRunner(
           ^^^^^^^^^^^^^^^^^^^^^^^^
  File "/home/mohammed/venv/lib/python3.11/site-packages/airflow/utils/operator_helpers.py", line 252, in run
    return self.func(*args, **kwargs)
           ^^^^^^^^^^^^^^^^^^^^^^^^^^
  File "/home/mohammed/venv/lib/python3.11/site-packages/airflow/models/baseoperator.py", line 424, in wrapper
    return func(self, *args, **kwargs)
           ^^^^^^^^^^^^^^^^^^^^^^^^^^^
  File "/home/mohammed/venv/lib/python3.11/site-packages/airflow/operators/bash.py", line 276, in execute
    raise AirflowException(
airflow.exceptions.AirflowException: Bash command failed. The command returned a non-zero exit code 1.
[2025-03-29T01:47:16.422+0000] {logging_mixin.py:190} INFO - Task instance in failure state
[2025-03-29T01:47:16.423+0000] {logging_mixin.py:190} INFO - Task start:2025-03-29 01:47:06.932427+00:00 end:2025-03-29 01:47:16.419306+00:00 duration:9.486879
[2025-03-29T01:47:16.424+0000] {logging_mixin.py:190} INFO - Task:<Task(BashOperator): dbt_run_decisionnal> dag:<DAG: bank_reviews_etl_and_analysis_pipeline> dagrun:<DagRun bank_reviews_etl_and_analysis_pipeline @ 2025-03-29 01:47:02.953474+00:00: manual__2025-03-29T01:47:02.953474+00:00, state:running, queued_at: 2025-03-29 01:47:03.233165+00:00. externally triggered: True>
[2025-03-29T01:47:16.424+0000] {logging_mixin.py:190} INFO - Failure caused by Bash command failed. The command returned a non-zero exit code 1.
[2025-03-29T01:47:16.425+0000] {taskinstance.py:1226} INFO - Marking task as UP_FOR_RETRY. dag_id=bank_reviews_etl_and_analysis_pipeline, task_id=dbt_run_decisionnal, run_id=manual__2025-03-29T01:47:02.953474+00:00, execution_date=20250329T014702, start_date=20250329T014706, end_date=20250329T014716
[2025-03-29T01:47:16.560+0000] {taskinstance.py:341} INFO - ::group::Post task execution logs
[2025-03-29T01:47:16.561+0000] {standard_task_runner.py:124} ERROR - Failed to execute job 2492 for task dbt_run_decisionnal (Bash command failed. The command returned a non-zero exit code 1.; 672534)
Traceback (most recent call last):
  File "/home/mohammed/venv/lib/python3.11/site-packages/airflow/task/task_runner/standard_task_runner.py", line 117, in _start_by_fork
    ret = args.func(args, dag=self.dag)
          ^^^^^^^^^^^^^^^^^^^^^^^^^^^^^
  File "/home/mohammed/venv/lib/python3.11/site-packages/airflow/cli/cli_config.py", line 49, in command
    return func(*args, **kwargs)
           ^^^^^^^^^^^^^^^^^^^^^
  File "/home/mohammed/venv/lib/python3.11/site-packages/airflow/utils/cli.py", line 116, in wrapper
    return f(*args, **kwargs)
           ^^^^^^^^^^^^^^^^^^
  File "/home/mohammed/venv/lib/python3.11/site-packages/airflow/cli/commands/task_command.py", line 483, in task_run
    task_return_code = _run_task_by_selected_method(args, _dag, ti)
                       ^^^^^^^^^^^^^^^^^^^^^^^^^^^^^^^^^^^^^^^^^^^^
  File "/home/mohammed/venv/lib/python3.11/site-packages/airflow/cli/commands/task_command.py", line 256, in _run_task_by_selected_method
    return _run_raw_task(args, ti)
           ^^^^^^^^^^^^^^^^^^^^^^^
  File "/home/mohammed/venv/lib/python3.11/site-packages/airflow/cli/commands/task_command.py", line 341, in _run_raw_task
    return ti._run_raw_task(
           ^^^^^^^^^^^^^^^^^
  File "/home/mohammed/venv/lib/python3.11/site-packages/airflow/utils/session.py", line 97, in wrapper
    return func(*args, session=session, **kwargs)
           ^^^^^^^^^^^^^^^^^^^^^^^^^^^^^^^^^^^^^^
  File "/home/mohammed/venv/lib/python3.11/site-packages/airflow/models/taskinstance.py", line 3006, in _run_raw_task
    return _run_raw_task(
           ^^^^^^^^^^^^^^
  File "/home/mohammed/venv/lib/python3.11/site-packages/airflow/models/taskinstance.py", line 274, in _run_raw_task
    TaskInstance._execute_task_with_callbacks(
  File "/home/mohammed/venv/lib/python3.11/site-packages/airflow/models/taskinstance.py", line 3161, in _execute_task_with_callbacks
    result = self._execute_task(context, task_orig)
             ^^^^^^^^^^^^^^^^^^^^^^^^^^^^^^^^^^^^^^
  File "/home/mohammed/venv/lib/python3.11/site-packages/airflow/models/taskinstance.py", line 3185, in _execute_task
    return _execute_task(self, context, task_orig)
           ^^^^^^^^^^^^^^^^^^^^^^^^^^^^^^^^^^^^^^^
  File "/home/mohammed/venv/lib/python3.11/site-packages/airflow/models/taskinstance.py", line 768, in _execute_task
    result = _execute_callable(context=context, **execute_callable_kwargs)
             ^^^^^^^^^^^^^^^^^^^^^^^^^^^^^^^^^^^^^^^^^^^^^^^^^^^^^^^^^^^^^
  File "/home/mohammed/venv/lib/python3.11/site-packages/airflow/models/taskinstance.py", line 734, in _execute_callable
    return ExecutionCallableRunner(
           ^^^^^^^^^^^^^^^^^^^^^^^^
  File "/home/mohammed/venv/lib/python3.11/site-packages/airflow/utils/operator_helpers.py", line 252, in run
    return self.func(*args, **kwargs)
           ^^^^^^^^^^^^^^^^^^^^^^^^^^
  File "/home/mohammed/venv/lib/python3.11/site-packages/airflow/models/baseoperator.py", line 424, in wrapper
    return func(self, *args, **kwargs)
           ^^^^^^^^^^^^^^^^^^^^^^^^^^^
  File "/home/mohammed/venv/lib/python3.11/site-packages/airflow/operators/bash.py", line 276, in execute
    raise AirflowException(
airflow.exceptions.AirflowException: Bash command failed. The command returned a non-zero exit code 1.
[2025-03-29T01:47:16.595+0000] {local_task_job_runner.py:266} INFO - Task exited with return code 1
[2025-03-29T01:47:16.656+0000] {taskinstance.py:3901} INFO - 0 downstream tasks scheduled from follow-on schedule check
[2025-03-29T01:47:16.659+0000] {local_task_job_runner.py:245} INFO - ::endgroup::
