[2025-03-17T00:41:46.409+0000] {local_task_job_runner.py:123} INFO - ::group::Pre task execution logs
[2025-03-17T00:41:46.479+0000] {taskinstance.py:2614} INFO - Dependencies all met for dep_context=non-requeueable deps ti=<TaskInstance: load_reviews_pipeline.dbt_run scheduled__2024-06-29T00:00:00+00:00 [queued]>
[2025-03-17T00:41:46.500+0000] {taskinstance.py:2614} INFO - Dependencies all met for dep_context=requeueable deps ti=<TaskInstance: load_reviews_pipeline.dbt_run scheduled__2024-06-29T00:00:00+00:00 [queued]>
[2025-03-17T00:41:46.501+0000] {taskinstance.py:2867} INFO - Starting attempt 1 of 2
[2025-03-17T00:41:46.544+0000] {taskinstance.py:2890} INFO - Executing <Task(BashOperator): dbt_run> on 2024-06-29 00:00:00+00:00
[2025-03-17T00:41:46.560+0000] {standard_task_runner.py:72} INFO - Started process 276028 to run task
[2025-03-17T00:41:46.574+0000] {standard_task_runner.py:104} INFO - Running: ['airflow', 'tasks', 'run', 'load_reviews_pipeline', 'dbt_run', 'scheduled__2024-06-29T00:00:00+00:00', '--job-id', '308', '--raw', '--subdir', 'DAGS_FOLDER/dag_load_reviews.py', '--cfg-path', '/tmp/tmprc2o4964']
[2025-03-17T00:41:46.580+0000] {standard_task_runner.py:105} INFO - Job 308: Subtask dbt_run
[2025-03-17T00:41:46.866+0000] {task_command.py:467} INFO - Running <TaskInstance: load_reviews_pipeline.dbt_run scheduled__2024-06-29T00:00:00+00:00 [running]> on host DESKTOP-IM7V4RI.
[2025-03-17T00:41:47.205+0000] {taskinstance.py:3134} INFO - Exporting env vars: AIRFLOW_CTX_DAG_OWNER='mohammed' AIRFLOW_CTX_DAG_ID='load_reviews_pipeline' AIRFLOW_CTX_TASK_ID='dbt_run' AIRFLOW_CTX_EXECUTION_DATE='2024-06-29T00:00:00+00:00' AIRFLOW_CTX_TRY_NUMBER='1' AIRFLOW_CTX_DAG_RUN_ID='scheduled__2024-06-29T00:00:00+00:00'
[2025-03-17T00:41:47.209+0000] {logging_mixin.py:190} INFO - Task instance is in running state
[2025-03-17T00:41:47.210+0000] {logging_mixin.py:190} INFO -  Previous state of the Task instance: queued
[2025-03-17T00:41:47.210+0000] {logging_mixin.py:190} INFO - Current task name:dbt_run state:running start_date:2025-03-17 00:41:46.480416+00:00
[2025-03-17T00:41:47.211+0000] {logging_mixin.py:190} INFO - Dag name:load_reviews_pipeline and current dag run status:running
[2025-03-17T00:41:47.212+0000] {taskinstance.py:732} INFO - ::endgroup::
[2025-03-17T00:41:47.214+0000] {subprocess.py:78} INFO - Tmp dir root location: /tmp
[2025-03-17T00:41:47.217+0000] {subprocess.py:88} INFO - Running command: ['/usr/bin/bash', '-c', 'cd /home/mohammed/.dbt/bank_reviews_project && dbt run']
[2025-03-17T00:41:47.243+0000] {subprocess.py:99} INFO - Output:
[2025-03-17T00:41:51.543+0000] {subprocess.py:106} INFO - [0m00:41:51  Running with dbt=1.9.3
[2025-03-17T00:41:52.280+0000] {subprocess.py:106} INFO - [0m00:41:52  Registered adapter: postgres=1.9.0
[2025-03-17T00:41:53.410+0000] {subprocess.py:106} INFO - [0m00:41:53  Found 6 models, 4 data tests, 2 sources, 433 macros
[2025-03-17T00:41:53.421+0000] {subprocess.py:106} INFO - [0m00:41:53
[2025-03-17T00:41:53.423+0000] {subprocess.py:106} INFO - [0m00:41:53  Concurrency: 4 threads (target='dev')
[2025-03-17T00:41:53.426+0000] {subprocess.py:106} INFO - [0m00:41:53
[2025-03-17T00:41:53.832+0000] {subprocess.py:106} INFO - [0m00:41:53  1 of 6 START sql view model public.clean_reviews ............................... [RUN]
[2025-03-17T00:41:53.834+0000] {subprocess.py:106} INFO - [0m00:41:53  2 of 6 START sql table model public.my_first_dbt_model ......................... [RUN]
[2025-03-17T00:41:53.840+0000] {subprocess.py:106} INFO - [0m00:41:53  3 of 6 START sql view model public.remove_duplicates ........................... [RUN]
[2025-03-17T00:41:53.845+0000] {subprocess.py:106} INFO - [0m00:41:53  4 of 6 START sql view model public.stg_clean_reviews ........................... [RUN]
[2025-03-17T00:41:54.431+0000] {subprocess.py:106} INFO - [0m00:41:54  1 of 6 ERROR creating sql view model public.clean_reviews ...................... [[31mERROR[0m in 0.58s]
[2025-03-17T00:41:54.608+0000] {subprocess.py:106} INFO - [0m00:41:54  3 of 6 ERROR creating sql view model public.remove_duplicates .................. [[31mERROR[0m in 0.71s]
[2025-03-17T00:41:54.633+0000] {subprocess.py:106} INFO - [0m00:41:54  4 of 6 ERROR creating sql view model public.stg_clean_reviews .................. [[31mERROR[0m in 0.77s]
[2025-03-17T00:41:54.643+0000] {subprocess.py:106} INFO - [0m00:41:54  2 of 6 ERROR creating sql table model public.my_first_dbt_model ................ [[31mERROR[0m in 0.79s]
[2025-03-17T00:41:54.661+0000] {subprocess.py:106} INFO - [0m00:41:54  5 of 6 SKIP relation public.dwh_model .......................................... [[33mSKIP[0m]
[2025-03-17T00:41:54.676+0000] {subprocess.py:106} INFO - [0m00:41:54  6 of 6 SKIP relation public.my_second_dbt_model ................................ [[33mSKIP[0m]
[2025-03-17T00:41:54.738+0000] {subprocess.py:106} INFO - [0m00:41:54
[2025-03-17T00:41:54.740+0000] {subprocess.py:106} INFO - [0m00:41:54  Finished running 1 table model, 5 view models in 0 hours 0 minutes and 1.31 seconds (1.31s).
[2025-03-17T00:41:54.942+0000] {subprocess.py:106} INFO - [0m00:41:54
[2025-03-17T00:41:54.944+0000] {subprocess.py:106} INFO - [0m00:41:54  [31mCompleted with 4 errors, 0 partial successes, and 0 warnings:[0m
[2025-03-17T00:41:54.945+0000] {subprocess.py:106} INFO - [0m00:41:54
[2025-03-17T00:41:54.946+0000] {subprocess.py:106} INFO - [0m00:41:54    Database Error in model clean_reviews (models/clean_reviews.sql)
[2025-03-17T00:41:54.947+0000] {subprocess.py:106} INFO -   syntax error at or near "external"
[2025-03-17T00:41:54.947+0000] {subprocess.py:106} INFO -   LINE 2: drop external if exists "project_data_wherhouse"."public"."c...
[2025-03-17T00:41:54.948+0000] {subprocess.py:106} INFO -                ^
[2025-03-17T00:41:54.948+0000] {subprocess.py:106} INFO - [0m00:41:54
[2025-03-17T00:41:54.949+0000] {subprocess.py:106} INFO - [0m00:41:54    Database Error in model remove_duplicates (models/remove_duplicates.sql)
[2025-03-17T00:41:54.950+0000] {subprocess.py:106} INFO -   relation "remove_duplicates__dbt_backup" already exists
[2025-03-17T00:41:54.950+0000] {subprocess.py:106} INFO -   compiled code at target/run/bank_reviews_project/models/remove_duplicates.sql
[2025-03-17T00:41:54.950+0000] {subprocess.py:106} INFO - [0m00:41:54
[2025-03-17T00:41:54.952+0000] {subprocess.py:106} INFO - [0m00:41:54    Database Error in model stg_clean_reviews (models/stg_clean_reviews.sql)
[2025-03-17T00:41:54.952+0000] {subprocess.py:106} INFO -   relation "stg_clean_reviews__dbt_backup" already exists
[2025-03-17T00:41:54.952+0000] {subprocess.py:106} INFO -   compiled code at target/run/bank_reviews_project/models/stg_clean_reviews.sql
[2025-03-17T00:41:54.953+0000] {subprocess.py:106} INFO - [0m00:41:54
[2025-03-17T00:41:54.954+0000] {subprocess.py:106} INFO - [0m00:41:54    Database Error in model my_first_dbt_model (models/example/my_first_dbt_model.sql)
[2025-03-17T00:41:54.955+0000] {subprocess.py:106} INFO -   relation "my_first_dbt_model__dbt_backup" already exists
[2025-03-17T00:41:54.955+0000] {subprocess.py:106} INFO -   compiled code at target/run/bank_reviews_project/models/example/my_first_dbt_model.sql
[2025-03-17T00:41:54.956+0000] {subprocess.py:106} INFO - [0m00:41:54
[2025-03-17T00:41:54.956+0000] {subprocess.py:106} INFO - [0m00:41:54  Done. PASS=0 WARN=0 ERROR=4 SKIP=2 TOTAL=6
[2025-03-17T00:42:00.022+0000] {subprocess.py:110} INFO - Command exited with return code 1
[2025-03-17T00:42:00.059+0000] {taskinstance.py:3313} ERROR - Task failed with exception
Traceback (most recent call last):
  File "/home/mohammed/venv/lib/python3.11/site-packages/airflow/models/taskinstance.py", line 768, in _execute_task
    result = _execute_callable(context=context, **execute_callable_kwargs)
             ^^^^^^^^^^^^^^^^^^^^^^^^^^^^^^^^^^^^^^^^^^^^^^^^^^^^^^^^^^^^^
  File "/home/mohammed/venv/lib/python3.11/site-packages/airflow/models/taskinstance.py", line 734, in _execute_callable
    return ExecutionCallableRunner(
           ^^^^^^^^^^^^^^^^^^^^^^^^
  File "/home/mohammed/venv/lib/python3.11/site-packages/airflow/utils/operator_helpers.py", line 252, in run
    return self.func(*args, **kwargs)
           ^^^^^^^^^^^^^^^^^^^^^^^^^^
  File "/home/mohammed/venv/lib/python3.11/site-packages/airflow/models/baseoperator.py", line 424, in wrapper
    return func(self, *args, **kwargs)
           ^^^^^^^^^^^^^^^^^^^^^^^^^^^
  File "/home/mohammed/venv/lib/python3.11/site-packages/airflow/operators/bash.py", line 276, in execute
    raise AirflowException(
airflow.exceptions.AirflowException: Bash command failed. The command returned a non-zero exit code 1.
[2025-03-17T00:42:00.077+0000] {logging_mixin.py:190} INFO - Task instance in failure state
[2025-03-17T00:42:00.077+0000] {logging_mixin.py:190} INFO - Task start:2025-03-17 00:41:46.480416+00:00 end:2025-03-17 00:42:00.075015+00:00 duration:13.594599
[2025-03-17T00:42:00.078+0000] {logging_mixin.py:190} INFO - Task:<Task(BashOperator): dbt_run> dag:<DAG: load_reviews_pipeline> dagrun:<DagRun load_reviews_pipeline @ 2024-06-29 00:00:00+00:00: scheduled__2024-06-29T00:00:00+00:00, state:running, queued_at: 2025-03-17 00:41:43.938330+00:00. externally triggered: False>
[2025-03-17T00:42:00.079+0000] {logging_mixin.py:190} INFO - Failure caused by Bash command failed. The command returned a non-zero exit code 1.
[2025-03-17T00:42:00.080+0000] {taskinstance.py:1226} INFO - Marking task as UP_FOR_RETRY. dag_id=load_reviews_pipeline, task_id=dbt_run, run_id=scheduled__2024-06-29T00:00:00+00:00, execution_date=20240629T000000, start_date=20250317T004146, end_date=20250317T004200
[2025-03-17T00:42:00.472+0000] {taskinstance.py:341} INFO - ::group::Post task execution logs
[2025-03-17T00:42:00.473+0000] {standard_task_runner.py:124} ERROR - Failed to execute job 308 for task dbt_run (Bash command failed. The command returned a non-zero exit code 1.; 276028)
Traceback (most recent call last):
  File "/home/mohammed/venv/lib/python3.11/site-packages/airflow/task/task_runner/standard_task_runner.py", line 117, in _start_by_fork
    ret = args.func(args, dag=self.dag)
          ^^^^^^^^^^^^^^^^^^^^^^^^^^^^^
  File "/home/mohammed/venv/lib/python3.11/site-packages/airflow/cli/cli_config.py", line 49, in command
    return func(*args, **kwargs)
           ^^^^^^^^^^^^^^^^^^^^^
  File "/home/mohammed/venv/lib/python3.11/site-packages/airflow/utils/cli.py", line 116, in wrapper
    return f(*args, **kwargs)
           ^^^^^^^^^^^^^^^^^^
  File "/home/mohammed/venv/lib/python3.11/site-packages/airflow/cli/commands/task_command.py", line 483, in task_run
    task_return_code = _run_task_by_selected_method(args, _dag, ti)
                       ^^^^^^^^^^^^^^^^^^^^^^^^^^^^^^^^^^^^^^^^^^^^
  File "/home/mohammed/venv/lib/python3.11/site-packages/airflow/cli/commands/task_command.py", line 256, in _run_task_by_selected_method
    return _run_raw_task(args, ti)
           ^^^^^^^^^^^^^^^^^^^^^^^
  File "/home/mohammed/venv/lib/python3.11/site-packages/airflow/cli/commands/task_command.py", line 341, in _run_raw_task
    return ti._run_raw_task(
           ^^^^^^^^^^^^^^^^^
  File "/home/mohammed/venv/lib/python3.11/site-packages/airflow/utils/session.py", line 97, in wrapper
    return func(*args, session=session, **kwargs)
           ^^^^^^^^^^^^^^^^^^^^^^^^^^^^^^^^^^^^^^
  File "/home/mohammed/venv/lib/python3.11/site-packages/airflow/models/taskinstance.py", line 3006, in _run_raw_task
    return _run_raw_task(
           ^^^^^^^^^^^^^^
  File "/home/mohammed/venv/lib/python3.11/site-packages/airflow/models/taskinstance.py", line 274, in _run_raw_task
    TaskInstance._execute_task_with_callbacks(
  File "/home/mohammed/venv/lib/python3.11/site-packages/airflow/models/taskinstance.py", line 3161, in _execute_task_with_callbacks
    result = self._execute_task(context, task_orig)
             ^^^^^^^^^^^^^^^^^^^^^^^^^^^^^^^^^^^^^^
  File "/home/mohammed/venv/lib/python3.11/site-packages/airflow/models/taskinstance.py", line 3185, in _execute_task
    return _execute_task(self, context, task_orig)
           ^^^^^^^^^^^^^^^^^^^^^^^^^^^^^^^^^^^^^^^
  File "/home/mohammed/venv/lib/python3.11/site-packages/airflow/models/taskinstance.py", line 768, in _execute_task
    result = _execute_callable(context=context, **execute_callable_kwargs)
             ^^^^^^^^^^^^^^^^^^^^^^^^^^^^^^^^^^^^^^^^^^^^^^^^^^^^^^^^^^^^^
  File "/home/mohammed/venv/lib/python3.11/site-packages/airflow/models/taskinstance.py", line 734, in _execute_callable
    return ExecutionCallableRunner(
           ^^^^^^^^^^^^^^^^^^^^^^^^
  File "/home/mohammed/venv/lib/python3.11/site-packages/airflow/utils/operator_helpers.py", line 252, in run
    return self.func(*args, **kwargs)
           ^^^^^^^^^^^^^^^^^^^^^^^^^^
  File "/home/mohammed/venv/lib/python3.11/site-packages/airflow/models/baseoperator.py", line 424, in wrapper
    return func(self, *args, **kwargs)
           ^^^^^^^^^^^^^^^^^^^^^^^^^^^
  File "/home/mohammed/venv/lib/python3.11/site-packages/airflow/operators/bash.py", line 276, in execute
    raise AirflowException(
airflow.exceptions.AirflowException: Bash command failed. The command returned a non-zero exit code 1.
[2025-03-17T00:42:00.518+0000] {local_task_job_runner.py:266} INFO - Task exited with return code 1
[2025-03-17T00:42:00.592+0000] {taskinstance.py:3901} INFO - 0 downstream tasks scheduled from follow-on schedule check
[2025-03-17T00:42:00.600+0000] {local_task_job_runner.py:245} INFO - ::endgroup::
