[2025-03-28T13:33:53.049+0000] {local_task_job_runner.py:123} INFO - ::group::Pre task execution logs
[2025-03-28T13:33:53.237+0000] {taskinstance.py:2614} INFO - Dependencies all met for dep_context=non-requeueable deps ti=<TaskInstance: load_dbt_clean_reviews_pipeline.dbt_run_transactional scheduled__2024-12-10T00:00:00+00:00 [queued]>
[2025-03-28T13:33:53.319+0000] {taskinstance.py:2614} INFO - Dependencies all met for dep_context=requeueable deps ti=<TaskInstance: load_dbt_clean_reviews_pipeline.dbt_run_transactional scheduled__2024-12-10T00:00:00+00:00 [queued]>
[2025-03-28T13:33:53.319+0000] {taskinstance.py:2867} INFO - Starting attempt 1 of 2
[2025-03-28T13:33:53.457+0000] {taskinstance.py:2890} INFO - Executing <Task(BashOperator): dbt_run_transactional> on 2024-12-10 00:00:00+00:00
[2025-03-28T13:33:53.488+0000] {standard_task_runner.py:72} INFO - Started process 4179 to run task
[2025-03-28T13:33:53.520+0000] {standard_task_runner.py:104} INFO - Running: ['airflow', 'tasks', 'run', 'load_dbt_clean_reviews_pipeline', 'dbt_run_transactional', 'scheduled__2024-12-10T00:00:00+00:00', '--job-id', '2271', '--raw', '--subdir', 'DAGS_FOLDER/dag_load_reviews.py', '--cfg-path', '/tmp/tmpx3mud63l']
[2025-03-28T13:33:53.523+0000] {standard_task_runner.py:105} INFO - Job 2271: Subtask dbt_run_transactional
[2025-03-28T13:33:53.972+0000] {task_command.py:467} INFO - Running <TaskInstance: load_dbt_clean_reviews_pipeline.dbt_run_transactional scheduled__2024-12-10T00:00:00+00:00 [running]> on host DESKTOP-IM7V4RI.
[2025-03-28T13:33:54.725+0000] {taskinstance.py:3134} INFO - Exporting env vars: AIRFLOW_CTX_DAG_OWNER='mohammed' AIRFLOW_CTX_DAG_ID='load_dbt_clean_reviews_pipeline' AIRFLOW_CTX_TASK_ID='dbt_run_transactional' AIRFLOW_CTX_EXECUTION_DATE='2024-12-10T00:00:00+00:00' AIRFLOW_CTX_TRY_NUMBER='1' AIRFLOW_CTX_DAG_RUN_ID='scheduled__2024-12-10T00:00:00+00:00'
[2025-03-28T13:33:54.728+0000] {logging_mixin.py:190} INFO - Task instance is in running state
[2025-03-28T13:33:54.734+0000] {logging_mixin.py:190} INFO -  Previous state of the Task instance: queued
[2025-03-28T13:33:54.735+0000] {logging_mixin.py:190} INFO - Current task name:dbt_run_transactional state:running start_date:2025-03-28 13:33:53.238564+00:00
[2025-03-28T13:33:54.735+0000] {logging_mixin.py:190} INFO - Dag name:load_dbt_clean_reviews_pipeline and current dag run status:running
[2025-03-28T13:33:54.736+0000] {taskinstance.py:732} INFO - ::endgroup::
[2025-03-28T13:33:54.738+0000] {subprocess.py:78} INFO - Tmp dir root location: /tmp
[2025-03-28T13:33:54.743+0000] {subprocess.py:88} INFO - Running command: ['/usr/bin/bash', '-c', 'cd /home/mohammed/.dbt/dbt_projects/bank_reviews_transactional && dbt run']
[2025-03-28T13:33:54.789+0000] {subprocess.py:99} INFO - Output:
[2025-03-28T13:34:18.067+0000] {subprocess.py:106} INFO - [0m13:34:18  Running with dbt=1.9.3
[2025-03-28T13:34:24.529+0000] {subprocess.py:106} INFO - [0m13:34:24  Registered adapter: postgres=1.9.0
[2025-03-28T13:34:27.209+0000] {subprocess.py:106} INFO - [0m13:34:27  [[33mWARNING[0m]: Configuration paths exist in your dbt_project.yml file which do not apply to any resources.
[2025-03-28T13:34:27.210+0000] {subprocess.py:106} INFO - There are 1 unused configuration paths:
[2025-03-28T13:34:27.211+0000] {subprocess.py:106} INFO - - models.bank_reviews_transactional.transactional
[2025-03-28T13:34:29.151+0000] {subprocess.py:106} INFO - [0m13:34:29  Found 1 model, 1 source, 433 macros
[2025-03-28T13:34:29.162+0000] {subprocess.py:106} INFO - [0m13:34:29
[2025-03-28T13:34:29.164+0000] {subprocess.py:106} INFO - [0m13:34:29  Concurrency: 4 threads (target='dev')
[2025-03-28T13:34:29.167+0000] {subprocess.py:106} INFO - [0m13:34:29
[2025-03-28T13:34:31.000+0000] {subprocess.py:106} INFO - [0m13:34:30  1 of 1 START sql table model transactional.clean_reviews ....................... [RUN]
[2025-03-28T13:34:40.758+0000] {subprocess.py:106} INFO - [0m13:34:40  1 of 1 ERROR creating sql table model transactional.clean_reviews .............. [[31mERROR[0m in 9.74s]
[2025-03-28T13:34:40.872+0000] {subprocess.py:106} INFO - [0m13:34:40
[2025-03-28T13:34:40.875+0000] {subprocess.py:106} INFO - [0m13:34:40  Finished running 1 table model in 0 hours 0 minutes and 11.68 seconds (11.68s).
[2025-03-28T13:34:41.022+0000] {subprocess.py:106} INFO - [0m13:34:41
[2025-03-28T13:34:41.025+0000] {subprocess.py:106} INFO - [0m13:34:41  [31mCompleted with 1 error, 0 partial successes, and 0 warnings:[0m
[2025-03-28T13:34:41.027+0000] {subprocess.py:106} INFO - [0m13:34:41
[2025-03-28T13:34:41.030+0000] {subprocess.py:106} INFO - [0m13:34:41    Database Error in model clean_reviews (models/clean_reviews.sql)
[2025-03-28T13:34:41.031+0000] {subprocess.py:106} INFO -   relation "clean_reviews__dbt_backup" already exists
[2025-03-28T13:34:41.031+0000] {subprocess.py:106} INFO -   compiled code at target/run/bank_reviews_transactional/models/clean_reviews.sql
[2025-03-28T13:34:41.036+0000] {subprocess.py:106} INFO - [0m13:34:41
[2025-03-28T13:34:41.044+0000] {subprocess.py:106} INFO - [0m13:34:41  Done. PASS=0 WARN=0 ERROR=1 SKIP=0 TOTAL=1
[2025-03-28T13:34:43.752+0000] {subprocess.py:110} INFO - Command exited with return code 1
[2025-03-28T13:34:43.987+0000] {taskinstance.py:3313} ERROR - Task failed with exception
Traceback (most recent call last):
  File "/home/mohammed/venv/lib/python3.11/site-packages/airflow/models/taskinstance.py", line 768, in _execute_task
    result = _execute_callable(context=context, **execute_callable_kwargs)
             ^^^^^^^^^^^^^^^^^^^^^^^^^^^^^^^^^^^^^^^^^^^^^^^^^^^^^^^^^^^^^
  File "/home/mohammed/venv/lib/python3.11/site-packages/airflow/models/taskinstance.py", line 734, in _execute_callable
    return ExecutionCallableRunner(
           ^^^^^^^^^^^^^^^^^^^^^^^^
  File "/home/mohammed/venv/lib/python3.11/site-packages/airflow/utils/operator_helpers.py", line 252, in run
    return self.func(*args, **kwargs)
           ^^^^^^^^^^^^^^^^^^^^^^^^^^
  File "/home/mohammed/venv/lib/python3.11/site-packages/airflow/models/baseoperator.py", line 424, in wrapper
    return func(self, *args, **kwargs)
           ^^^^^^^^^^^^^^^^^^^^^^^^^^^
  File "/home/mohammed/venv/lib/python3.11/site-packages/airflow/operators/bash.py", line 276, in execute
    raise AirflowException(
airflow.exceptions.AirflowException: Bash command failed. The command returned a non-zero exit code 1.
[2025-03-28T13:34:44.069+0000] {logging_mixin.py:190} INFO - Task instance in failure state
[2025-03-28T13:34:44.071+0000] {logging_mixin.py:190} INFO - Task start:2025-03-28 13:33:53.238564+00:00 end:2025-03-28 13:34:44.065738+00:00 duration:50.827174
[2025-03-28T13:34:44.072+0000] {logging_mixin.py:190} INFO - Task:<Task(BashOperator): dbt_run_transactional> dag:<DAG: load_dbt_clean_reviews_pipeline> dagrun:<DagRun load_dbt_clean_reviews_pipeline @ 2024-12-10 00:00:00+00:00: scheduled__2024-12-10T00:00:00+00:00, state:running, queued_at: 2025-03-28 13:33:47.643801+00:00. externally triggered: False>
[2025-03-28T13:34:44.073+0000] {logging_mixin.py:190} INFO - Failure caused by Bash command failed. The command returned a non-zero exit code 1.
[2025-03-28T13:34:44.074+0000] {taskinstance.py:1226} INFO - Marking task as UP_FOR_RETRY. dag_id=load_dbt_clean_reviews_pipeline, task_id=dbt_run_transactional, run_id=scheduled__2024-12-10T00:00:00+00:00, execution_date=20241210T000000, start_date=20250328T133353, end_date=20250328T133444
[2025-03-28T13:34:44.396+0000] {taskinstance.py:341} INFO - ::group::Post task execution logs
[2025-03-28T13:34:44.398+0000] {standard_task_runner.py:124} ERROR - Failed to execute job 2271 for task dbt_run_transactional (Bash command failed. The command returned a non-zero exit code 1.; 4179)
Traceback (most recent call last):
  File "/home/mohammed/venv/lib/python3.11/site-packages/airflow/task/task_runner/standard_task_runner.py", line 117, in _start_by_fork
    ret = args.func(args, dag=self.dag)
          ^^^^^^^^^^^^^^^^^^^^^^^^^^^^^
  File "/home/mohammed/venv/lib/python3.11/site-packages/airflow/cli/cli_config.py", line 49, in command
    return func(*args, **kwargs)
           ^^^^^^^^^^^^^^^^^^^^^
  File "/home/mohammed/venv/lib/python3.11/site-packages/airflow/utils/cli.py", line 116, in wrapper
    return f(*args, **kwargs)
           ^^^^^^^^^^^^^^^^^^
  File "/home/mohammed/venv/lib/python3.11/site-packages/airflow/cli/commands/task_command.py", line 483, in task_run
    task_return_code = _run_task_by_selected_method(args, _dag, ti)
                       ^^^^^^^^^^^^^^^^^^^^^^^^^^^^^^^^^^^^^^^^^^^^
  File "/home/mohammed/venv/lib/python3.11/site-packages/airflow/cli/commands/task_command.py", line 256, in _run_task_by_selected_method
    return _run_raw_task(args, ti)
           ^^^^^^^^^^^^^^^^^^^^^^^
  File "/home/mohammed/venv/lib/python3.11/site-packages/airflow/cli/commands/task_command.py", line 341, in _run_raw_task
    return ti._run_raw_task(
           ^^^^^^^^^^^^^^^^^
  File "/home/mohammed/venv/lib/python3.11/site-packages/airflow/utils/session.py", line 97, in wrapper
    return func(*args, session=session, **kwargs)
           ^^^^^^^^^^^^^^^^^^^^^^^^^^^^^^^^^^^^^^
  File "/home/mohammed/venv/lib/python3.11/site-packages/airflow/models/taskinstance.py", line 3006, in _run_raw_task
    return _run_raw_task(
           ^^^^^^^^^^^^^^
  File "/home/mohammed/venv/lib/python3.11/site-packages/airflow/models/taskinstance.py", line 274, in _run_raw_task
    TaskInstance._execute_task_with_callbacks(
  File "/home/mohammed/venv/lib/python3.11/site-packages/airflow/models/taskinstance.py", line 3161, in _execute_task_with_callbacks
    result = self._execute_task(context, task_orig)
             ^^^^^^^^^^^^^^^^^^^^^^^^^^^^^^^^^^^^^^
  File "/home/mohammed/venv/lib/python3.11/site-packages/airflow/models/taskinstance.py", line 3185, in _execute_task
    return _execute_task(self, context, task_orig)
           ^^^^^^^^^^^^^^^^^^^^^^^^^^^^^^^^^^^^^^^
  File "/home/mohammed/venv/lib/python3.11/site-packages/airflow/models/taskinstance.py", line 768, in _execute_task
    result = _execute_callable(context=context, **execute_callable_kwargs)
             ^^^^^^^^^^^^^^^^^^^^^^^^^^^^^^^^^^^^^^^^^^^^^^^^^^^^^^^^^^^^^
  File "/home/mohammed/venv/lib/python3.11/site-packages/airflow/models/taskinstance.py", line 734, in _execute_callable
    return ExecutionCallableRunner(
           ^^^^^^^^^^^^^^^^^^^^^^^^
  File "/home/mohammed/venv/lib/python3.11/site-packages/airflow/utils/operator_helpers.py", line 252, in run
    return self.func(*args, **kwargs)
           ^^^^^^^^^^^^^^^^^^^^^^^^^^
  File "/home/mohammed/venv/lib/python3.11/site-packages/airflow/models/baseoperator.py", line 424, in wrapper
    return func(self, *args, **kwargs)
           ^^^^^^^^^^^^^^^^^^^^^^^^^^^
  File "/home/mohammed/venv/lib/python3.11/site-packages/airflow/operators/bash.py", line 276, in execute
    raise AirflowException(
airflow.exceptions.AirflowException: Bash command failed. The command returned a non-zero exit code 1.
[2025-03-28T13:34:44.436+0000] {local_task_job_runner.py:266} INFO - Task exited with return code 1
[2025-03-28T13:34:44.661+0000] {taskinstance.py:3901} INFO - 0 downstream tasks scheduled from follow-on schedule check
[2025-03-28T13:34:44.675+0000] {local_task_job_runner.py:245} INFO - ::endgroup::
