[2025-03-18T17:05:14.873+0000] {local_task_job_runner.py:123} INFO - ::group::Pre task execution logs
[2025-03-18T17:05:15.204+0000] {taskinstance.py:2614} INFO - Dependencies all met for dep_context=non-requeueable deps ti=<TaskInstance: load_dbt_clean_reviews_pipeline.dbt_run scheduled__2024-04-16T00:00:00+00:00 [queued]>
[2025-03-18T17:05:15.316+0000] {taskinstance.py:2614} INFO - Dependencies all met for dep_context=requeueable deps ti=<TaskInstance: load_dbt_clean_reviews_pipeline.dbt_run scheduled__2024-04-16T00:00:00+00:00 [queued]>
[2025-03-18T17:05:15.318+0000] {taskinstance.py:2867} INFO - Starting attempt 1 of 2
[2025-03-18T17:05:15.508+0000] {taskinstance.py:2890} INFO - Executing <Task(BashOperator): dbt_run> on 2024-04-16 00:00:00+00:00
[2025-03-18T17:05:15.569+0000] {standard_task_runner.py:72} INFO - Started process 50112 to run task
[2025-03-18T17:05:15.665+0000] {standard_task_runner.py:104} INFO - Running: ['airflow', 'tasks', 'run', 'load_dbt_clean_reviews_pipeline', 'dbt_run', 'scheduled__2024-04-16T00:00:00+00:00', '--job-id', '777', '--raw', '--subdir', 'DAGS_FOLDER/dag_load_reviews.py', '--cfg-path', '/tmp/tmpomgu49c1']
[2025-03-18T17:05:15.668+0000] {standard_task_runner.py:105} INFO - Job 777: Subtask dbt_run
[2025-03-18T17:05:16.613+0000] {task_command.py:467} INFO - Running <TaskInstance: load_dbt_clean_reviews_pipeline.dbt_run scheduled__2024-04-16T00:00:00+00:00 [running]> on host DESKTOP-IM7V4RI.
[2025-03-18T17:05:18.287+0000] {taskinstance.py:3134} INFO - Exporting env vars: AIRFLOW_CTX_DAG_OWNER='mohammed' AIRFLOW_CTX_DAG_ID='load_dbt_clean_reviews_pipeline' AIRFLOW_CTX_TASK_ID='dbt_run' AIRFLOW_CTX_EXECUTION_DATE='2024-04-16T00:00:00+00:00' AIRFLOW_CTX_TRY_NUMBER='1' AIRFLOW_CTX_DAG_RUN_ID='scheduled__2024-04-16T00:00:00+00:00'
[2025-03-18T17:05:18.322+0000] {logging_mixin.py:190} INFO - Task instance is in running state
[2025-03-18T17:05:18.323+0000] {logging_mixin.py:190} INFO -  Previous state of the Task instance: queued
[2025-03-18T17:05:18.324+0000] {logging_mixin.py:190} INFO - Current task name:dbt_run state:running start_date:2025-03-18 17:05:15.208317+00:00
[2025-03-18T17:05:18.324+0000] {logging_mixin.py:190} INFO - Dag name:load_dbt_clean_reviews_pipeline and current dag run status:running
[2025-03-18T17:05:18.325+0000] {taskinstance.py:732} INFO - ::endgroup::
[2025-03-18T17:05:18.356+0000] {subprocess.py:78} INFO - Tmp dir root location: /tmp
[2025-03-18T17:05:18.364+0000] {subprocess.py:88} INFO - Running command: ['/usr/bin/bash', '-c', 'cd /home/mohammed/.dbt/dbt_projects/bank_reviews_transactional && dbt run']
[2025-03-18T17:05:18.522+0000] {subprocess.py:99} INFO - Output:
[2025-03-18T17:05:40.539+0000] {subprocess.py:106} INFO - [0m17:05:40  Running with dbt=1.9.3
[2025-03-18T17:05:42.614+0000] {subprocess.py:106} INFO - [0m17:05:42  Registered adapter: postgres=1.9.0
[2025-03-18T17:05:44.167+0000] {subprocess.py:106} INFO - [0m17:05:44  [[33mWARNING[0m]: Configuration paths exist in your dbt_project.yml file which do not apply to any resources.
[2025-03-18T17:05:44.168+0000] {subprocess.py:106} INFO - There are 1 unused configuration paths:
[2025-03-18T17:05:44.168+0000] {subprocess.py:106} INFO - - models.bank_reviews_transactional.transactional
[2025-03-18T17:05:45.756+0000] {subprocess.py:106} INFO - [0m17:05:45  Found 3 models, 4 data tests, 1 source, 433 macros
[2025-03-18T17:05:45.765+0000] {subprocess.py:106} INFO - [0m17:05:45
[2025-03-18T17:05:45.768+0000] {subprocess.py:106} INFO - [0m17:05:45  Concurrency: 4 threads (target='dev')
[2025-03-18T17:05:45.774+0000] {subprocess.py:106} INFO - [0m17:05:45
[2025-03-18T17:05:46.899+0000] {subprocess.py:106} INFO - [0m17:05:46  1 of 3 START sql table model transactional.clean_reviews ....................... [RUN]
[2025-03-18T17:05:46.903+0000] {subprocess.py:106} INFO - [0m17:05:46  2 of 3 START sql table model transactional.my_first_dbt_model .................. [RUN]
[2025-03-18T17:05:47.624+0000] {subprocess.py:106} INFO - [0m17:05:47  1 of 3 ERROR creating sql table model transactional.clean_reviews .............. [[31mERROR[0m in 0.67s]
[2025-03-18T17:05:47.952+0000] {subprocess.py:106} INFO - [0m17:05:47  2 of 3 OK created sql table model transactional.my_first_dbt_model ............. [[32mSELECT 2[0m in 1.03s]
[2025-03-18T17:05:47.981+0000] {subprocess.py:106} INFO - [0m17:05:47  3 of 3 START sql view model transactional.my_second_dbt_model .................. [RUN]
[2025-03-18T17:05:48.313+0000] {subprocess.py:106} INFO - [0m17:05:48  3 of 3 ERROR creating sql view model transactional.my_second_dbt_model ......... [[31mERROR[0m in 0.33s]
[2025-03-18T17:05:48.409+0000] {subprocess.py:106} INFO - [0m17:05:48
[2025-03-18T17:05:48.416+0000] {subprocess.py:106} INFO - [0m17:05:48  Finished running 2 table models, 1 view model in 0 hours 0 minutes and 2.62 seconds (2.62s).
[2025-03-18T17:05:48.652+0000] {subprocess.py:106} INFO - [0m17:05:48
[2025-03-18T17:05:48.661+0000] {subprocess.py:106} INFO - [0m17:05:48  [31mCompleted with 2 errors, 0 partial successes, and 0 warnings:[0m
[2025-03-18T17:05:48.663+0000] {subprocess.py:106} INFO - [0m17:05:48
[2025-03-18T17:05:48.677+0000] {subprocess.py:106} INFO - [0m17:05:48    Database Error in model clean_reviews (models/clean_reviews.sql)
[2025-03-18T17:05:48.678+0000] {subprocess.py:106} INFO -   column reference "review_text" is ambiguous
[2025-03-18T17:05:48.678+0000] {subprocess.py:106} INFO -   LINE 160: SELECT id, bank_name, branch_name, location, review_text, cl...
[2025-03-18T17:05:48.679+0000] {subprocess.py:106} INFO -                                                          ^
[2025-03-18T17:05:48.680+0000] {subprocess.py:106} INFO -   compiled code at target/run/bank_reviews_transactional/models/clean_reviews.sql
[2025-03-18T17:05:48.687+0000] {subprocess.py:106} INFO - [0m17:05:48
[2025-03-18T17:05:48.690+0000] {subprocess.py:106} INFO - [0m17:05:48    Database Error in model my_second_dbt_model (models/example/my_second_dbt_model.sql)
[2025-03-18T17:05:48.692+0000] {subprocess.py:106} INFO -   relation "transactional.my_second_dbt_model" does not exist
[2025-03-18T17:05:48.692+0000] {subprocess.py:106} INFO -   compiled code at target/run/bank_reviews_transactional/models/example/my_second_dbt_model.sql
[2025-03-18T17:05:48.695+0000] {subprocess.py:106} INFO - [0m17:05:48
[2025-03-18T17:05:48.697+0000] {subprocess.py:106} INFO - [0m17:05:48  Done. PASS=1 WARN=0 ERROR=2 SKIP=0 TOTAL=3
[2025-03-18T17:05:52.351+0000] {subprocess.py:110} INFO - Command exited with return code 1
[2025-03-18T17:05:52.472+0000] {taskinstance.py:3313} ERROR - Task failed with exception
Traceback (most recent call last):
  File "/home/mohammed/venv/lib/python3.11/site-packages/airflow/models/taskinstance.py", line 768, in _execute_task
    result = _execute_callable(context=context, **execute_callable_kwargs)
             ^^^^^^^^^^^^^^^^^^^^^^^^^^^^^^^^^^^^^^^^^^^^^^^^^^^^^^^^^^^^^
  File "/home/mohammed/venv/lib/python3.11/site-packages/airflow/models/taskinstance.py", line 734, in _execute_callable
    return ExecutionCallableRunner(
           ^^^^^^^^^^^^^^^^^^^^^^^^
  File "/home/mohammed/venv/lib/python3.11/site-packages/airflow/utils/operator_helpers.py", line 252, in run
    return self.func(*args, **kwargs)
           ^^^^^^^^^^^^^^^^^^^^^^^^^^
  File "/home/mohammed/venv/lib/python3.11/site-packages/airflow/models/baseoperator.py", line 424, in wrapper
    return func(self, *args, **kwargs)
           ^^^^^^^^^^^^^^^^^^^^^^^^^^^
  File "/home/mohammed/venv/lib/python3.11/site-packages/airflow/operators/bash.py", line 276, in execute
    raise AirflowException(
airflow.exceptions.AirflowException: Bash command failed. The command returned a non-zero exit code 1.
[2025-03-18T17:05:52.504+0000] {logging_mixin.py:190} INFO - Task instance in failure state
[2025-03-18T17:05:52.505+0000] {logging_mixin.py:190} INFO - Task start:2025-03-18 17:05:15.208317+00:00 end:2025-03-18 17:05:52.500915+00:00 duration:37.292598
[2025-03-18T17:05:52.506+0000] {logging_mixin.py:190} INFO - Task:<Task(BashOperator): dbt_run> dag:<DAG: load_dbt_clean_reviews_pipeline> dagrun:<DagRun load_dbt_clean_reviews_pipeline @ 2024-04-16 00:00:00+00:00: scheduled__2024-04-16T00:00:00+00:00, state:running, queued_at: 2025-03-18 17:05:07.286885+00:00. externally triggered: False>
[2025-03-18T17:05:52.507+0000] {logging_mixin.py:190} INFO - Failure caused by Bash command failed. The command returned a non-zero exit code 1.
[2025-03-18T17:05:52.508+0000] {taskinstance.py:1226} INFO - Marking task as UP_FOR_RETRY. dag_id=load_dbt_clean_reviews_pipeline, task_id=dbt_run, run_id=scheduled__2024-04-16T00:00:00+00:00, execution_date=20240416T000000, start_date=20250318T170515, end_date=20250318T170552
[2025-03-18T17:05:52.827+0000] {taskinstance.py:341} INFO - ::group::Post task execution logs
[2025-03-18T17:05:52.846+0000] {standard_task_runner.py:124} ERROR - Failed to execute job 777 for task dbt_run (Bash command failed. The command returned a non-zero exit code 1.; 50112)
Traceback (most recent call last):
  File "/home/mohammed/venv/lib/python3.11/site-packages/airflow/task/task_runner/standard_task_runner.py", line 117, in _start_by_fork
    ret = args.func(args, dag=self.dag)
          ^^^^^^^^^^^^^^^^^^^^^^^^^^^^^
  File "/home/mohammed/venv/lib/python3.11/site-packages/airflow/cli/cli_config.py", line 49, in command
    return func(*args, **kwargs)
           ^^^^^^^^^^^^^^^^^^^^^
  File "/home/mohammed/venv/lib/python3.11/site-packages/airflow/utils/cli.py", line 116, in wrapper
    return f(*args, **kwargs)
           ^^^^^^^^^^^^^^^^^^
  File "/home/mohammed/venv/lib/python3.11/site-packages/airflow/cli/commands/task_command.py", line 483, in task_run
    task_return_code = _run_task_by_selected_method(args, _dag, ti)
                       ^^^^^^^^^^^^^^^^^^^^^^^^^^^^^^^^^^^^^^^^^^^^
  File "/home/mohammed/venv/lib/python3.11/site-packages/airflow/cli/commands/task_command.py", line 256, in _run_task_by_selected_method
    return _run_raw_task(args, ti)
           ^^^^^^^^^^^^^^^^^^^^^^^
  File "/home/mohammed/venv/lib/python3.11/site-packages/airflow/cli/commands/task_command.py", line 341, in _run_raw_task
    return ti._run_raw_task(
           ^^^^^^^^^^^^^^^^^
  File "/home/mohammed/venv/lib/python3.11/site-packages/airflow/utils/session.py", line 97, in wrapper
    return func(*args, session=session, **kwargs)
           ^^^^^^^^^^^^^^^^^^^^^^^^^^^^^^^^^^^^^^
  File "/home/mohammed/venv/lib/python3.11/site-packages/airflow/models/taskinstance.py", line 3006, in _run_raw_task
    return _run_raw_task(
           ^^^^^^^^^^^^^^
  File "/home/mohammed/venv/lib/python3.11/site-packages/airflow/models/taskinstance.py", line 274, in _run_raw_task
    TaskInstance._execute_task_with_callbacks(
  File "/home/mohammed/venv/lib/python3.11/site-packages/airflow/models/taskinstance.py", line 3161, in _execute_task_with_callbacks
    result = self._execute_task(context, task_orig)
             ^^^^^^^^^^^^^^^^^^^^^^^^^^^^^^^^^^^^^^
  File "/home/mohammed/venv/lib/python3.11/site-packages/airflow/models/taskinstance.py", line 3185, in _execute_task
    return _execute_task(self, context, task_orig)
           ^^^^^^^^^^^^^^^^^^^^^^^^^^^^^^^^^^^^^^^
  File "/home/mohammed/venv/lib/python3.11/site-packages/airflow/models/taskinstance.py", line 768, in _execute_task
    result = _execute_callable(context=context, **execute_callable_kwargs)
             ^^^^^^^^^^^^^^^^^^^^^^^^^^^^^^^^^^^^^^^^^^^^^^^^^^^^^^^^^^^^^
  File "/home/mohammed/venv/lib/python3.11/site-packages/airflow/models/taskinstance.py", line 734, in _execute_callable
    return ExecutionCallableRunner(
           ^^^^^^^^^^^^^^^^^^^^^^^^
  File "/home/mohammed/venv/lib/python3.11/site-packages/airflow/utils/operator_helpers.py", line 252, in run
    return self.func(*args, **kwargs)
           ^^^^^^^^^^^^^^^^^^^^^^^^^^
  File "/home/mohammed/venv/lib/python3.11/site-packages/airflow/models/baseoperator.py", line 424, in wrapper
    return func(self, *args, **kwargs)
           ^^^^^^^^^^^^^^^^^^^^^^^^^^^
  File "/home/mohammed/venv/lib/python3.11/site-packages/airflow/operators/bash.py", line 276, in execute
    raise AirflowException(
airflow.exceptions.AirflowException: Bash command failed. The command returned a non-zero exit code 1.
[2025-03-18T17:05:52.909+0000] {local_task_job_runner.py:266} INFO - Task exited with return code 1
[2025-03-18T17:05:53.059+0000] {taskinstance.py:3901} INFO - 0 downstream tasks scheduled from follow-on schedule check
[2025-03-18T17:05:53.064+0000] {local_task_job_runner.py:245} INFO - ::endgroup::
