[2025-03-17T00:55:18.824+0000] {local_task_job_runner.py:123} INFO - ::group::Pre task execution logs
[2025-03-17T00:55:19.131+0000] {taskinstance.py:2614} INFO - Dependencies all met for dep_context=non-requeueable deps ti=<TaskInstance: load_reviews_pipeline.dbt_run scheduled__2024-08-20T00:00:00+00:00 [queued]>
[2025-03-17T00:55:19.182+0000] {taskinstance.py:2614} INFO - Dependencies all met for dep_context=requeueable deps ti=<TaskInstance: load_reviews_pipeline.dbt_run scheduled__2024-08-20T00:00:00+00:00 [queued]>
[2025-03-17T00:55:19.183+0000] {taskinstance.py:2867} INFO - Starting attempt 1 of 2
[2025-03-17T00:55:19.746+0000] {taskinstance.py:2890} INFO - Executing <Task(BashOperator): dbt_run> on 2024-08-20 00:00:00+00:00
[2025-03-17T00:55:19.789+0000] {standard_task_runner.py:72} INFO - Started process 294008 to run task
[2025-03-17T00:55:19.809+0000] {standard_task_runner.py:104} INFO - Running: ['airflow', 'tasks', 'run', 'load_reviews_pipeline', 'dbt_run', 'scheduled__2024-08-20T00:00:00+00:00', '--job-id', '394', '--raw', '--subdir', 'DAGS_FOLDER/dag_load_reviews.py', '--cfg-path', '/tmp/tmpf9nfl4si']
[2025-03-17T00:55:19.812+0000] {standard_task_runner.py:105} INFO - Job 394: Subtask dbt_run
[2025-03-17T00:55:20.596+0000] {task_command.py:467} INFO - Running <TaskInstance: load_reviews_pipeline.dbt_run scheduled__2024-08-20T00:00:00+00:00 [running]> on host DESKTOP-IM7V4RI.
[2025-03-17T00:55:21.814+0000] {taskinstance.py:3134} INFO - Exporting env vars: AIRFLOW_CTX_DAG_OWNER='mohammed' AIRFLOW_CTX_DAG_ID='load_reviews_pipeline' AIRFLOW_CTX_TASK_ID='dbt_run' AIRFLOW_CTX_EXECUTION_DATE='2024-08-20T00:00:00+00:00' AIRFLOW_CTX_TRY_NUMBER='1' AIRFLOW_CTX_DAG_RUN_ID='scheduled__2024-08-20T00:00:00+00:00'
[2025-03-17T00:55:21.843+0000] {logging_mixin.py:190} INFO - Task instance is in running state
[2025-03-17T00:55:21.844+0000] {logging_mixin.py:190} INFO -  Previous state of the Task instance: queued
[2025-03-17T00:55:21.845+0000] {logging_mixin.py:190} INFO - Current task name:dbt_run state:running start_date:2025-03-17 00:55:19.132301+00:00
[2025-03-17T00:55:21.847+0000] {logging_mixin.py:190} INFO - Dag name:load_reviews_pipeline and current dag run status:running
[2025-03-17T00:55:21.848+0000] {taskinstance.py:732} INFO - ::endgroup::
[2025-03-17T00:55:21.851+0000] {subprocess.py:78} INFO - Tmp dir root location: /tmp
[2025-03-17T00:55:21.858+0000] {subprocess.py:88} INFO - Running command: ['/usr/bin/bash', '-c', 'cd /home/mohammed/.dbt/bank_reviews_project && dbt run']
[2025-03-17T00:55:21.924+0000] {subprocess.py:99} INFO - Output:
[2025-03-17T00:55:34.220+0000] {subprocess.py:106} INFO - [0m00:55:34  Running with dbt=1.9.3
[2025-03-17T00:55:36.537+0000] {subprocess.py:106} INFO - [0m00:55:36  Registered adapter: postgres=1.9.0
[2025-03-17T00:55:40.076+0000] {subprocess.py:106} INFO - [0m00:55:40  Found 10 models, 4 data tests, 2 sources, 433 macros
[2025-03-17T00:55:40.100+0000] {subprocess.py:106} INFO - [0m00:55:40
[2025-03-17T00:55:40.102+0000] {subprocess.py:106} INFO - [0m00:55:40  Concurrency: 4 threads (target='dev')
[2025-03-17T00:55:40.107+0000] {subprocess.py:106} INFO - [0m00:55:40
[2025-03-17T00:55:41.306+0000] {subprocess.py:106} INFO - [0m00:55:41  1 of 10 START sql view model public.clean_reviews .............................. [RUN]
[2025-03-17T00:55:41.333+0000] {subprocess.py:106} INFO - [0m00:55:41  2 of 10 START sql table model public.my_first_dbt_model ........................ [RUN]
[2025-03-17T00:55:41.345+0000] {subprocess.py:106} INFO - [0m00:55:41  4 of 10 START sql view model public.stg_clean_reviews .......................... [RUN]
[2025-03-17T00:55:41.412+0000] {subprocess.py:106} INFO - [0m00:55:41  3 of 10 START sql view model public.remove_duplicates .......................... [RUN]
[2025-03-17T00:55:44.187+0000] {subprocess.py:106} INFO - [0m00:55:44  2 of 10 OK created sql table model public.my_first_dbt_model ................... [[32mSELECT 2[0m in 2.80s]
[2025-03-17T00:55:44.193+0000] {subprocess.py:106} INFO - [0m00:55:44  3 of 10 OK created sql view model public.remove_duplicates ..................... [[32mCREATE VIEW[0m in 2.79s]
[2025-03-17T00:55:44.201+0000] {subprocess.py:106} INFO - [0m00:55:44  5 of 10 START sql view model public.my_second_dbt_model ........................ [RUN]
[2025-03-17T00:55:44.685+0000] {subprocess.py:106} INFO - [0m00:55:44  4 of 10 ERROR creating sql view model public.stg_clean_reviews ................. [[31mERROR[0m in 3.28s]
[2025-03-17T00:55:44.772+0000] {subprocess.py:106} INFO - [0m00:55:44  6 of 10 SKIP relation public.dim_bank .......................................... [[33mSKIP[0m]
[2025-03-17T00:55:44.804+0000] {subprocess.py:106} INFO - [0m00:55:44  7 of 10 SKIP relation public.dim_branch ........................................ [[33mSKIP[0m]
[2025-03-17T00:55:44.810+0000] {subprocess.py:106} INFO - [0m00:55:44  8 of 10 SKIP relation public.dim_location ...................................... [[33mSKIP[0m]
[2025-03-17T00:55:44.833+0000] {subprocess.py:106} INFO - [0m00:55:44  1 of 10 ERROR creating sql view model public.clean_reviews ..................... [[31mERROR[0m in 3.50s]
[2025-03-17T00:55:44.850+0000] {subprocess.py:106} INFO - [0m00:55:44  9 of 10 SKIP relation public.dim_sentiment ..................................... [[33mSKIP[0m]
[2025-03-17T00:55:44.856+0000] {subprocess.py:106} INFO - [0m00:55:44  10 of 10 SKIP relation public.fact_reviews ..................................... [[33mSKIP[0m]
[2025-03-17T00:55:44.999+0000] {subprocess.py:106} INFO - [0m00:55:44  5 of 10 OK created sql view model public.my_second_dbt_model ................... [[32mCREATE VIEW[0m in 0.78s]
[2025-03-17T00:55:45.156+0000] {subprocess.py:106} INFO - [0m00:55:45
[2025-03-17T00:55:45.158+0000] {subprocess.py:106} INFO - [0m00:55:45  Finished running 1 table model, 9 view models in 0 hours 0 minutes and 5.05 seconds (5.05s).
[2025-03-17T00:55:45.453+0000] {subprocess.py:106} INFO - [0m00:55:45
[2025-03-17T00:55:45.455+0000] {subprocess.py:106} INFO - [0m00:55:45  [31mCompleted with 2 errors, 0 partial successes, and 0 warnings:[0m
[2025-03-17T00:55:45.457+0000] {subprocess.py:106} INFO - [0m00:55:45
[2025-03-17T00:55:45.460+0000] {subprocess.py:106} INFO - [0m00:55:45    Database Error in model stg_clean_reviews (models/stg_clean_reviews.sql)
[2025-03-17T00:55:45.462+0000] {subprocess.py:106} INFO -   relation "stg_clean_reviews__dbt_backup" already exists
[2025-03-17T00:55:45.463+0000] {subprocess.py:106} INFO -   compiled code at target/run/bank_reviews_project/models/stg_clean_reviews.sql
[2025-03-17T00:55:45.463+0000] {subprocess.py:106} INFO - [0m00:55:45
[2025-03-17T00:55:45.466+0000] {subprocess.py:106} INFO - [0m00:55:45    Database Error in model clean_reviews (models/clean_reviews.sql)
[2025-03-17T00:55:45.467+0000] {subprocess.py:106} INFO -   relation "clean_reviews__dbt_backup" already exists
[2025-03-17T00:55:45.467+0000] {subprocess.py:106} INFO -   compiled code at target/run/bank_reviews_project/models/clean_reviews.sql
[2025-03-17T00:55:45.467+0000] {subprocess.py:106} INFO - [0m00:55:45
[2025-03-17T00:55:45.469+0000] {subprocess.py:106} INFO - [0m00:55:45  Done. PASS=3 WARN=0 ERROR=2 SKIP=5 TOTAL=10
[2025-03-17T00:55:51.772+0000] {subprocess.py:110} INFO - Command exited with return code 1
[2025-03-17T00:55:51.958+0000] {taskinstance.py:3313} ERROR - Task failed with exception
Traceback (most recent call last):
  File "/home/mohammed/venv/lib/python3.11/site-packages/airflow/models/taskinstance.py", line 768, in _execute_task
    result = _execute_callable(context=context, **execute_callable_kwargs)
             ^^^^^^^^^^^^^^^^^^^^^^^^^^^^^^^^^^^^^^^^^^^^^^^^^^^^^^^^^^^^^
  File "/home/mohammed/venv/lib/python3.11/site-packages/airflow/models/taskinstance.py", line 734, in _execute_callable
    return ExecutionCallableRunner(
           ^^^^^^^^^^^^^^^^^^^^^^^^
  File "/home/mohammed/venv/lib/python3.11/site-packages/airflow/utils/operator_helpers.py", line 252, in run
    return self.func(*args, **kwargs)
           ^^^^^^^^^^^^^^^^^^^^^^^^^^
  File "/home/mohammed/venv/lib/python3.11/site-packages/airflow/models/baseoperator.py", line 424, in wrapper
    return func(self, *args, **kwargs)
           ^^^^^^^^^^^^^^^^^^^^^^^^^^^
  File "/home/mohammed/venv/lib/python3.11/site-packages/airflow/operators/bash.py", line 276, in execute
    raise AirflowException(
airflow.exceptions.AirflowException: Bash command failed. The command returned a non-zero exit code 1.
[2025-03-17T00:55:52.037+0000] {logging_mixin.py:190} INFO - Task instance in failure state
[2025-03-17T00:55:52.038+0000] {logging_mixin.py:190} INFO - Task start:2025-03-17 00:55:19.132301+00:00 end:2025-03-17 00:55:52.022429+00:00 duration:32.890128
[2025-03-17T00:55:52.039+0000] {logging_mixin.py:190} INFO - Task:<Task(BashOperator): dbt_run> dag:<DAG: load_reviews_pipeline> dagrun:<DagRun load_reviews_pipeline @ 2024-08-20 00:00:00+00:00: scheduled__2024-08-20T00:00:00+00:00, state:running, queued_at: 2025-03-17 00:55:03.903387+00:00. externally triggered: False>
[2025-03-17T00:55:52.040+0000] {logging_mixin.py:190} INFO - Failure caused by Bash command failed. The command returned a non-zero exit code 1.
[2025-03-17T00:55:52.041+0000] {taskinstance.py:1226} INFO - Marking task as UP_FOR_RETRY. dag_id=load_reviews_pipeline, task_id=dbt_run, run_id=scheduled__2024-08-20T00:00:00+00:00, execution_date=20240820T000000, start_date=20250317T005519, end_date=20250317T005552
[2025-03-17T00:55:52.608+0000] {taskinstance.py:341} INFO - ::group::Post task execution logs
[2025-03-17T00:55:52.611+0000] {standard_task_runner.py:124} ERROR - Failed to execute job 394 for task dbt_run (Bash command failed. The command returned a non-zero exit code 1.; 294008)
Traceback (most recent call last):
  File "/home/mohammed/venv/lib/python3.11/site-packages/airflow/task/task_runner/standard_task_runner.py", line 117, in _start_by_fork
    ret = args.func(args, dag=self.dag)
          ^^^^^^^^^^^^^^^^^^^^^^^^^^^^^
  File "/home/mohammed/venv/lib/python3.11/site-packages/airflow/cli/cli_config.py", line 49, in command
    return func(*args, **kwargs)
           ^^^^^^^^^^^^^^^^^^^^^
  File "/home/mohammed/venv/lib/python3.11/site-packages/airflow/utils/cli.py", line 116, in wrapper
    return f(*args, **kwargs)
           ^^^^^^^^^^^^^^^^^^
  File "/home/mohammed/venv/lib/python3.11/site-packages/airflow/cli/commands/task_command.py", line 483, in task_run
    task_return_code = _run_task_by_selected_method(args, _dag, ti)
                       ^^^^^^^^^^^^^^^^^^^^^^^^^^^^^^^^^^^^^^^^^^^^
  File "/home/mohammed/venv/lib/python3.11/site-packages/airflow/cli/commands/task_command.py", line 256, in _run_task_by_selected_method
    return _run_raw_task(args, ti)
           ^^^^^^^^^^^^^^^^^^^^^^^
  File "/home/mohammed/venv/lib/python3.11/site-packages/airflow/cli/commands/task_command.py", line 341, in _run_raw_task
    return ti._run_raw_task(
           ^^^^^^^^^^^^^^^^^
  File "/home/mohammed/venv/lib/python3.11/site-packages/airflow/utils/session.py", line 97, in wrapper
    return func(*args, session=session, **kwargs)
           ^^^^^^^^^^^^^^^^^^^^^^^^^^^^^^^^^^^^^^
  File "/home/mohammed/venv/lib/python3.11/site-packages/airflow/models/taskinstance.py", line 3006, in _run_raw_task
    return _run_raw_task(
           ^^^^^^^^^^^^^^
  File "/home/mohammed/venv/lib/python3.11/site-packages/airflow/models/taskinstance.py", line 274, in _run_raw_task
    TaskInstance._execute_task_with_callbacks(
  File "/home/mohammed/venv/lib/python3.11/site-packages/airflow/models/taskinstance.py", line 3161, in _execute_task_with_callbacks
    result = self._execute_task(context, task_orig)
             ^^^^^^^^^^^^^^^^^^^^^^^^^^^^^^^^^^^^^^
  File "/home/mohammed/venv/lib/python3.11/site-packages/airflow/models/taskinstance.py", line 3185, in _execute_task
    return _execute_task(self, context, task_orig)
           ^^^^^^^^^^^^^^^^^^^^^^^^^^^^^^^^^^^^^^^
  File "/home/mohammed/venv/lib/python3.11/site-packages/airflow/models/taskinstance.py", line 768, in _execute_task
    result = _execute_callable(context=context, **execute_callable_kwargs)
             ^^^^^^^^^^^^^^^^^^^^^^^^^^^^^^^^^^^^^^^^^^^^^^^^^^^^^^^^^^^^^
  File "/home/mohammed/venv/lib/python3.11/site-packages/airflow/models/taskinstance.py", line 734, in _execute_callable
    return ExecutionCallableRunner(
           ^^^^^^^^^^^^^^^^^^^^^^^^
  File "/home/mohammed/venv/lib/python3.11/site-packages/airflow/utils/operator_helpers.py", line 252, in run
    return self.func(*args, **kwargs)
           ^^^^^^^^^^^^^^^^^^^^^^^^^^
  File "/home/mohammed/venv/lib/python3.11/site-packages/airflow/models/baseoperator.py", line 424, in wrapper
    return func(self, *args, **kwargs)
           ^^^^^^^^^^^^^^^^^^^^^^^^^^^
  File "/home/mohammed/venv/lib/python3.11/site-packages/airflow/operators/bash.py", line 276, in execute
    raise AirflowException(
airflow.exceptions.AirflowException: Bash command failed. The command returned a non-zero exit code 1.
[2025-03-17T00:55:52.753+0000] {local_task_job_runner.py:266} INFO - Task exited with return code 1
[2025-03-17T00:55:53.063+0000] {taskinstance.py:3901} INFO - 0 downstream tasks scheduled from follow-on schedule check
[2025-03-17T00:55:53.114+0000] {local_task_job_runner.py:245} INFO - ::endgroup::
