[2025-03-17T01:19:10.923+0000] {local_task_job_runner.py:123} INFO - ::group::Pre task execution logs
[2025-03-17T01:19:11.014+0000] {taskinstance.py:2614} INFO - Dependencies all met for dep_context=non-requeueable deps ti=<TaskInstance: load_reviews_pipeline.dbt_run scheduled__2025-03-02T00:00:00+00:00 [queued]>
[2025-03-17T01:19:11.039+0000] {taskinstance.py:2614} INFO - Dependencies all met for dep_context=requeueable deps ti=<TaskInstance: load_reviews_pipeline.dbt_run scheduled__2025-03-02T00:00:00+00:00 [queued]>
[2025-03-17T01:19:11.040+0000] {taskinstance.py:2867} INFO - Starting attempt 1 of 2
[2025-03-17T01:19:11.075+0000] {taskinstance.py:2890} INFO - Executing <Task(BashOperator): dbt_run> on 2025-03-02 00:00:00+00:00
[2025-03-17T01:19:11.084+0000] {standard_task_runner.py:72} INFO - Started process 329900 to run task
[2025-03-17T01:19:11.106+0000] {standard_task_runner.py:104} INFO - Running: ['airflow', 'tasks', 'run', 'load_reviews_pipeline', 'dbt_run', 'scheduled__2025-03-02T00:00:00+00:00', '--job-id', '646', '--raw', '--subdir', 'DAGS_FOLDER/dag_load_reviews.py', '--cfg-path', '/tmp/tmpm1vmq48w']
[2025-03-17T01:19:11.108+0000] {standard_task_runner.py:105} INFO - Job 646: Subtask dbt_run
[2025-03-17T01:19:11.307+0000] {task_command.py:467} INFO - Running <TaskInstance: load_reviews_pipeline.dbt_run scheduled__2025-03-02T00:00:00+00:00 [running]> on host DESKTOP-IM7V4RI.
[2025-03-17T01:19:11.579+0000] {taskinstance.py:3134} INFO - Exporting env vars: AIRFLOW_CTX_DAG_OWNER='mohammed' AIRFLOW_CTX_DAG_ID='load_reviews_pipeline' AIRFLOW_CTX_TASK_ID='dbt_run' AIRFLOW_CTX_EXECUTION_DATE='2025-03-02T00:00:00+00:00' AIRFLOW_CTX_TRY_NUMBER='1' AIRFLOW_CTX_DAG_RUN_ID='scheduled__2025-03-02T00:00:00+00:00'
[2025-03-17T01:19:11.581+0000] {logging_mixin.py:190} INFO - Task instance is in running state
[2025-03-17T01:19:11.581+0000] {logging_mixin.py:190} INFO -  Previous state of the Task instance: queued
[2025-03-17T01:19:11.582+0000] {logging_mixin.py:190} INFO - Current task name:dbt_run state:running start_date:2025-03-17 01:19:11.015357+00:00
[2025-03-17T01:19:11.582+0000] {logging_mixin.py:190} INFO - Dag name:load_reviews_pipeline and current dag run status:running
[2025-03-17T01:19:11.582+0000] {taskinstance.py:732} INFO - ::endgroup::
[2025-03-17T01:19:11.583+0000] {subprocess.py:78} INFO - Tmp dir root location: /tmp
[2025-03-17T01:19:11.584+0000] {subprocess.py:88} INFO - Running command: ['/usr/bin/bash', '-c', 'cd /home/mohammed/.dbt/bank_reviews_project && dbt run']
[2025-03-17T01:19:11.599+0000] {subprocess.py:99} INFO - Output:
[2025-03-17T01:19:15.757+0000] {subprocess.py:106} INFO - [0m01:19:15  Running with dbt=1.9.3
[2025-03-17T01:19:16.432+0000] {subprocess.py:106} INFO - [0m01:19:16  Registered adapter: postgres=1.9.0
[2025-03-17T01:19:17.562+0000] {subprocess.py:106} INFO - [0m01:19:17  Found 10 models, 4 data tests, 2 sources, 433 macros
[2025-03-17T01:19:17.575+0000] {subprocess.py:106} INFO - [0m01:19:17
[2025-03-17T01:19:17.575+0000] {subprocess.py:106} INFO - [0m01:19:17  Concurrency: 4 threads (target='dev')
[2025-03-17T01:19:17.577+0000] {subprocess.py:106} INFO - [0m01:19:17
[2025-03-17T01:19:18.027+0000] {subprocess.py:106} INFO - [0m01:19:18  1 of 10 START sql view model public.clean_reviews .............................. [RUN]
[2025-03-17T01:19:18.031+0000] {subprocess.py:106} INFO - [0m01:19:18  2 of 10 START sql table model public.my_first_dbt_model ........................ [RUN]
[2025-03-17T01:19:18.051+0000] {subprocess.py:106} INFO - [0m01:19:18  3 of 10 START sql view model public.remove_duplicates .......................... [RUN]
[2025-03-17T01:19:18.052+0000] {subprocess.py:106} INFO - [0m01:19:18  4 of 10 START sql view model public.stg_clean_reviews .......................... [RUN]
[2025-03-17T01:19:18.704+0000] {subprocess.py:106} INFO - [0m01:19:18  2 of 10 OK created sql table model public.my_first_dbt_model ................... [[32mSELECT 2[0m in 0.67s]
[2025-03-17T01:19:18.739+0000] {subprocess.py:106} INFO - [0m01:19:18  5 of 10 START sql view model public.my_second_dbt_model ........................ [RUN]
[2025-03-17T01:19:18.882+0000] {subprocess.py:106} INFO - [0m01:19:18  4 of 10 ERROR creating sql view model public.stg_clean_reviews ................. [[31mERROR[0m in 0.81s]
[2025-03-17T01:19:18.907+0000] {subprocess.py:106} INFO - [0m01:19:18  3 of 10 ERROR creating sql view model public.remove_duplicates ................. [[31mERROR[0m in 0.84s]
[2025-03-17T01:19:18.910+0000] {subprocess.py:106} INFO - [0m01:19:18  6 of 10 SKIP relation public.dim_bank .......................................... [[33mSKIP[0m]
[2025-03-17T01:19:18.923+0000] {subprocess.py:106} INFO - [0m01:19:18  1 of 10 ERROR creating sql view model public.clean_reviews ..................... [[31mERROR[0m in 0.90s]
[2025-03-17T01:19:18.946+0000] {subprocess.py:106} INFO - [0m01:19:18  8 of 10 SKIP relation public.dim_location ...................................... [[33mSKIP[0m]
[2025-03-17T01:19:18.947+0000] {subprocess.py:106} INFO - [0m01:19:18  7 of 10 SKIP relation public.dim_branch ........................................ [[33mSKIP[0m]
[2025-03-17T01:19:18.951+0000] {subprocess.py:106} INFO - [0m01:19:18  9 of 10 SKIP relation public.dim_sentiment ..................................... [[33mSKIP[0m]
[2025-03-17T01:19:18.972+0000] {subprocess.py:106} INFO - [0m01:19:18  10 of 10 SKIP relation public.fact_reviews ..................................... [[33mSKIP[0m]
[2025-03-17T01:19:19.104+0000] {subprocess.py:106} INFO - [0m01:19:19  5 of 10 ERROR creating sql view model public.my_second_dbt_model ............... [[31mERROR[0m in 0.36s]
[2025-03-17T01:19:19.143+0000] {subprocess.py:106} INFO - [0m01:19:19
[2025-03-17T01:19:19.144+0000] {subprocess.py:106} INFO - [0m01:19:19  Finished running 1 table model, 9 view models in 0 hours 0 minutes and 1.57 seconds (1.57s).
[2025-03-17T01:19:19.220+0000] {subprocess.py:106} INFO - [0m01:19:19
[2025-03-17T01:19:19.221+0000] {subprocess.py:106} INFO - [0m01:19:19  [31mCompleted with 4 errors, 0 partial successes, and 0 warnings:[0m
[2025-03-17T01:19:19.222+0000] {subprocess.py:106} INFO - [0m01:19:19
[2025-03-17T01:19:19.223+0000] {subprocess.py:106} INFO - [0m01:19:19    Database Error in model stg_clean_reviews (models/stg_clean_reviews.sql)
[2025-03-17T01:19:19.224+0000] {subprocess.py:106} INFO -   relation "stg_clean_reviews__dbt_backup" already exists
[2025-03-17T01:19:19.224+0000] {subprocess.py:106} INFO -   compiled code at target/run/bank_reviews_project/models/stg_clean_reviews.sql
[2025-03-17T01:19:19.224+0000] {subprocess.py:106} INFO - [0m01:19:19
[2025-03-17T01:19:19.225+0000] {subprocess.py:106} INFO - [0m01:19:19    Database Error in model remove_duplicates (models/remove_duplicates.sql)
[2025-03-17T01:19:19.226+0000] {subprocess.py:106} INFO -   relation "remove_duplicates__dbt_backup" already exists
[2025-03-17T01:19:19.226+0000] {subprocess.py:106} INFO -   compiled code at target/run/bank_reviews_project/models/remove_duplicates.sql
[2025-03-17T01:19:19.226+0000] {subprocess.py:106} INFO - [0m01:19:19
[2025-03-17T01:19:19.227+0000] {subprocess.py:106} INFO - [0m01:19:19    Database Error in model clean_reviews (models/clean_reviews.sql)
[2025-03-17T01:19:19.228+0000] {subprocess.py:106} INFO -   relation "clean_reviews__dbt_backup" already exists
[2025-03-17T01:19:19.228+0000] {subprocess.py:106} INFO -   compiled code at target/run/bank_reviews_project/models/clean_reviews.sql
[2025-03-17T01:19:19.229+0000] {subprocess.py:106} INFO - [0m01:19:19
[2025-03-17T01:19:19.229+0000] {subprocess.py:106} INFO - [0m01:19:19    Database Error in model my_second_dbt_model (models/example/my_second_dbt_model.sql)
[2025-03-17T01:19:19.230+0000] {subprocess.py:106} INFO -   relation "my_second_dbt_model" already exists
[2025-03-17T01:19:19.230+0000] {subprocess.py:106} INFO -   compiled code at target/run/bank_reviews_project/models/example/my_second_dbt_model.sql
[2025-03-17T01:19:19.230+0000] {subprocess.py:106} INFO - [0m01:19:19
[2025-03-17T01:19:19.231+0000] {subprocess.py:106} INFO - [0m01:19:19  Done. PASS=1 WARN=0 ERROR=4 SKIP=5 TOTAL=10
[2025-03-17T01:19:21.777+0000] {subprocess.py:110} INFO - Command exited with return code 1
[2025-03-17T01:19:21.815+0000] {taskinstance.py:3313} ERROR - Task failed with exception
Traceback (most recent call last):
  File "/home/mohammed/venv/lib/python3.11/site-packages/airflow/models/taskinstance.py", line 768, in _execute_task
    result = _execute_callable(context=context, **execute_callable_kwargs)
             ^^^^^^^^^^^^^^^^^^^^^^^^^^^^^^^^^^^^^^^^^^^^^^^^^^^^^^^^^^^^^
  File "/home/mohammed/venv/lib/python3.11/site-packages/airflow/models/taskinstance.py", line 734, in _execute_callable
    return ExecutionCallableRunner(
           ^^^^^^^^^^^^^^^^^^^^^^^^
  File "/home/mohammed/venv/lib/python3.11/site-packages/airflow/utils/operator_helpers.py", line 252, in run
    return self.func(*args, **kwargs)
           ^^^^^^^^^^^^^^^^^^^^^^^^^^
  File "/home/mohammed/venv/lib/python3.11/site-packages/airflow/models/baseoperator.py", line 424, in wrapper
    return func(self, *args, **kwargs)
           ^^^^^^^^^^^^^^^^^^^^^^^^^^^
  File "/home/mohammed/venv/lib/python3.11/site-packages/airflow/operators/bash.py", line 276, in execute
    raise AirflowException(
airflow.exceptions.AirflowException: Bash command failed. The command returned a non-zero exit code 1.
[2025-03-17T01:19:21.832+0000] {logging_mixin.py:190} INFO - Task instance in failure state
[2025-03-17T01:19:21.833+0000] {logging_mixin.py:190} INFO - Task start:2025-03-17 01:19:11.015357+00:00 end:2025-03-17 01:19:21.830745+00:00 duration:10.815388
[2025-03-17T01:19:21.833+0000] {logging_mixin.py:190} INFO - Task:<Task(BashOperator): dbt_run> dag:<DAG: load_reviews_pipeline> dagrun:<DagRun load_reviews_pipeline @ 2025-03-02 00:00:00+00:00: scheduled__2025-03-02T00:00:00+00:00, state:running, queued_at: 2025-03-17 01:19:09.050135+00:00. externally triggered: False>
[2025-03-17T01:19:21.834+0000] {logging_mixin.py:190} INFO - Failure caused by Bash command failed. The command returned a non-zero exit code 1.
[2025-03-17T01:19:21.834+0000] {taskinstance.py:1226} INFO - Marking task as UP_FOR_RETRY. dag_id=load_reviews_pipeline, task_id=dbt_run, run_id=scheduled__2025-03-02T00:00:00+00:00, execution_date=20250302T000000, start_date=20250317T011911, end_date=20250317T011921
[2025-03-17T01:19:21.914+0000] {taskinstance.py:341} INFO - ::group::Post task execution logs
[2025-03-17T01:19:21.915+0000] {standard_task_runner.py:124} ERROR - Failed to execute job 646 for task dbt_run (Bash command failed. The command returned a non-zero exit code 1.; 329900)
Traceback (most recent call last):
  File "/home/mohammed/venv/lib/python3.11/site-packages/airflow/task/task_runner/standard_task_runner.py", line 117, in _start_by_fork
    ret = args.func(args, dag=self.dag)
          ^^^^^^^^^^^^^^^^^^^^^^^^^^^^^
  File "/home/mohammed/venv/lib/python3.11/site-packages/airflow/cli/cli_config.py", line 49, in command
    return func(*args, **kwargs)
           ^^^^^^^^^^^^^^^^^^^^^
  File "/home/mohammed/venv/lib/python3.11/site-packages/airflow/utils/cli.py", line 116, in wrapper
    return f(*args, **kwargs)
           ^^^^^^^^^^^^^^^^^^
  File "/home/mohammed/venv/lib/python3.11/site-packages/airflow/cli/commands/task_command.py", line 483, in task_run
    task_return_code = _run_task_by_selected_method(args, _dag, ti)
                       ^^^^^^^^^^^^^^^^^^^^^^^^^^^^^^^^^^^^^^^^^^^^
  File "/home/mohammed/venv/lib/python3.11/site-packages/airflow/cli/commands/task_command.py", line 256, in _run_task_by_selected_method
    return _run_raw_task(args, ti)
           ^^^^^^^^^^^^^^^^^^^^^^^
  File "/home/mohammed/venv/lib/python3.11/site-packages/airflow/cli/commands/task_command.py", line 341, in _run_raw_task
    return ti._run_raw_task(
           ^^^^^^^^^^^^^^^^^
  File "/home/mohammed/venv/lib/python3.11/site-packages/airflow/utils/session.py", line 97, in wrapper
    return func(*args, session=session, **kwargs)
           ^^^^^^^^^^^^^^^^^^^^^^^^^^^^^^^^^^^^^^
  File "/home/mohammed/venv/lib/python3.11/site-packages/airflow/models/taskinstance.py", line 3006, in _run_raw_task
    return _run_raw_task(
           ^^^^^^^^^^^^^^
  File "/home/mohammed/venv/lib/python3.11/site-packages/airflow/models/taskinstance.py", line 274, in _run_raw_task
    TaskInstance._execute_task_with_callbacks(
  File "/home/mohammed/venv/lib/python3.11/site-packages/airflow/models/taskinstance.py", line 3161, in _execute_task_with_callbacks
    result = self._execute_task(context, task_orig)
             ^^^^^^^^^^^^^^^^^^^^^^^^^^^^^^^^^^^^^^
  File "/home/mohammed/venv/lib/python3.11/site-packages/airflow/models/taskinstance.py", line 3185, in _execute_task
    return _execute_task(self, context, task_orig)
           ^^^^^^^^^^^^^^^^^^^^^^^^^^^^^^^^^^^^^^^
  File "/home/mohammed/venv/lib/python3.11/site-packages/airflow/models/taskinstance.py", line 768, in _execute_task
    result = _execute_callable(context=context, **execute_callable_kwargs)
             ^^^^^^^^^^^^^^^^^^^^^^^^^^^^^^^^^^^^^^^^^^^^^^^^^^^^^^^^^^^^^
  File "/home/mohammed/venv/lib/python3.11/site-packages/airflow/models/taskinstance.py", line 734, in _execute_callable
    return ExecutionCallableRunner(
           ^^^^^^^^^^^^^^^^^^^^^^^^
  File "/home/mohammed/venv/lib/python3.11/site-packages/airflow/utils/operator_helpers.py", line 252, in run
    return self.func(*args, **kwargs)
           ^^^^^^^^^^^^^^^^^^^^^^^^^^
  File "/home/mohammed/venv/lib/python3.11/site-packages/airflow/models/baseoperator.py", line 424, in wrapper
    return func(self, *args, **kwargs)
           ^^^^^^^^^^^^^^^^^^^^^^^^^^^
  File "/home/mohammed/venv/lib/python3.11/site-packages/airflow/operators/bash.py", line 276, in execute
    raise AirflowException(
airflow.exceptions.AirflowException: Bash command failed. The command returned a non-zero exit code 1.
[2025-03-17T01:19:21.958+0000] {local_task_job_runner.py:266} INFO - Task exited with return code 1
[2025-03-17T01:19:22.010+0000] {taskinstance.py:3901} INFO - 0 downstream tasks scheduled from follow-on schedule check
[2025-03-17T01:19:22.013+0000] {local_task_job_runner.py:245} INFO - ::endgroup::
