[2025-05-28T18:09:03.749+0100] {local_task_job_runner.py:123} INFO - ::group::Pre task execution logs
[2025-05-28T18:09:03.958+0100] {taskinstance.py:2614} INFO - Dependencies all met for dep_context=non-requeueable deps ti=<TaskInstance: bank_reviews_etl_and_analysis_pipeline.dbt_run_decisionnal scheduled__2025-04-20T00:00:00+00:00 [queued]>
[2025-05-28T18:09:03.992+0100] {taskinstance.py:2614} INFO - Dependencies all met for dep_context=requeueable deps ti=<TaskInstance: bank_reviews_etl_and_analysis_pipeline.dbt_run_decisionnal scheduled__2025-04-20T00:00:00+00:00 [queued]>
[2025-05-28T18:09:03.993+0100] {taskinstance.py:2867} INFO - Starting attempt 1 of 2
[2025-05-28T18:09:04.264+0100] {taskinstance.py:2890} INFO - Executing <Task(BashOperator): dbt_run_decisionnal> on 2025-04-20 00:00:00+00:00
[2025-05-28T18:09:04.273+0100] {standard_task_runner.py:72} INFO - Started process 956 to run task
[2025-05-28T18:09:04.303+0100] {standard_task_runner.py:104} INFO - Running: ['airflow', 'tasks', 'run', 'bank_reviews_etl_and_analysis_pipeline', 'dbt_run_decisionnal', 'scheduled__2025-04-20T00:00:00+00:00', '--job-id', '2503', '--raw', '--subdir', 'DAGS_FOLDER/dag_load_reviews.py', '--cfg-path', '/tmp/tmprk2rp6vr']
[2025-05-28T18:09:04.312+0100] {standard_task_runner.py:105} INFO - Job 2503: Subtask dbt_run_decisionnal
[2025-05-28T18:09:04.759+0100] {task_command.py:467} INFO - Running <TaskInstance: bank_reviews_etl_and_analysis_pipeline.dbt_run_decisionnal scheduled__2025-04-20T00:00:00+00:00 [running]> on host DESKTOP-IM7V4RI.
[2025-05-28T18:09:06.437+0100] {taskinstance.py:3134} INFO - Exporting env vars: AIRFLOW_CTX_DAG_OWNER='mohammed' AIRFLOW_CTX_DAG_ID='bank_reviews_etl_and_analysis_pipeline' AIRFLOW_CTX_TASK_ID='dbt_run_decisionnal' AIRFLOW_CTX_EXECUTION_DATE='2025-04-20T00:00:00+00:00' AIRFLOW_CTX_TRY_NUMBER='1' AIRFLOW_CTX_DAG_RUN_ID='scheduled__2025-04-20T00:00:00+00:00'
[2025-05-28T18:09:06.440+0100] {logging_mixin.py:190} INFO - Task instance is in running state
[2025-05-28T18:09:06.440+0100] {logging_mixin.py:190} INFO -  Previous state of the Task instance: queued
[2025-05-28T18:09:06.441+0100] {logging_mixin.py:190} INFO - Current task name:dbt_run_decisionnal state:running start_date:2025-05-28 17:09:03.959236+00:00
[2025-05-28T18:09:06.441+0100] {logging_mixin.py:190} INFO - Dag name:bank_reviews_etl_and_analysis_pipeline and current dag run status:running
[2025-05-28T18:09:06.443+0100] {taskinstance.py:732} INFO - ::endgroup::
[2025-05-28T18:09:06.451+0100] {subprocess.py:78} INFO - Tmp dir root location: /tmp
[2025-05-28T18:09:06.464+0100] {subprocess.py:88} INFO - Running command: ['/usr/bin/bash', '-c', 'cd /home/mohammed/.dbt/dbt_projects/bank_reviews_decisionnal && dbt run --full-refresh']
[2025-05-28T18:09:06.573+0100] {subprocess.py:99} INFO - Output:
[2025-05-28T18:09:26.318+0100] {subprocess.py:106} INFO - [0m17:09:26  Running with dbt=1.9.3
[2025-05-28T18:09:28.426+0100] {subprocess.py:106} INFO - [0m17:09:28  Registered adapter: postgres=1.9.0
[2025-05-28T18:09:30.926+0100] {subprocess.py:106} INFO - [0m17:09:30  [[33mWARNING[0m]: Configuration paths exist in your dbt_project.yml file which do not apply to any resources.
[2025-05-28T18:09:30.927+0100] {subprocess.py:106} INFO - There are 1 unused configuration paths:
[2025-05-28T18:09:30.927+0100] {subprocess.py:106} INFO - - models.bank_reviews_decisionnal.decisionnal
[2025-05-28T18:09:31.817+0100] {subprocess.py:106} INFO - [0m17:09:31  Found 5 models, 2 sources, 547 macros
[2025-05-28T18:09:31.831+0100] {subprocess.py:106} INFO - [0m17:09:31
[2025-05-28T18:09:31.833+0100] {subprocess.py:106} INFO - [0m17:09:31  Concurrency: 4 threads (target='dev')
[2025-05-28T18:09:31.836+0100] {subprocess.py:106} INFO - [0m17:09:31
[2025-05-28T18:09:34.216+0100] {subprocess.py:106} INFO - [0m17:09:34  1 of 5 START sql table model decisionnal.dim_bank .............................. [RUN]
[2025-05-28T18:09:34.235+0100] {subprocess.py:106} INFO - [0m17:09:34  2 of 5 START sql table model decisionnal.dim_branch ............................ [RUN]
[2025-05-28T18:09:34.277+0100] {subprocess.py:106} INFO - [0m17:09:34  3 of 5 START sql table model decisionnal.dim_location .......................... [RUN]
[2025-05-28T18:09:34.344+0100] {subprocess.py:106} INFO - [0m17:09:34  4 of 5 START sql table model decisionnal.dim_sentiment ......................... [RUN]
[2025-05-28T18:09:38.536+0100] {subprocess.py:106} INFO - [0m17:09:38  4 of 5 OK created sql table model decisionnal.dim_sentiment .................... [[32mSELECT 3[0m in 4.18s]
[2025-05-28T18:09:38.547+0100] {subprocess.py:106} INFO - [0m17:09:38  1 of 5 OK created sql table model decisionnal.dim_bank ......................... [[32mSELECT 299[0m in 4.32s]
[2025-05-28T18:09:39.539+0100] {subprocess.py:106} INFO - [0m17:09:39  2 of 5 ERROR creating sql table model decisionnal.dim_branch ................... [[31mERROR[0m in 5.30s]
[2025-05-28T18:09:39.878+0100] {subprocess.py:106} INFO - [0m17:09:39  3 of 5 OK created sql table model decisionnal.dim_location ..................... [[32mSELECT 298[0m in 5.59s]
[2025-05-28T18:09:39.924+0100] {subprocess.py:106} INFO - [0m17:09:39  5 of 5 SKIP relation decisionnal.fact_reviews .................................. [[33mSKIP[0m]
[2025-05-28T18:09:40.105+0100] {subprocess.py:106} INFO - [0m17:09:40
[2025-05-28T18:09:40.155+0100] {subprocess.py:106} INFO - [0m17:09:40  Finished running 5 table models in 0 hours 0 minutes and 8.26 seconds (8.26s).
[2025-05-28T18:09:41.248+0100] {subprocess.py:106} INFO - [0m17:09:41
[2025-05-28T18:09:41.269+0100] {subprocess.py:106} INFO - [0m17:09:41  [31mCompleted with 1 error, 0 partial successes, and 0 warnings:[0m
[2025-05-28T18:09:41.271+0100] {subprocess.py:106} INFO - [0m17:09:41
[2025-05-28T18:09:41.272+0100] {subprocess.py:106} INFO - [0m17:09:41    Database Error in model dim_branch (models/dim_branch.sql)
[2025-05-28T18:09:41.279+0100] {subprocess.py:106} INFO -   relation "dim_branch__dbt_backup" already exists
[2025-05-28T18:09:41.281+0100] {subprocess.py:106} INFO -   compiled code at target/run/bank_reviews_decisionnal/models/dim_branch.sql
[2025-05-28T18:09:41.282+0100] {subprocess.py:106} INFO - [0m17:09:41
[2025-05-28T18:09:41.283+0100] {subprocess.py:106} INFO - [0m17:09:41  Done. PASS=3 WARN=0 ERROR=1 SKIP=1 TOTAL=5
[2025-05-28T18:09:46.313+0100] {subprocess.py:110} INFO - Command exited with return code 1
[2025-05-28T18:09:47.083+0100] {taskinstance.py:3313} ERROR - Task failed with exception
Traceback (most recent call last):
  File "/home/mohammed/venv/lib/python3.11/site-packages/airflow/models/taskinstance.py", line 768, in _execute_task
    result = _execute_callable(context=context, **execute_callable_kwargs)
             ^^^^^^^^^^^^^^^^^^^^^^^^^^^^^^^^^^^^^^^^^^^^^^^^^^^^^^^^^^^^^
  File "/home/mohammed/venv/lib/python3.11/site-packages/airflow/models/taskinstance.py", line 734, in _execute_callable
    return ExecutionCallableRunner(
           ^^^^^^^^^^^^^^^^^^^^^^^^
  File "/home/mohammed/venv/lib/python3.11/site-packages/airflow/utils/operator_helpers.py", line 252, in run
    return self.func(*args, **kwargs)
           ^^^^^^^^^^^^^^^^^^^^^^^^^^
  File "/home/mohammed/venv/lib/python3.11/site-packages/airflow/models/baseoperator.py", line 424, in wrapper
    return func(self, *args, **kwargs)
           ^^^^^^^^^^^^^^^^^^^^^^^^^^^
  File "/home/mohammed/venv/lib/python3.11/site-packages/airflow/operators/bash.py", line 276, in execute
    raise AirflowException(
airflow.exceptions.AirflowException: Bash command failed. The command returned a non-zero exit code 1.
[2025-05-28T18:09:48.668+0100] {logging_mixin.py:190} INFO - Task instance in failure state
[2025-05-28T18:09:48.669+0100] {logging_mixin.py:190} INFO - Task start:2025-05-28 17:09:03.959236+00:00 end:2025-05-28 17:09:48.633895+00:00 duration:44.674659
[2025-05-28T18:09:48.673+0100] {logging_mixin.py:190} INFO - Task:<Task(BashOperator): dbt_run_decisionnal> dag:<DAG: bank_reviews_etl_and_analysis_pipeline> dagrun:<DagRun bank_reviews_etl_and_analysis_pipeline @ 2025-04-20 00:00:00+00:00: scheduled__2025-04-20T00:00:00+00:00, state:running, queued_at: 2025-05-28 17:08:58.556561+00:00. externally triggered: False>
[2025-05-28T18:09:48.675+0100] {logging_mixin.py:190} INFO - Failure caused by Bash command failed. The command returned a non-zero exit code 1.
[2025-05-28T18:09:48.681+0100] {taskinstance.py:1226} INFO - Marking task as UP_FOR_RETRY. dag_id=bank_reviews_etl_and_analysis_pipeline, task_id=dbt_run_decisionnal, run_id=scheduled__2025-04-20T00:00:00+00:00, execution_date=20250420T000000, start_date=20250528T170903, end_date=20250528T170948
[2025-05-28T18:09:49.437+0100] {taskinstance.py:341} INFO - ::group::Post task execution logs
[2025-05-28T18:09:49.443+0100] {standard_task_runner.py:124} ERROR - Failed to execute job 2503 for task dbt_run_decisionnal (Bash command failed. The command returned a non-zero exit code 1.; 956)
Traceback (most recent call last):
  File "/home/mohammed/venv/lib/python3.11/site-packages/airflow/task/task_runner/standard_task_runner.py", line 117, in _start_by_fork
    ret = args.func(args, dag=self.dag)
          ^^^^^^^^^^^^^^^^^^^^^^^^^^^^^
  File "/home/mohammed/venv/lib/python3.11/site-packages/airflow/cli/cli_config.py", line 49, in command
    return func(*args, **kwargs)
           ^^^^^^^^^^^^^^^^^^^^^
  File "/home/mohammed/venv/lib/python3.11/site-packages/airflow/utils/cli.py", line 116, in wrapper
    return f(*args, **kwargs)
           ^^^^^^^^^^^^^^^^^^
  File "/home/mohammed/venv/lib/python3.11/site-packages/airflow/cli/commands/task_command.py", line 483, in task_run
    task_return_code = _run_task_by_selected_method(args, _dag, ti)
                       ^^^^^^^^^^^^^^^^^^^^^^^^^^^^^^^^^^^^^^^^^^^^
  File "/home/mohammed/venv/lib/python3.11/site-packages/airflow/cli/commands/task_command.py", line 256, in _run_task_by_selected_method
    return _run_raw_task(args, ti)
           ^^^^^^^^^^^^^^^^^^^^^^^
  File "/home/mohammed/venv/lib/python3.11/site-packages/airflow/cli/commands/task_command.py", line 341, in _run_raw_task
    return ti._run_raw_task(
           ^^^^^^^^^^^^^^^^^
  File "/home/mohammed/venv/lib/python3.11/site-packages/airflow/utils/session.py", line 97, in wrapper
    return func(*args, session=session, **kwargs)
           ^^^^^^^^^^^^^^^^^^^^^^^^^^^^^^^^^^^^^^
  File "/home/mohammed/venv/lib/python3.11/site-packages/airflow/models/taskinstance.py", line 3006, in _run_raw_task
    return _run_raw_task(
           ^^^^^^^^^^^^^^
  File "/home/mohammed/venv/lib/python3.11/site-packages/airflow/models/taskinstance.py", line 274, in _run_raw_task
    TaskInstance._execute_task_with_callbacks(
  File "/home/mohammed/venv/lib/python3.11/site-packages/airflow/models/taskinstance.py", line 3161, in _execute_task_with_callbacks
    result = self._execute_task(context, task_orig)
             ^^^^^^^^^^^^^^^^^^^^^^^^^^^^^^^^^^^^^^
  File "/home/mohammed/venv/lib/python3.11/site-packages/airflow/models/taskinstance.py", line 3185, in _execute_task
    return _execute_task(self, context, task_orig)
           ^^^^^^^^^^^^^^^^^^^^^^^^^^^^^^^^^^^^^^^
  File "/home/mohammed/venv/lib/python3.11/site-packages/airflow/models/taskinstance.py", line 768, in _execute_task
    result = _execute_callable(context=context, **execute_callable_kwargs)
             ^^^^^^^^^^^^^^^^^^^^^^^^^^^^^^^^^^^^^^^^^^^^^^^^^^^^^^^^^^^^^
  File "/home/mohammed/venv/lib/python3.11/site-packages/airflow/models/taskinstance.py", line 734, in _execute_callable
    return ExecutionCallableRunner(
           ^^^^^^^^^^^^^^^^^^^^^^^^
  File "/home/mohammed/venv/lib/python3.11/site-packages/airflow/utils/operator_helpers.py", line 252, in run
    return self.func(*args, **kwargs)
           ^^^^^^^^^^^^^^^^^^^^^^^^^^
  File "/home/mohammed/venv/lib/python3.11/site-packages/airflow/models/baseoperator.py", line 424, in wrapper
    return func(self, *args, **kwargs)
           ^^^^^^^^^^^^^^^^^^^^^^^^^^^
  File "/home/mohammed/venv/lib/python3.11/site-packages/airflow/operators/bash.py", line 276, in execute
    raise AirflowException(
airflow.exceptions.AirflowException: Bash command failed. The command returned a non-zero exit code 1.
[2025-05-28T18:09:49.539+0100] {local_task_job_runner.py:266} INFO - Task exited with return code 1
[2025-05-28T18:09:49.992+0100] {local_task_job_runner.py:245} INFO - ::endgroup::
