[2025-03-28T23:01:50.067+0000] {local_task_job_runner.py:123} INFO - ::group::Pre task execution logs
[2025-03-28T23:01:50.198+0000] {taskinstance.py:2614} INFO - Dependencies all met for dep_context=non-requeueable deps ti=<TaskInstance: bank_reviews_etl_and_analysis_pipeline.dbt_run_decisionnal scheduled__2024-11-17T00:00:00+00:00 [queued]>
[2025-03-28T23:01:50.255+0000] {taskinstance.py:2614} INFO - Dependencies all met for dep_context=requeueable deps ti=<TaskInstance: bank_reviews_etl_and_analysis_pipeline.dbt_run_decisionnal scheduled__2024-11-17T00:00:00+00:00 [queued]>
[2025-03-28T23:01:50.256+0000] {taskinstance.py:2867} INFO - Starting attempt 2 of 2
[2025-03-28T23:01:50.345+0000] {taskinstance.py:2890} INFO - Executing <Task(BashOperator): dbt_run_decisionnal> on 2024-11-17 00:00:00+00:00
[2025-03-28T23:01:50.366+0000] {standard_task_runner.py:72} INFO - Started process 593682 to run task
[2025-03-28T23:01:50.392+0000] {standard_task_runner.py:104} INFO - Running: ['airflow', 'tasks', 'run', 'bank_reviews_etl_and_analysis_pipeline', 'dbt_run_decisionnal', 'scheduled__2024-11-17T00:00:00+00:00', '--job-id', '2471', '--raw', '--subdir', 'DAGS_FOLDER/dag_load_reviews.py', '--cfg-path', '/tmp/tmpy6xqrio7']
[2025-03-28T23:01:50.398+0000] {standard_task_runner.py:105} INFO - Job 2471: Subtask dbt_run_decisionnal
[2025-03-28T23:01:51.053+0000] {task_command.py:467} INFO - Running <TaskInstance: bank_reviews_etl_and_analysis_pipeline.dbt_run_decisionnal scheduled__2024-11-17T00:00:00+00:00 [running]> on host DESKTOP-IM7V4RI.
[2025-03-28T23:01:52.490+0000] {taskinstance.py:3134} INFO - Exporting env vars: AIRFLOW_CTX_DAG_OWNER='mohammed' AIRFLOW_CTX_DAG_ID='bank_reviews_etl_and_analysis_pipeline' AIRFLOW_CTX_TASK_ID='dbt_run_decisionnal' AIRFLOW_CTX_EXECUTION_DATE='2024-11-17T00:00:00+00:00' AIRFLOW_CTX_TRY_NUMBER='2' AIRFLOW_CTX_DAG_RUN_ID='scheduled__2024-11-17T00:00:00+00:00'
[2025-03-28T23:01:52.546+0000] {logging_mixin.py:190} INFO - Task instance is in running state
[2025-03-28T23:01:52.547+0000] {logging_mixin.py:190} INFO -  Previous state of the Task instance: queued
[2025-03-28T23:01:52.549+0000] {logging_mixin.py:190} INFO - Current task name:dbt_run_decisionnal state:running start_date:2025-03-28 23:01:50.199198+00:00
[2025-03-28T23:01:52.549+0000] {logging_mixin.py:190} INFO - Dag name:bank_reviews_etl_and_analysis_pipeline and current dag run status:running
[2025-03-28T23:01:52.550+0000] {taskinstance.py:732} INFO - ::endgroup::
[2025-03-28T23:01:52.581+0000] {subprocess.py:78} INFO - Tmp dir root location: /tmp
[2025-03-28T23:01:52.599+0000] {subprocess.py:88} INFO - Running command: ['/usr/bin/bash', '-c', 'cd /home/mohammed/.dbt/dbt_projects/bank_reviews_decisionnal && dbt run']
[2025-03-28T23:01:52.678+0000] {subprocess.py:99} INFO - Output:
[2025-03-28T23:02:19.828+0000] {subprocess.py:106} INFO - [0m23:02:19  Running with dbt=1.9.3
[2025-03-28T23:02:24.074+0000] {subprocess.py:106} INFO - [0m23:02:24  Registered adapter: postgres=1.9.0
[2025-03-28T23:02:31.241+0000] {subprocess.py:106} INFO - [0m23:02:31  [[33mWARNING[0m]: Configuration paths exist in your dbt_project.yml file which do not apply to any resources.
[2025-03-28T23:02:31.245+0000] {subprocess.py:106} INFO - There are 1 unused configuration paths:
[2025-03-28T23:02:31.246+0000] {subprocess.py:106} INFO - - models.bank_reviews_decisionnal.decisionnal
[2025-03-28T23:02:32.617+0000] {subprocess.py:106} INFO - [0m23:02:32  Found 5 models, 2 sources, 547 macros
[2025-03-28T23:02:32.646+0000] {subprocess.py:106} INFO - [0m23:02:32
[2025-03-28T23:02:32.665+0000] {subprocess.py:106} INFO - [0m23:02:32  Concurrency: 4 threads (target='dev')
[2025-03-28T23:02:32.696+0000] {subprocess.py:106} INFO - [0m23:02:32
[2025-03-28T23:02:36.353+0000] {subprocess.py:106} INFO - [0m23:02:36  1 of 5 START sql table model decisionnal.dim_bank .............................. [RUN]
[2025-03-28T23:02:36.363+0000] {subprocess.py:106} INFO - [0m23:02:36  4 of 5 START sql table model decisionnal.dim_sentiment ......................... [RUN]
[2025-03-28T23:02:36.407+0000] {subprocess.py:106} INFO - [0m23:02:36  3 of 5 START sql table model decisionnal.dim_location .......................... [RUN]
[2025-03-28T23:02:36.437+0000] {subprocess.py:106} INFO - [0m23:02:36  2 of 5 START sql table model decisionnal.dim_branch ............................ [RUN]
[2025-03-28T23:02:42.503+0000] {subprocess.py:106} INFO - [0m23:02:42  3 of 5 OK created sql table model decisionnal.dim_location ..................... [[32mSELECT 298[0m in 5.97s]
[2025-03-28T23:02:44.612+0000] {subprocess.py:106} INFO - [0m23:02:44  1 of 5 OK created sql table model decisionnal.dim_bank ......................... [[32mSELECT 299[0m in 8.24s]
[2025-03-28T23:02:45.815+0000] {subprocess.py:106} INFO - [0m23:02:45  4 of 5 OK created sql table model decisionnal.dim_sentiment .................... [[32mSELECT 2591[0m in 9.40s]
[2025-03-28T23:02:46.431+0000] {subprocess.py:106} INFO - [0m23:02:46  2 of 5 ERROR creating sql table model decisionnal.dim_branch ................... [[31mERROR[0m in 9.98s]
[2025-03-28T23:02:46.481+0000] {subprocess.py:106} INFO - [0m23:02:46  5 of 5 SKIP relation decisionnal.fact_reviews .................................. [[33mSKIP[0m]
[2025-03-28T23:02:46.688+0000] {subprocess.py:106} INFO - [0m23:02:46
[2025-03-28T23:02:46.689+0000] {subprocess.py:106} INFO - [0m23:02:46  Finished running 5 table models in 0 hours 0 minutes and 13.99 seconds (13.99s).
[2025-03-28T23:02:47.098+0000] {subprocess.py:106} INFO - [0m23:02:47
[2025-03-28T23:02:47.112+0000] {subprocess.py:106} INFO - [0m23:02:47  [31mCompleted with 1 error, 0 partial successes, and 0 warnings:[0m
[2025-03-28T23:02:47.115+0000] {subprocess.py:106} INFO - [0m23:02:47
[2025-03-28T23:02:47.130+0000] {subprocess.py:106} INFO - [0m23:02:47    Database Error in model dim_branch (models/dim_branch.sql)
[2025-03-28T23:02:47.130+0000] {subprocess.py:106} INFO -   relation "dim_branch__dbt_backup" already exists
[2025-03-28T23:02:47.133+0000] {subprocess.py:106} INFO -   compiled code at target/run/bank_reviews_decisionnal/models/dim_branch.sql
[2025-03-28T23:02:47.139+0000] {subprocess.py:106} INFO - [0m23:02:47
[2025-03-28T23:02:47.140+0000] {subprocess.py:106} INFO - [0m23:02:47  Done. PASS=3 WARN=0 ERROR=1 SKIP=1 TOTAL=5
[2025-03-28T23:02:56.991+0000] {subprocess.py:110} INFO - Command exited with return code 1
[2025-03-28T23:02:58.393+0000] {taskinstance.py:3313} ERROR - Task failed with exception
Traceback (most recent call last):
  File "/home/mohammed/venv/lib/python3.11/site-packages/airflow/models/taskinstance.py", line 768, in _execute_task
    result = _execute_callable(context=context, **execute_callable_kwargs)
             ^^^^^^^^^^^^^^^^^^^^^^^^^^^^^^^^^^^^^^^^^^^^^^^^^^^^^^^^^^^^^
  File "/home/mohammed/venv/lib/python3.11/site-packages/airflow/models/taskinstance.py", line 734, in _execute_callable
    return ExecutionCallableRunner(
           ^^^^^^^^^^^^^^^^^^^^^^^^
  File "/home/mohammed/venv/lib/python3.11/site-packages/airflow/utils/operator_helpers.py", line 252, in run
    return self.func(*args, **kwargs)
           ^^^^^^^^^^^^^^^^^^^^^^^^^^
  File "/home/mohammed/venv/lib/python3.11/site-packages/airflow/models/baseoperator.py", line 424, in wrapper
    return func(self, *args, **kwargs)
           ^^^^^^^^^^^^^^^^^^^^^^^^^^^
  File "/home/mohammed/venv/lib/python3.11/site-packages/airflow/operators/bash.py", line 276, in execute
    raise AirflowException(
airflow.exceptions.AirflowException: Bash command failed. The command returned a non-zero exit code 1.
[2025-03-28T23:02:58.597+0000] {logging_mixin.py:190} INFO - Task instance in failure state
[2025-03-28T23:02:58.598+0000] {logging_mixin.py:190} INFO - Task start:2025-03-28 23:01:50.199198+00:00 end:2025-03-28 23:02:58.522964+00:00 duration:68.323766
[2025-03-28T23:02:58.601+0000] {logging_mixin.py:190} INFO - Task:<Task(BashOperator): dbt_run_decisionnal> dag:<DAG: bank_reviews_etl_and_analysis_pipeline> dagrun:<DagRun bank_reviews_etl_and_analysis_pipeline @ 2024-11-17 00:00:00+00:00: scheduled__2024-11-17T00:00:00+00:00, state:running, queued_at: 2025-03-28 22:55:58.684734+00:00. externally triggered: False>
[2025-03-28T23:02:58.632+0000] {logging_mixin.py:190} INFO - Failure caused by Bash command failed. The command returned a non-zero exit code 1.
[2025-03-28T23:02:58.634+0000] {taskinstance.py:1226} INFO - Marking task as FAILED. dag_id=bank_reviews_etl_and_analysis_pipeline, task_id=dbt_run_decisionnal, run_id=scheduled__2024-11-17T00:00:00+00:00, execution_date=20241117T000000, start_date=20250328T230150, end_date=20250328T230258
[2025-03-28T23:02:59.318+0000] {taskinstance.py:341} INFO - ::group::Post task execution logs
[2025-03-28T23:02:59.346+0000] {standard_task_runner.py:124} ERROR - Failed to execute job 2471 for task dbt_run_decisionnal (Bash command failed. The command returned a non-zero exit code 1.; 593682)
Traceback (most recent call last):
  File "/home/mohammed/venv/lib/python3.11/site-packages/airflow/task/task_runner/standard_task_runner.py", line 117, in _start_by_fork
    ret = args.func(args, dag=self.dag)
          ^^^^^^^^^^^^^^^^^^^^^^^^^^^^^
  File "/home/mohammed/venv/lib/python3.11/site-packages/airflow/cli/cli_config.py", line 49, in command
    return func(*args, **kwargs)
           ^^^^^^^^^^^^^^^^^^^^^
  File "/home/mohammed/venv/lib/python3.11/site-packages/airflow/utils/cli.py", line 116, in wrapper
    return f(*args, **kwargs)
           ^^^^^^^^^^^^^^^^^^
  File "/home/mohammed/venv/lib/python3.11/site-packages/airflow/cli/commands/task_command.py", line 483, in task_run
    task_return_code = _run_task_by_selected_method(args, _dag, ti)
                       ^^^^^^^^^^^^^^^^^^^^^^^^^^^^^^^^^^^^^^^^^^^^
  File "/home/mohammed/venv/lib/python3.11/site-packages/airflow/cli/commands/task_command.py", line 256, in _run_task_by_selected_method
    return _run_raw_task(args, ti)
           ^^^^^^^^^^^^^^^^^^^^^^^
  File "/home/mohammed/venv/lib/python3.11/site-packages/airflow/cli/commands/task_command.py", line 341, in _run_raw_task
    return ti._run_raw_task(
           ^^^^^^^^^^^^^^^^^
  File "/home/mohammed/venv/lib/python3.11/site-packages/airflow/utils/session.py", line 97, in wrapper
    return func(*args, session=session, **kwargs)
           ^^^^^^^^^^^^^^^^^^^^^^^^^^^^^^^^^^^^^^
  File "/home/mohammed/venv/lib/python3.11/site-packages/airflow/models/taskinstance.py", line 3006, in _run_raw_task
    return _run_raw_task(
           ^^^^^^^^^^^^^^
  File "/home/mohammed/venv/lib/python3.11/site-packages/airflow/models/taskinstance.py", line 274, in _run_raw_task
    TaskInstance._execute_task_with_callbacks(
  File "/home/mohammed/venv/lib/python3.11/site-packages/airflow/models/taskinstance.py", line 3161, in _execute_task_with_callbacks
    result = self._execute_task(context, task_orig)
             ^^^^^^^^^^^^^^^^^^^^^^^^^^^^^^^^^^^^^^
  File "/home/mohammed/venv/lib/python3.11/site-packages/airflow/models/taskinstance.py", line 3185, in _execute_task
    return _execute_task(self, context, task_orig)
           ^^^^^^^^^^^^^^^^^^^^^^^^^^^^^^^^^^^^^^^
  File "/home/mohammed/venv/lib/python3.11/site-packages/airflow/models/taskinstance.py", line 768, in _execute_task
    result = _execute_callable(context=context, **execute_callable_kwargs)
             ^^^^^^^^^^^^^^^^^^^^^^^^^^^^^^^^^^^^^^^^^^^^^^^^^^^^^^^^^^^^^
  File "/home/mohammed/venv/lib/python3.11/site-packages/airflow/models/taskinstance.py", line 734, in _execute_callable
    return ExecutionCallableRunner(
           ^^^^^^^^^^^^^^^^^^^^^^^^
  File "/home/mohammed/venv/lib/python3.11/site-packages/airflow/utils/operator_helpers.py", line 252, in run
    return self.func(*args, **kwargs)
           ^^^^^^^^^^^^^^^^^^^^^^^^^^
  File "/home/mohammed/venv/lib/python3.11/site-packages/airflow/models/baseoperator.py", line 424, in wrapper
    return func(self, *args, **kwargs)
           ^^^^^^^^^^^^^^^^^^^^^^^^^^^
  File "/home/mohammed/venv/lib/python3.11/site-packages/airflow/operators/bash.py", line 276, in execute
    raise AirflowException(
airflow.exceptions.AirflowException: Bash command failed. The command returned a non-zero exit code 1.
[2025-03-28T23:02:59.501+0000] {local_task_job_runner.py:266} INFO - Task exited with return code 1
[2025-03-28T23:02:59.873+0000] {local_task_job_runner.py:245} INFO - ::endgroup::
