[2025-03-17T01:01:49.403+0000] {local_task_job_runner.py:123} INFO - ::group::Pre task execution logs
[2025-03-17T01:01:49.462+0000] {taskinstance.py:2614} INFO - Dependencies all met for dep_context=non-requeueable deps ti=<TaskInstance: load_reviews_pipeline.dbt_run scheduled__2024-10-15T00:00:00+00:00 [queued]>
[2025-03-17T01:01:49.497+0000] {taskinstance.py:2614} INFO - Dependencies all met for dep_context=requeueable deps ti=<TaskInstance: load_reviews_pipeline.dbt_run scheduled__2024-10-15T00:00:00+00:00 [queued]>
[2025-03-17T01:01:49.498+0000] {taskinstance.py:2867} INFO - Starting attempt 1 of 2
[2025-03-17T01:01:49.702+0000] {taskinstance.py:2890} INFO - Executing <Task(BashOperator): dbt_run> on 2024-10-15 00:00:00+00:00
[2025-03-17T01:01:49.714+0000] {standard_task_runner.py:72} INFO - Started process 304056 to run task
[2025-03-17T01:01:49.740+0000] {standard_task_runner.py:104} INFO - Running: ['airflow', 'tasks', 'run', 'load_reviews_pipeline', 'dbt_run', 'scheduled__2024-10-15T00:00:00+00:00', '--job-id', '463', '--raw', '--subdir', 'DAGS_FOLDER/dag_load_reviews.py', '--cfg-path', '/tmp/tmpfxzsf5fx']
[2025-03-17T01:01:49.741+0000] {standard_task_runner.py:105} INFO - Job 463: Subtask dbt_run
[2025-03-17T01:01:49.915+0000] {task_command.py:467} INFO - Running <TaskInstance: load_reviews_pipeline.dbt_run scheduled__2024-10-15T00:00:00+00:00 [running]> on host DESKTOP-IM7V4RI.
[2025-03-17T01:01:50.239+0000] {taskinstance.py:3134} INFO - Exporting env vars: AIRFLOW_CTX_DAG_OWNER='mohammed' AIRFLOW_CTX_DAG_ID='load_reviews_pipeline' AIRFLOW_CTX_TASK_ID='dbt_run' AIRFLOW_CTX_EXECUTION_DATE='2024-10-15T00:00:00+00:00' AIRFLOW_CTX_TRY_NUMBER='1' AIRFLOW_CTX_DAG_RUN_ID='scheduled__2024-10-15T00:00:00+00:00'
[2025-03-17T01:01:50.242+0000] {logging_mixin.py:190} INFO - Task instance is in running state
[2025-03-17T01:01:50.243+0000] {logging_mixin.py:190} INFO -  Previous state of the Task instance: queued
[2025-03-17T01:01:50.244+0000] {logging_mixin.py:190} INFO - Current task name:dbt_run state:running start_date:2025-03-17 01:01:49.463046+00:00
[2025-03-17T01:01:50.245+0000] {logging_mixin.py:190} INFO - Dag name:load_reviews_pipeline and current dag run status:running
[2025-03-17T01:01:50.245+0000] {taskinstance.py:732} INFO - ::endgroup::
[2025-03-17T01:01:50.246+0000] {subprocess.py:78} INFO - Tmp dir root location: /tmp
[2025-03-17T01:01:50.248+0000] {subprocess.py:88} INFO - Running command: ['/usr/bin/bash', '-c', 'cd /home/mohammed/.dbt/bank_reviews_project && dbt run']
[2025-03-17T01:01:50.282+0000] {subprocess.py:99} INFO - Output:
[2025-03-17T01:01:53.175+0000] {subprocess.py:106} INFO - [0m01:01:53  Running with dbt=1.9.3
[2025-03-17T01:01:54.085+0000] {subprocess.py:106} INFO - [0m01:01:54  Registered adapter: postgres=1.9.0
[2025-03-17T01:01:55.232+0000] {subprocess.py:106} INFO - [0m01:01:55  Found 10 models, 4 data tests, 2 sources, 433 macros
[2025-03-17T01:01:55.242+0000] {subprocess.py:106} INFO - [0m01:01:55
[2025-03-17T01:01:55.244+0000] {subprocess.py:106} INFO - [0m01:01:55  Concurrency: 4 threads (target='dev')
[2025-03-17T01:01:55.245+0000] {subprocess.py:106} INFO - [0m01:01:55
[2025-03-17T01:01:55.849+0000] {subprocess.py:106} INFO - [0m01:01:55  1 of 10 START sql view model public.clean_reviews .............................. [RUN]
[2025-03-17T01:01:55.876+0000] {subprocess.py:106} INFO - [0m01:01:55  3 of 10 START sql view model public.remove_duplicates .......................... [RUN]
[2025-03-17T01:01:55.877+0000] {subprocess.py:106} INFO - [0m01:01:55  4 of 10 START sql view model public.stg_clean_reviews .......................... [RUN]
[2025-03-17T01:01:55.885+0000] {subprocess.py:106} INFO - [0m01:01:55  2 of 10 START sql table model public.my_first_dbt_model ........................ [RUN]
[2025-03-17T01:01:56.921+0000] {subprocess.py:106} INFO - [0m01:01:56  2 of 10 ERROR creating sql table model public.my_first_dbt_model ............... [[31mERROR[0m in 1.02s]
[2025-03-17T01:01:56.929+0000] {subprocess.py:106} INFO - [0m01:01:56  4 of 10 ERROR creating sql view model public.stg_clean_reviews ................. [[31mERROR[0m in 1.06s]
[2025-03-17T01:01:56.963+0000] {subprocess.py:106} INFO - [0m01:01:56  3 of 10 OK created sql view model public.remove_duplicates ..................... [[32mCREATE VIEW[0m in 1.09s]
[2025-03-17T01:01:56.974+0000] {subprocess.py:106} INFO - [0m01:01:56  5 of 10 SKIP relation public.my_second_dbt_model ............................... [[33mSKIP[0m]
[2025-03-17T01:01:56.986+0000] {subprocess.py:106} INFO - [0m01:01:56  1 of 10 OK created sql view model public.clean_reviews ......................... [[32mCREATE VIEW[0m in 1.14s]
[2025-03-17T01:01:57.000+0000] {subprocess.py:106} INFO - [0m01:01:57  6 of 10 SKIP relation public.dim_bank .......................................... [[33mSKIP[0m]
[2025-03-17T01:01:57.005+0000] {subprocess.py:106} INFO - [0m01:01:57  7 of 10 SKIP relation public.dim_branch ........................................ [[33mSKIP[0m]
[2025-03-17T01:01:57.006+0000] {subprocess.py:106} INFO - [0m01:01:57  8 of 10 SKIP relation public.dim_location ...................................... [[33mSKIP[0m]
[2025-03-17T01:01:57.008+0000] {subprocess.py:106} INFO - [0m01:01:57  9 of 10 SKIP relation public.dim_sentiment ..................................... [[33mSKIP[0m]
[2025-03-17T01:01:57.019+0000] {subprocess.py:106} INFO - [0m01:01:57  10 of 10 SKIP relation public.fact_reviews ..................................... [[33mSKIP[0m]
[2025-03-17T01:01:57.110+0000] {subprocess.py:106} INFO - [0m01:01:57
[2025-03-17T01:01:57.121+0000] {subprocess.py:106} INFO - [0m01:01:57  Finished running 1 table model, 9 view models in 0 hours 0 minutes and 1.86 seconds (1.86s).
[2025-03-17T01:01:57.224+0000] {subprocess.py:106} INFO - [0m01:01:57
[2025-03-17T01:01:57.226+0000] {subprocess.py:106} INFO - [0m01:01:57  [31mCompleted with 2 errors, 0 partial successes, and 0 warnings:[0m
[2025-03-17T01:01:57.227+0000] {subprocess.py:106} INFO - [0m01:01:57
[2025-03-17T01:01:57.229+0000] {subprocess.py:106} INFO - [0m01:01:57    Database Error in model my_first_dbt_model (models/example/my_first_dbt_model.sql)
[2025-03-17T01:01:57.230+0000] {subprocess.py:106} INFO -   relation "my_first_dbt_model__dbt_backup" already exists
[2025-03-17T01:01:57.231+0000] {subprocess.py:106} INFO -   compiled code at target/run/bank_reviews_project/models/example/my_first_dbt_model.sql
[2025-03-17T01:01:57.231+0000] {subprocess.py:106} INFO - [0m01:01:57
[2025-03-17T01:01:57.232+0000] {subprocess.py:106} INFO - [0m01:01:57    Database Error in model stg_clean_reviews (models/stg_clean_reviews.sql)
[2025-03-17T01:01:57.232+0000] {subprocess.py:106} INFO -   relation "stg_clean_reviews__dbt_backup" already exists
[2025-03-17T01:01:57.233+0000] {subprocess.py:106} INFO -   compiled code at target/run/bank_reviews_project/models/stg_clean_reviews.sql
[2025-03-17T01:01:57.235+0000] {subprocess.py:106} INFO - [0m01:01:57
[2025-03-17T01:01:57.235+0000] {subprocess.py:106} INFO - [0m01:01:57  Done. PASS=2 WARN=0 ERROR=2 SKIP=6 TOTAL=10
[2025-03-17T01:02:04.843+0000] {subprocess.py:110} INFO - Command exited with return code 1
[2025-03-17T01:02:04.879+0000] {taskinstance.py:3313} ERROR - Task failed with exception
Traceback (most recent call last):
  File "/home/mohammed/venv/lib/python3.11/site-packages/airflow/models/taskinstance.py", line 768, in _execute_task
    result = _execute_callable(context=context, **execute_callable_kwargs)
             ^^^^^^^^^^^^^^^^^^^^^^^^^^^^^^^^^^^^^^^^^^^^^^^^^^^^^^^^^^^^^
  File "/home/mohammed/venv/lib/python3.11/site-packages/airflow/models/taskinstance.py", line 734, in _execute_callable
    return ExecutionCallableRunner(
           ^^^^^^^^^^^^^^^^^^^^^^^^
  File "/home/mohammed/venv/lib/python3.11/site-packages/airflow/utils/operator_helpers.py", line 252, in run
    return self.func(*args, **kwargs)
           ^^^^^^^^^^^^^^^^^^^^^^^^^^
  File "/home/mohammed/venv/lib/python3.11/site-packages/airflow/models/baseoperator.py", line 424, in wrapper
    return func(self, *args, **kwargs)
           ^^^^^^^^^^^^^^^^^^^^^^^^^^^
  File "/home/mohammed/venv/lib/python3.11/site-packages/airflow/operators/bash.py", line 276, in execute
    raise AirflowException(
airflow.exceptions.AirflowException: Bash command failed. The command returned a non-zero exit code 1.
[2025-03-17T01:02:04.898+0000] {logging_mixin.py:190} INFO - Task instance in failure state
[2025-03-17T01:02:04.899+0000] {logging_mixin.py:190} INFO - Task start:2025-03-17 01:01:49.463046+00:00 end:2025-03-17 01:02:04.897137+00:00 duration:15.434091
[2025-03-17T01:02:04.900+0000] {logging_mixin.py:190} INFO - Task:<Task(BashOperator): dbt_run> dag:<DAG: load_reviews_pipeline> dagrun:<DagRun load_reviews_pipeline @ 2024-10-15 00:00:00+00:00: scheduled__2024-10-15T00:00:00+00:00, state:running, queued_at: 2025-03-17 01:01:48.270969+00:00. externally triggered: False>
[2025-03-17T01:02:04.900+0000] {logging_mixin.py:190} INFO - Failure caused by Bash command failed. The command returned a non-zero exit code 1.
[2025-03-17T01:02:04.902+0000] {taskinstance.py:1226} INFO - Marking task as UP_FOR_RETRY. dag_id=load_reviews_pipeline, task_id=dbt_run, run_id=scheduled__2024-10-15T00:00:00+00:00, execution_date=20241015T000000, start_date=20250317T010149, end_date=20250317T010204
[2025-03-17T01:02:05.201+0000] {taskinstance.py:341} INFO - ::group::Post task execution logs
[2025-03-17T01:02:05.202+0000] {standard_task_runner.py:124} ERROR - Failed to execute job 463 for task dbt_run (Bash command failed. The command returned a non-zero exit code 1.; 304056)
Traceback (most recent call last):
  File "/home/mohammed/venv/lib/python3.11/site-packages/airflow/task/task_runner/standard_task_runner.py", line 117, in _start_by_fork
    ret = args.func(args, dag=self.dag)
          ^^^^^^^^^^^^^^^^^^^^^^^^^^^^^
  File "/home/mohammed/venv/lib/python3.11/site-packages/airflow/cli/cli_config.py", line 49, in command
    return func(*args, **kwargs)
           ^^^^^^^^^^^^^^^^^^^^^
  File "/home/mohammed/venv/lib/python3.11/site-packages/airflow/utils/cli.py", line 116, in wrapper
    return f(*args, **kwargs)
           ^^^^^^^^^^^^^^^^^^
  File "/home/mohammed/venv/lib/python3.11/site-packages/airflow/cli/commands/task_command.py", line 483, in task_run
    task_return_code = _run_task_by_selected_method(args, _dag, ti)
                       ^^^^^^^^^^^^^^^^^^^^^^^^^^^^^^^^^^^^^^^^^^^^
  File "/home/mohammed/venv/lib/python3.11/site-packages/airflow/cli/commands/task_command.py", line 256, in _run_task_by_selected_method
    return _run_raw_task(args, ti)
           ^^^^^^^^^^^^^^^^^^^^^^^
  File "/home/mohammed/venv/lib/python3.11/site-packages/airflow/cli/commands/task_command.py", line 341, in _run_raw_task
    return ti._run_raw_task(
           ^^^^^^^^^^^^^^^^^
  File "/home/mohammed/venv/lib/python3.11/site-packages/airflow/utils/session.py", line 97, in wrapper
    return func(*args, session=session, **kwargs)
           ^^^^^^^^^^^^^^^^^^^^^^^^^^^^^^^^^^^^^^
  File "/home/mohammed/venv/lib/python3.11/site-packages/airflow/models/taskinstance.py", line 3006, in _run_raw_task
    return _run_raw_task(
           ^^^^^^^^^^^^^^
  File "/home/mohammed/venv/lib/python3.11/site-packages/airflow/models/taskinstance.py", line 274, in _run_raw_task
    TaskInstance._execute_task_with_callbacks(
  File "/home/mohammed/venv/lib/python3.11/site-packages/airflow/models/taskinstance.py", line 3161, in _execute_task_with_callbacks
    result = self._execute_task(context, task_orig)
             ^^^^^^^^^^^^^^^^^^^^^^^^^^^^^^^^^^^^^^
  File "/home/mohammed/venv/lib/python3.11/site-packages/airflow/models/taskinstance.py", line 3185, in _execute_task
    return _execute_task(self, context, task_orig)
           ^^^^^^^^^^^^^^^^^^^^^^^^^^^^^^^^^^^^^^^
  File "/home/mohammed/venv/lib/python3.11/site-packages/airflow/models/taskinstance.py", line 768, in _execute_task
    result = _execute_callable(context=context, **execute_callable_kwargs)
             ^^^^^^^^^^^^^^^^^^^^^^^^^^^^^^^^^^^^^^^^^^^^^^^^^^^^^^^^^^^^^
  File "/home/mohammed/venv/lib/python3.11/site-packages/airflow/models/taskinstance.py", line 734, in _execute_callable
    return ExecutionCallableRunner(
           ^^^^^^^^^^^^^^^^^^^^^^^^
  File "/home/mohammed/venv/lib/python3.11/site-packages/airflow/utils/operator_helpers.py", line 252, in run
    return self.func(*args, **kwargs)
           ^^^^^^^^^^^^^^^^^^^^^^^^^^
  File "/home/mohammed/venv/lib/python3.11/site-packages/airflow/models/baseoperator.py", line 424, in wrapper
    return func(self, *args, **kwargs)
           ^^^^^^^^^^^^^^^^^^^^^^^^^^^
  File "/home/mohammed/venv/lib/python3.11/site-packages/airflow/operators/bash.py", line 276, in execute
    raise AirflowException(
airflow.exceptions.AirflowException: Bash command failed. The command returned a non-zero exit code 1.
[2025-03-17T01:02:05.256+0000] {local_task_job_runner.py:266} INFO - Task exited with return code 1
[2025-03-17T01:02:05.307+0000] {taskinstance.py:3901} INFO - 0 downstream tasks scheduled from follow-on schedule check
[2025-03-17T01:02:05.311+0000] {local_task_job_runner.py:245} INFO - ::endgroup::
