[2025-03-28T23:01:49.100+0000] {local_task_job_runner.py:123} INFO - ::group::Pre task execution logs
[2025-03-28T23:01:49.274+0000] {taskinstance.py:2614} INFO - Dependencies all met for dep_context=non-requeueable deps ti=<TaskInstance: bank_reviews_etl_and_analysis_pipeline.dbt_run_decisionnal scheduled__2025-01-05T00:00:00+00:00 [queued]>
[2025-03-28T23:01:49.337+0000] {taskinstance.py:2614} INFO - Dependencies all met for dep_context=requeueable deps ti=<TaskInstance: bank_reviews_etl_and_analysis_pipeline.dbt_run_decisionnal scheduled__2025-01-05T00:00:00+00:00 [queued]>
[2025-03-28T23:01:49.337+0000] {taskinstance.py:2867} INFO - Starting attempt 2 of 2
[2025-03-28T23:01:49.943+0000] {taskinstance.py:2890} INFO - Executing <Task(BashOperator): dbt_run_decisionnal> on 2025-01-05 00:00:00+00:00
[2025-03-28T23:01:49.985+0000] {standard_task_runner.py:72} INFO - Started process 593661 to run task
[2025-03-28T23:01:50.050+0000] {standard_task_runner.py:104} INFO - Running: ['airflow', 'tasks', 'run', 'bank_reviews_etl_and_analysis_pipeline', 'dbt_run_decisionnal', 'scheduled__2025-01-05T00:00:00+00:00', '--job-id', '2469', '--raw', '--subdir', 'DAGS_FOLDER/dag_load_reviews.py', '--cfg-path', '/tmp/tmpu2qxckfp']
[2025-03-28T23:01:50.078+0000] {standard_task_runner.py:105} INFO - Job 2469: Subtask dbt_run_decisionnal
[2025-03-28T23:01:50.788+0000] {task_command.py:467} INFO - Running <TaskInstance: bank_reviews_etl_and_analysis_pipeline.dbt_run_decisionnal scheduled__2025-01-05T00:00:00+00:00 [running]> on host DESKTOP-IM7V4RI.
[2025-03-28T23:01:52.433+0000] {taskinstance.py:3134} INFO - Exporting env vars: AIRFLOW_CTX_DAG_OWNER='mohammed' AIRFLOW_CTX_DAG_ID='bank_reviews_etl_and_analysis_pipeline' AIRFLOW_CTX_TASK_ID='dbt_run_decisionnal' AIRFLOW_CTX_EXECUTION_DATE='2025-01-05T00:00:00+00:00' AIRFLOW_CTX_TRY_NUMBER='2' AIRFLOW_CTX_DAG_RUN_ID='scheduled__2025-01-05T00:00:00+00:00'
[2025-03-28T23:01:52.436+0000] {logging_mixin.py:190} INFO - Task instance is in running state
[2025-03-28T23:01:52.437+0000] {logging_mixin.py:190} INFO -  Previous state of the Task instance: queued
[2025-03-28T23:01:52.440+0000] {logging_mixin.py:190} INFO - Current task name:dbt_run_decisionnal state:running start_date:2025-03-28 23:01:49.275458+00:00
[2025-03-28T23:01:52.440+0000] {logging_mixin.py:190} INFO - Dag name:bank_reviews_etl_and_analysis_pipeline and current dag run status:running
[2025-03-28T23:01:52.458+0000] {taskinstance.py:732} INFO - ::endgroup::
[2025-03-28T23:01:52.461+0000] {subprocess.py:78} INFO - Tmp dir root location: /tmp
[2025-03-28T23:01:52.463+0000] {subprocess.py:88} INFO - Running command: ['/usr/bin/bash', '-c', 'cd /home/mohammed/.dbt/dbt_projects/bank_reviews_decisionnal && dbt run']
[2025-03-28T23:01:52.608+0000] {subprocess.py:99} INFO - Output:
[2025-03-28T23:02:21.323+0000] {subprocess.py:106} INFO - [0m23:02:21  Running with dbt=1.9.3
[2025-03-28T23:02:24.703+0000] {subprocess.py:106} INFO - [0m23:02:24  Registered adapter: postgres=1.9.0
[2025-03-28T23:02:32.064+0000] {subprocess.py:106} INFO - [0m23:02:32  [[33mWARNING[0m]: Configuration paths exist in your dbt_project.yml file which do not apply to any resources.
[2025-03-28T23:02:32.066+0000] {subprocess.py:106} INFO - There are 1 unused configuration paths:
[2025-03-28T23:02:32.067+0000] {subprocess.py:106} INFO - - models.bank_reviews_decisionnal.decisionnal
[2025-03-28T23:02:33.985+0000] {subprocess.py:106} INFO - [0m23:02:33  Found 5 models, 2 sources, 547 macros
[2025-03-28T23:02:34.042+0000] {subprocess.py:106} INFO - [0m23:02:34
[2025-03-28T23:02:34.070+0000] {subprocess.py:106} INFO - [0m23:02:34  Concurrency: 4 threads (target='dev')
[2025-03-28T23:02:34.088+0000] {subprocess.py:106} INFO - [0m23:02:34
[2025-03-28T23:02:39.007+0000] {subprocess.py:106} INFO - [0m23:02:39  3 of 5 START sql table model decisionnal.dim_location .......................... [RUN]
[2025-03-28T23:02:39.096+0000] {subprocess.py:106} INFO - [0m23:02:39  1 of 5 START sql table model decisionnal.dim_bank .............................. [RUN]
[2025-03-28T23:02:39.306+0000] {subprocess.py:106} INFO - [0m23:02:39  4 of 5 START sql table model decisionnal.dim_sentiment ......................... [RUN]
[2025-03-28T23:02:39.318+0000] {subprocess.py:106} INFO - [0m23:02:39  2 of 5 START sql table model decisionnal.dim_branch ............................ [RUN]
[2025-03-28T23:02:44.268+0000] {subprocess.py:106} INFO - [0m23:02:44  2 of 5 OK created sql table model decisionnal.dim_branch ....................... [[32mSELECT 298[0m in 4.94s]
[2025-03-28T23:02:44.362+0000] {subprocess.py:106} INFO - [0m23:02:44  3 of 5 OK created sql table model decisionnal.dim_location ..................... [[32mSELECT 298[0m in 5.33s]
[2025-03-28T23:02:46.613+0000] {subprocess.py:106} INFO - [0m23:02:46  1 of 5 OK created sql table model decisionnal.dim_bank ......................... [[32mSELECT 299[0m in 7.31s]
[2025-03-28T23:02:52.442+0000] {subprocess.py:106} INFO - [0m23:02:52  4 of 5 OK created sql table model decisionnal.dim_sentiment .................... [[32mSELECT 2591[0m in 13.06s]
[2025-03-28T23:02:52.492+0000] {subprocess.py:106} INFO - [0m23:02:52  5 of 5 START sql table model decisionnal.fact_reviews .......................... [RUN]
[2025-03-28T23:02:53.581+0000] {subprocess.py:106} INFO - [0m23:02:53  5 of 5 ERROR creating sql table model decisionnal.fact_reviews ................. [[31mERROR[0m in 0.97s]
[2025-03-28T23:02:54.291+0000] {subprocess.py:106} INFO - [0m23:02:54
[2025-03-28T23:02:54.394+0000] {subprocess.py:106} INFO - [0m23:02:54  Finished running 5 table models in 0 hours 0 minutes and 20.20 seconds (20.20s).
[2025-03-28T23:02:55.948+0000] {subprocess.py:106} INFO - [0m23:02:55
[2025-03-28T23:02:56.029+0000] {subprocess.py:106} INFO - [0m23:02:56  [31mCompleted with 1 error, 0 partial successes, and 0 warnings:[0m
[2025-03-28T23:02:56.034+0000] {subprocess.py:106} INFO - [0m23:02:56
[2025-03-28T23:02:56.055+0000] {subprocess.py:106} INFO - [0m23:02:56    Database Error in model fact_reviews (models/fact_reviews.sql)
[2025-03-28T23:02:56.056+0000] {subprocess.py:106} INFO -   column cr.topics does not exist
[2025-03-28T23:02:56.060+0000] {subprocess.py:106} INFO -   LINE 24:     cr.topics,
[2025-03-28T23:02:56.061+0000] {subprocess.py:106} INFO -                ^
[2025-03-28T23:02:56.067+0000] {subprocess.py:106} INFO -   HINT:  Perhaps you meant to reference the column "cr.topic".
[2025-03-28T23:02:56.070+0000] {subprocess.py:106} INFO -   compiled code at target/run/bank_reviews_decisionnal/models/fact_reviews.sql
[2025-03-28T23:02:56.085+0000] {subprocess.py:106} INFO - [0m23:02:56
[2025-03-28T23:02:56.087+0000] {subprocess.py:106} INFO - [0m23:02:56  Done. PASS=4 WARN=0 ERROR=1 SKIP=0 TOTAL=5
[2025-03-28T23:03:00.593+0000] {subprocess.py:110} INFO - Command exited with return code 1
[2025-03-28T23:03:01.462+0000] {taskinstance.py:3313} ERROR - Task failed with exception
Traceback (most recent call last):
  File "/home/mohammed/venv/lib/python3.11/site-packages/airflow/models/taskinstance.py", line 768, in _execute_task
    result = _execute_callable(context=context, **execute_callable_kwargs)
             ^^^^^^^^^^^^^^^^^^^^^^^^^^^^^^^^^^^^^^^^^^^^^^^^^^^^^^^^^^^^^
  File "/home/mohammed/venv/lib/python3.11/site-packages/airflow/models/taskinstance.py", line 734, in _execute_callable
    return ExecutionCallableRunner(
           ^^^^^^^^^^^^^^^^^^^^^^^^
  File "/home/mohammed/venv/lib/python3.11/site-packages/airflow/utils/operator_helpers.py", line 252, in run
    return self.func(*args, **kwargs)
           ^^^^^^^^^^^^^^^^^^^^^^^^^^
  File "/home/mohammed/venv/lib/python3.11/site-packages/airflow/models/baseoperator.py", line 424, in wrapper
    return func(self, *args, **kwargs)
           ^^^^^^^^^^^^^^^^^^^^^^^^^^^
  File "/home/mohammed/venv/lib/python3.11/site-packages/airflow/operators/bash.py", line 276, in execute
    raise AirflowException(
airflow.exceptions.AirflowException: Bash command failed. The command returned a non-zero exit code 1.
[2025-03-28T23:03:01.811+0000] {logging_mixin.py:190} INFO - Task instance in failure state
[2025-03-28T23:03:01.812+0000] {logging_mixin.py:190} INFO - Task start:2025-03-28 23:01:49.275458+00:00 end:2025-03-28 23:03:01.754051+00:00 duration:72.478593
[2025-03-28T23:03:01.826+0000] {logging_mixin.py:190} INFO - Task:<Task(BashOperator): dbt_run_decisionnal> dag:<DAG: bank_reviews_etl_and_analysis_pipeline> dagrun:<DagRun bank_reviews_etl_and_analysis_pipeline @ 2025-01-05 00:00:00+00:00: scheduled__2025-01-05T00:00:00+00:00, state:running, queued_at: 2025-03-28 22:56:00.110151+00:00. externally triggered: False>
[2025-03-28T23:03:01.847+0000] {logging_mixin.py:190} INFO - Failure caused by Bash command failed. The command returned a non-zero exit code 1.
[2025-03-28T23:03:01.849+0000] {taskinstance.py:1226} INFO - Marking task as FAILED. dag_id=bank_reviews_etl_and_analysis_pipeline, task_id=dbt_run_decisionnal, run_id=scheduled__2025-01-05T00:00:00+00:00, execution_date=20250105T000000, start_date=20250328T230149, end_date=20250328T230301
[2025-03-28T23:03:02.299+0000] {taskinstance.py:341} INFO - ::group::Post task execution logs
[2025-03-28T23:03:02.311+0000] {standard_task_runner.py:124} ERROR - Failed to execute job 2469 for task dbt_run_decisionnal (Bash command failed. The command returned a non-zero exit code 1.; 593661)
Traceback (most recent call last):
  File "/home/mohammed/venv/lib/python3.11/site-packages/airflow/task/task_runner/standard_task_runner.py", line 117, in _start_by_fork
    ret = args.func(args, dag=self.dag)
          ^^^^^^^^^^^^^^^^^^^^^^^^^^^^^
  File "/home/mohammed/venv/lib/python3.11/site-packages/airflow/cli/cli_config.py", line 49, in command
    return func(*args, **kwargs)
           ^^^^^^^^^^^^^^^^^^^^^
  File "/home/mohammed/venv/lib/python3.11/site-packages/airflow/utils/cli.py", line 116, in wrapper
    return f(*args, **kwargs)
           ^^^^^^^^^^^^^^^^^^
  File "/home/mohammed/venv/lib/python3.11/site-packages/airflow/cli/commands/task_command.py", line 483, in task_run
    task_return_code = _run_task_by_selected_method(args, _dag, ti)
                       ^^^^^^^^^^^^^^^^^^^^^^^^^^^^^^^^^^^^^^^^^^^^
  File "/home/mohammed/venv/lib/python3.11/site-packages/airflow/cli/commands/task_command.py", line 256, in _run_task_by_selected_method
    return _run_raw_task(args, ti)
           ^^^^^^^^^^^^^^^^^^^^^^^
  File "/home/mohammed/venv/lib/python3.11/site-packages/airflow/cli/commands/task_command.py", line 341, in _run_raw_task
    return ti._run_raw_task(
           ^^^^^^^^^^^^^^^^^
  File "/home/mohammed/venv/lib/python3.11/site-packages/airflow/utils/session.py", line 97, in wrapper
    return func(*args, session=session, **kwargs)
           ^^^^^^^^^^^^^^^^^^^^^^^^^^^^^^^^^^^^^^
  File "/home/mohammed/venv/lib/python3.11/site-packages/airflow/models/taskinstance.py", line 3006, in _run_raw_task
    return _run_raw_task(
           ^^^^^^^^^^^^^^
  File "/home/mohammed/venv/lib/python3.11/site-packages/airflow/models/taskinstance.py", line 274, in _run_raw_task
    TaskInstance._execute_task_with_callbacks(
  File "/home/mohammed/venv/lib/python3.11/site-packages/airflow/models/taskinstance.py", line 3161, in _execute_task_with_callbacks
    result = self._execute_task(context, task_orig)
             ^^^^^^^^^^^^^^^^^^^^^^^^^^^^^^^^^^^^^^
  File "/home/mohammed/venv/lib/python3.11/site-packages/airflow/models/taskinstance.py", line 3185, in _execute_task
    return _execute_task(self, context, task_orig)
           ^^^^^^^^^^^^^^^^^^^^^^^^^^^^^^^^^^^^^^^
  File "/home/mohammed/venv/lib/python3.11/site-packages/airflow/models/taskinstance.py", line 768, in _execute_task
    result = _execute_callable(context=context, **execute_callable_kwargs)
             ^^^^^^^^^^^^^^^^^^^^^^^^^^^^^^^^^^^^^^^^^^^^^^^^^^^^^^^^^^^^^
  File "/home/mohammed/venv/lib/python3.11/site-packages/airflow/models/taskinstance.py", line 734, in _execute_callable
    return ExecutionCallableRunner(
           ^^^^^^^^^^^^^^^^^^^^^^^^
  File "/home/mohammed/venv/lib/python3.11/site-packages/airflow/utils/operator_helpers.py", line 252, in run
    return self.func(*args, **kwargs)
           ^^^^^^^^^^^^^^^^^^^^^^^^^^
  File "/home/mohammed/venv/lib/python3.11/site-packages/airflow/models/baseoperator.py", line 424, in wrapper
    return func(self, *args, **kwargs)
           ^^^^^^^^^^^^^^^^^^^^^^^^^^^
  File "/home/mohammed/venv/lib/python3.11/site-packages/airflow/operators/bash.py", line 276, in execute
    raise AirflowException(
airflow.exceptions.AirflowException: Bash command failed. The command returned a non-zero exit code 1.
[2025-03-28T23:03:02.370+0000] {local_task_job_runner.py:266} INFO - Task exited with return code 1
[2025-03-28T23:03:02.509+0000] {taskinstance.py:3901} INFO - 0 downstream tasks scheduled from follow-on schedule check
[2025-03-28T23:03:02.514+0000] {local_task_job_runner.py:245} INFO - ::endgroup::
