[2025-03-18T17:04:00.204+0000] {local_task_job_runner.py:123} INFO - ::group::Pre task execution logs
[2025-03-18T17:04:00.347+0000] {taskinstance.py:2614} INFO - Dependencies all met for dep_context=non-requeueable deps ti=<TaskInstance: load_dbt_clean_reviews_pipeline.dbt_run manual__2025-03-18T16:57:11.890840+00:00 [queued]>
[2025-03-18T17:04:00.393+0000] {taskinstance.py:2614} INFO - Dependencies all met for dep_context=requeueable deps ti=<TaskInstance: load_dbt_clean_reviews_pipeline.dbt_run manual__2025-03-18T16:57:11.890840+00:00 [queued]>
[2025-03-18T17:04:00.393+0000] {taskinstance.py:2867} INFO - Starting attempt 2 of 2
[2025-03-18T17:04:00.489+0000] {taskinstance.py:2890} INFO - Executing <Task(BashOperator): dbt_run> on 2025-03-18 16:57:11.890840+00:00
[2025-03-18T17:04:00.541+0000] {standard_task_runner.py:72} INFO - Started process 48480 to run task
[2025-03-18T17:04:00.607+0000] {standard_task_runner.py:104} INFO - Running: ['airflow', 'tasks', 'run', 'load_dbt_clean_reviews_pipeline', 'dbt_run', 'manual__2025-03-18T16:57:11.890840+00:00', '--job-id', '759', '--raw', '--subdir', 'DAGS_FOLDER/dag_load_reviews.py', '--cfg-path', '/tmp/tmp3ni2m9ws']
[2025-03-18T17:04:00.613+0000] {standard_task_runner.py:105} INFO - Job 759: Subtask dbt_run
[2025-03-18T17:04:01.179+0000] {task_command.py:467} INFO - Running <TaskInstance: load_dbt_clean_reviews_pipeline.dbt_run manual__2025-03-18T16:57:11.890840+00:00 [running]> on host DESKTOP-IM7V4RI.
[2025-03-18T17:04:01.921+0000] {taskinstance.py:3134} INFO - Exporting env vars: AIRFLOW_CTX_DAG_OWNER='mohammed' AIRFLOW_CTX_DAG_ID='load_dbt_clean_reviews_pipeline' AIRFLOW_CTX_TASK_ID='dbt_run' AIRFLOW_CTX_EXECUTION_DATE='2025-03-18T16:57:11.890840+00:00' AIRFLOW_CTX_TRY_NUMBER='2' AIRFLOW_CTX_DAG_RUN_ID='manual__2025-03-18T16:57:11.890840+00:00'
[2025-03-18T17:04:01.924+0000] {logging_mixin.py:190} INFO - Task instance is in running state
[2025-03-18T17:04:01.924+0000] {logging_mixin.py:190} INFO -  Previous state of the Task instance: queued
[2025-03-18T17:04:01.925+0000] {logging_mixin.py:190} INFO - Current task name:dbt_run state:running start_date:2025-03-18 17:04:00.348658+00:00
[2025-03-18T17:04:01.925+0000] {logging_mixin.py:190} INFO - Dag name:load_dbt_clean_reviews_pipeline and current dag run status:running
[2025-03-18T17:04:01.926+0000] {taskinstance.py:732} INFO - ::endgroup::
[2025-03-18T17:04:01.928+0000] {subprocess.py:78} INFO - Tmp dir root location: /tmp
[2025-03-18T17:04:01.954+0000] {subprocess.py:88} INFO - Running command: ['/usr/bin/bash', '-c', 'cd /home/mohammed/.dbt/dbt_projects/bank_reviews_transactional && dbt run']
[2025-03-18T17:04:02.045+0000] {subprocess.py:99} INFO - Output:
[2025-03-18T17:04:20.786+0000] {subprocess.py:106} INFO - [0m17:04:20  Running with dbt=1.9.3
[2025-03-18T17:04:25.741+0000] {subprocess.py:106} INFO - [0m17:04:25  Registered adapter: postgres=1.9.0
[2025-03-18T17:04:29.706+0000] {subprocess.py:106} INFO - [0m17:04:29  [[33mWARNING[0m]: Configuration paths exist in your dbt_project.yml file which do not apply to any resources.
[2025-03-18T17:04:29.710+0000] {subprocess.py:106} INFO - There are 1 unused configuration paths:
[2025-03-18T17:04:29.711+0000] {subprocess.py:106} INFO - - models.bank_reviews_transactional.transactional
[2025-03-18T17:04:32.503+0000] {subprocess.py:106} INFO - [0m17:04:32  Found 3 models, 4 data tests, 1 source, 433 macros
[2025-03-18T17:04:32.516+0000] {subprocess.py:106} INFO - [0m17:04:32
[2025-03-18T17:04:32.530+0000] {subprocess.py:106} INFO - [0m17:04:32  Concurrency: 4 threads (target='dev')
[2025-03-18T17:04:32.534+0000] {subprocess.py:106} INFO - [0m17:04:32
[2025-03-18T17:04:34.009+0000] {subprocess.py:106} INFO - [0m17:04:34  2 of 3 START sql table model transactional.my_first_dbt_model .................. [RUN]
[2025-03-18T17:04:34.012+0000] {subprocess.py:106} INFO - [0m17:04:34  1 of 3 START sql table model transactional.clean_reviews ....................... [RUN]
[2025-03-18T17:04:36.136+0000] {subprocess.py:106} INFO - [0m17:04:36  1 of 3 ERROR creating sql table model transactional.clean_reviews .............. [[31mERROR[0m in 2.05s]
[2025-03-18T17:04:36.281+0000] {subprocess.py:106} INFO - [0m17:04:36  2 of 3 ERROR creating sql table model transactional.my_first_dbt_model ......... [[31mERROR[0m in 2.23s]
[2025-03-18T17:04:36.339+0000] {subprocess.py:106} INFO - [0m17:04:36  3 of 3 SKIP relation transactional.my_second_dbt_model ......................... [[33mSKIP[0m]
[2025-03-18T17:04:36.812+0000] {subprocess.py:106} INFO - [0m17:04:36
[2025-03-18T17:04:36.820+0000] {subprocess.py:106} INFO - [0m17:04:36  Finished running 2 table models, 1 view model in 0 hours 0 minutes and 4.26 seconds (4.26s).
[2025-03-18T17:04:37.574+0000] {subprocess.py:106} INFO - [0m17:04:37
[2025-03-18T17:04:37.580+0000] {subprocess.py:106} INFO - [0m17:04:37  [31mCompleted with 2 errors, 0 partial successes, and 0 warnings:[0m
[2025-03-18T17:04:37.584+0000] {subprocess.py:106} INFO - [0m17:04:37
[2025-03-18T17:04:37.587+0000] {subprocess.py:106} INFO - [0m17:04:37    Database Error in model clean_reviews (models/clean_reviews.sql)
[2025-03-18T17:04:37.592+0000] {subprocess.py:106} INFO -   column reference "review_text" is ambiguous
[2025-03-18T17:04:37.593+0000] {subprocess.py:106} INFO -   LINE 160: SELECT id, bank_name, branch_name, location, review_text, cl...
[2025-03-18T17:04:37.594+0000] {subprocess.py:106} INFO -                                                          ^
[2025-03-18T17:04:37.595+0000] {subprocess.py:106} INFO -   compiled code at target/run/bank_reviews_transactional/models/clean_reviews.sql
[2025-03-18T17:04:37.598+0000] {subprocess.py:106} INFO - [0m17:04:37
[2025-03-18T17:04:37.615+0000] {subprocess.py:106} INFO - [0m17:04:37    Database Error in model my_first_dbt_model (models/example/my_first_dbt_model.sql)
[2025-03-18T17:04:37.616+0000] {subprocess.py:106} INFO -   relation "my_first_dbt_model__dbt_backup" already exists
[2025-03-18T17:04:37.617+0000] {subprocess.py:106} INFO -   compiled code at target/run/bank_reviews_transactional/models/example/my_first_dbt_model.sql
[2025-03-18T17:04:37.621+0000] {subprocess.py:106} INFO - [0m17:04:37
[2025-03-18T17:04:37.648+0000] {subprocess.py:106} INFO - [0m17:04:37  Done. PASS=0 WARN=0 ERROR=2 SKIP=1 TOTAL=3
[2025-03-18T17:04:42.494+0000] {subprocess.py:110} INFO - Command exited with return code 1
[2025-03-18T17:04:42.808+0000] {taskinstance.py:3313} ERROR - Task failed with exception
Traceback (most recent call last):
  File "/home/mohammed/venv/lib/python3.11/site-packages/airflow/models/taskinstance.py", line 768, in _execute_task
    result = _execute_callable(context=context, **execute_callable_kwargs)
             ^^^^^^^^^^^^^^^^^^^^^^^^^^^^^^^^^^^^^^^^^^^^^^^^^^^^^^^^^^^^^
  File "/home/mohammed/venv/lib/python3.11/site-packages/airflow/models/taskinstance.py", line 734, in _execute_callable
    return ExecutionCallableRunner(
           ^^^^^^^^^^^^^^^^^^^^^^^^
  File "/home/mohammed/venv/lib/python3.11/site-packages/airflow/utils/operator_helpers.py", line 252, in run
    return self.func(*args, **kwargs)
           ^^^^^^^^^^^^^^^^^^^^^^^^^^
  File "/home/mohammed/venv/lib/python3.11/site-packages/airflow/models/baseoperator.py", line 424, in wrapper
    return func(self, *args, **kwargs)
           ^^^^^^^^^^^^^^^^^^^^^^^^^^^
  File "/home/mohammed/venv/lib/python3.11/site-packages/airflow/operators/bash.py", line 276, in execute
    raise AirflowException(
airflow.exceptions.AirflowException: Bash command failed. The command returned a non-zero exit code 1.
[2025-03-18T17:04:42.903+0000] {logging_mixin.py:190} INFO - Task instance in failure state
[2025-03-18T17:04:42.904+0000] {logging_mixin.py:190} INFO - Task start:2025-03-18 17:04:00.348658+00:00 end:2025-03-18 17:04:42.872987+00:00 duration:42.524329
[2025-03-18T17:04:42.905+0000] {logging_mixin.py:190} INFO - Task:<Task(BashOperator): dbt_run> dag:<DAG: load_dbt_clean_reviews_pipeline> dagrun:<DagRun load_dbt_clean_reviews_pipeline @ 2025-03-18 16:57:11.890840+00:00: manual__2025-03-18T16:57:11.890840+00:00, state:running, queued_at: 2025-03-18 16:57:12.727108+00:00. externally triggered: True>
[2025-03-18T17:04:42.906+0000] {logging_mixin.py:190} INFO - Failure caused by Bash command failed. The command returned a non-zero exit code 1.
[2025-03-18T17:04:42.907+0000] {taskinstance.py:1226} INFO - Marking task as FAILED. dag_id=load_dbt_clean_reviews_pipeline, task_id=dbt_run, run_id=manual__2025-03-18T16:57:11.890840+00:00, execution_date=20250318T165711, start_date=20250318T170400, end_date=20250318T170442
[2025-03-18T17:04:43.407+0000] {taskinstance.py:341} INFO - ::group::Post task execution logs
[2025-03-18T17:04:43.413+0000] {standard_task_runner.py:124} ERROR - Failed to execute job 759 for task dbt_run (Bash command failed. The command returned a non-zero exit code 1.; 48480)
Traceback (most recent call last):
  File "/home/mohammed/venv/lib/python3.11/site-packages/airflow/task/task_runner/standard_task_runner.py", line 117, in _start_by_fork
    ret = args.func(args, dag=self.dag)
          ^^^^^^^^^^^^^^^^^^^^^^^^^^^^^
  File "/home/mohammed/venv/lib/python3.11/site-packages/airflow/cli/cli_config.py", line 49, in command
    return func(*args, **kwargs)
           ^^^^^^^^^^^^^^^^^^^^^
  File "/home/mohammed/venv/lib/python3.11/site-packages/airflow/utils/cli.py", line 116, in wrapper
    return f(*args, **kwargs)
           ^^^^^^^^^^^^^^^^^^
  File "/home/mohammed/venv/lib/python3.11/site-packages/airflow/cli/commands/task_command.py", line 483, in task_run
    task_return_code = _run_task_by_selected_method(args, _dag, ti)
                       ^^^^^^^^^^^^^^^^^^^^^^^^^^^^^^^^^^^^^^^^^^^^
  File "/home/mohammed/venv/lib/python3.11/site-packages/airflow/cli/commands/task_command.py", line 256, in _run_task_by_selected_method
    return _run_raw_task(args, ti)
           ^^^^^^^^^^^^^^^^^^^^^^^
  File "/home/mohammed/venv/lib/python3.11/site-packages/airflow/cli/commands/task_command.py", line 341, in _run_raw_task
    return ti._run_raw_task(
           ^^^^^^^^^^^^^^^^^
  File "/home/mohammed/venv/lib/python3.11/site-packages/airflow/utils/session.py", line 97, in wrapper
    return func(*args, session=session, **kwargs)
           ^^^^^^^^^^^^^^^^^^^^^^^^^^^^^^^^^^^^^^
  File "/home/mohammed/venv/lib/python3.11/site-packages/airflow/models/taskinstance.py", line 3006, in _run_raw_task
    return _run_raw_task(
           ^^^^^^^^^^^^^^
  File "/home/mohammed/venv/lib/python3.11/site-packages/airflow/models/taskinstance.py", line 274, in _run_raw_task
    TaskInstance._execute_task_with_callbacks(
  File "/home/mohammed/venv/lib/python3.11/site-packages/airflow/models/taskinstance.py", line 3161, in _execute_task_with_callbacks
    result = self._execute_task(context, task_orig)
             ^^^^^^^^^^^^^^^^^^^^^^^^^^^^^^^^^^^^^^
  File "/home/mohammed/venv/lib/python3.11/site-packages/airflow/models/taskinstance.py", line 3185, in _execute_task
    return _execute_task(self, context, task_orig)
           ^^^^^^^^^^^^^^^^^^^^^^^^^^^^^^^^^^^^^^^
  File "/home/mohammed/venv/lib/python3.11/site-packages/airflow/models/taskinstance.py", line 768, in _execute_task
    result = _execute_callable(context=context, **execute_callable_kwargs)
             ^^^^^^^^^^^^^^^^^^^^^^^^^^^^^^^^^^^^^^^^^^^^^^^^^^^^^^^^^^^^^
  File "/home/mohammed/venv/lib/python3.11/site-packages/airflow/models/taskinstance.py", line 734, in _execute_callable
    return ExecutionCallableRunner(
           ^^^^^^^^^^^^^^^^^^^^^^^^
  File "/home/mohammed/venv/lib/python3.11/site-packages/airflow/utils/operator_helpers.py", line 252, in run
    return self.func(*args, **kwargs)
           ^^^^^^^^^^^^^^^^^^^^^^^^^^
  File "/home/mohammed/venv/lib/python3.11/site-packages/airflow/models/baseoperator.py", line 424, in wrapper
    return func(self, *args, **kwargs)
           ^^^^^^^^^^^^^^^^^^^^^^^^^^^
  File "/home/mohammed/venv/lib/python3.11/site-packages/airflow/operators/bash.py", line 276, in execute
    raise AirflowException(
airflow.exceptions.AirflowException: Bash command failed. The command returned a non-zero exit code 1.
[2025-03-18T17:04:43.556+0000] {local_task_job_runner.py:266} INFO - Task exited with return code 1
[2025-03-18T17:04:43.714+0000] {taskinstance.py:3901} INFO - 0 downstream tasks scheduled from follow-on schedule check
[2025-03-18T17:04:43.774+0000] {local_task_job_runner.py:245} INFO - ::endgroup::
