[2025-03-18T18:11:32.037+0000] {local_task_job_runner.py:123} INFO - ::group::Pre task execution logs
[2025-03-18T18:11:32.509+0000] {taskinstance.py:2614} INFO - Dependencies all met for dep_context=non-requeueable deps ti=<TaskInstance: load_dbt_clean_reviews_pipeline.dbt_run scheduled__2024-04-18T00:00:00+00:00 [queued]>
[2025-03-18T18:11:32.575+0000] {taskinstance.py:2614} INFO - Dependencies all met for dep_context=requeueable deps ti=<TaskInstance: load_dbt_clean_reviews_pipeline.dbt_run scheduled__2024-04-18T00:00:00+00:00 [queued]>
[2025-03-18T18:11:32.578+0000] {taskinstance.py:2867} INFO - Starting attempt 2 of 2
[2025-03-18T18:11:32.803+0000] {taskinstance.py:2890} INFO - Executing <Task(BashOperator): dbt_run> on 2024-04-18 00:00:00+00:00
[2025-03-18T18:11:33.041+0000] {standard_task_runner.py:104} INFO - Running: ['airflow', 'tasks', 'run', 'load_dbt_clean_reviews_pipeline', 'dbt_run', 'scheduled__2024-04-18T00:00:00+00:00', '--job-id', '863', '--raw', '--subdir', 'DAGS_FOLDER/dag_load_reviews.py', '--cfg-path', '/tmp/tmpxeuaa9eg']
[2025-03-18T18:11:33.057+0000] {standard_task_runner.py:105} INFO - Job 863: Subtask dbt_run
[2025-03-18T18:11:32.925+0000] {standard_task_runner.py:72} INFO - Started process 975 to run task
[2025-03-18T18:11:34.129+0000] {task_command.py:467} INFO - Running <TaskInstance: load_dbt_clean_reviews_pipeline.dbt_run scheduled__2024-04-18T00:00:00+00:00 [running]> on host DESKTOP-IM7V4RI.
[2025-03-18T18:11:35.438+0000] {taskinstance.py:3134} INFO - Exporting env vars: AIRFLOW_CTX_DAG_OWNER='mohammed' AIRFLOW_CTX_DAG_ID='load_dbt_clean_reviews_pipeline' AIRFLOW_CTX_TASK_ID='dbt_run' AIRFLOW_CTX_EXECUTION_DATE='2024-04-18T00:00:00+00:00' AIRFLOW_CTX_TRY_NUMBER='2' AIRFLOW_CTX_DAG_RUN_ID='scheduled__2024-04-18T00:00:00+00:00'
[2025-03-18T18:11:35.444+0000] {logging_mixin.py:190} INFO - Task instance is in running state
[2025-03-18T18:11:35.446+0000] {logging_mixin.py:190} INFO -  Previous state of the Task instance: queued
[2025-03-18T18:11:35.447+0000] {logging_mixin.py:190} INFO - Current task name:dbt_run state:running start_date:2025-03-18 18:11:32.510141+00:00
[2025-03-18T18:11:35.447+0000] {logging_mixin.py:190} INFO - Dag name:load_dbt_clean_reviews_pipeline and current dag run status:running
[2025-03-18T18:11:35.461+0000] {taskinstance.py:732} INFO - ::endgroup::
[2025-03-18T18:11:35.464+0000] {subprocess.py:78} INFO - Tmp dir root location: /tmp
[2025-03-18T18:11:35.479+0000] {subprocess.py:88} INFO - Running command: ['/usr/bin/bash', '-c', 'cd /home/mohammed/.dbt/dbt_projects/bank_reviews_transactional && dbt run']
[2025-03-18T18:11:35.594+0000] {subprocess.py:99} INFO - Output:
[2025-03-18T18:11:56.740+0000] {subprocess.py:106} INFO - [0m18:11:56  Running with dbt=1.9.3
[2025-03-18T18:12:01.499+0000] {subprocess.py:106} INFO - [0m18:12:01  Registered adapter: postgres=1.9.0
[2025-03-18T18:12:05.145+0000] {subprocess.py:106} INFO - [0m18:12:05  [[33mWARNING[0m]: Configuration paths exist in your dbt_project.yml file which do not apply to any resources.
[2025-03-18T18:12:05.146+0000] {subprocess.py:106} INFO - There are 1 unused configuration paths:
[2025-03-18T18:12:05.148+0000] {subprocess.py:106} INFO - - models.bank_reviews_transactional.transactional
[2025-03-18T18:12:07.255+0000] {subprocess.py:106} INFO - [0m18:12:07  Found 3 models, 4 data tests, 1 source, 433 macros
[2025-03-18T18:12:07.263+0000] {subprocess.py:106} INFO - [0m18:12:07
[2025-03-18T18:12:07.266+0000] {subprocess.py:106} INFO - [0m18:12:07  Concurrency: 4 threads (target='dev')
[2025-03-18T18:12:07.268+0000] {subprocess.py:106} INFO - [0m18:12:07
[2025-03-18T18:12:08.851+0000] {subprocess.py:106} INFO - [0m18:12:08  1 of 3 START sql table model transactional.clean_reviews ....................... [RUN]
[2025-03-18T18:12:08.883+0000] {subprocess.py:106} INFO - [0m18:12:08  2 of 3 START sql table model transactional.my_first_dbt_model .................. [RUN]
[2025-03-18T18:12:12.290+0000] {subprocess.py:106} INFO - [0m18:12:12  2 of 3 OK created sql table model transactional.my_first_dbt_model ............. [[32mSELECT 2[0m in 3.40s]
[2025-03-18T18:12:12.299+0000] {subprocess.py:106} INFO - [0m18:12:12  3 of 3 START sql view model transactional.my_second_dbt_model .................. [RUN]
[2025-03-18T18:12:12.470+0000] {subprocess.py:106} INFO - [0m18:12:12  3 of 3 ERROR creating sql view model transactional.my_second_dbt_model ......... [[31mERROR[0m in 0.17s]
[2025-03-18T18:12:16.034+0000] {subprocess.py:106} INFO - [0m18:12:16  1 of 3 OK created sql table model transactional.clean_reviews .................. [[32mSELECT 549[0m in 7.18s]
[2025-03-18T18:12:16.162+0000] {subprocess.py:106} INFO - [0m18:12:16
[2025-03-18T18:12:16.169+0000] {subprocess.py:106} INFO - [0m18:12:16  Finished running 2 table models, 1 view model in 0 hours 0 minutes and 8.89 seconds (8.89s).
[2025-03-18T18:12:16.577+0000] {subprocess.py:106} INFO - [0m18:12:16
[2025-03-18T18:12:16.582+0000] {subprocess.py:106} INFO - [0m18:12:16  [31mCompleted with 1 error, 0 partial successes, and 0 warnings:[0m
[2025-03-18T18:12:16.593+0000] {subprocess.py:106} INFO - [0m18:12:16
[2025-03-18T18:12:16.618+0000] {subprocess.py:106} INFO - [0m18:12:16    Database Error in model my_second_dbt_model (models/example/my_second_dbt_model.sql)
[2025-03-18T18:12:16.620+0000] {subprocess.py:106} INFO -   relation "my_second_dbt_model" already exists
[2025-03-18T18:12:16.622+0000] {subprocess.py:106} INFO -   compiled code at target/run/bank_reviews_transactional/models/example/my_second_dbt_model.sql
[2025-03-18T18:12:16.630+0000] {subprocess.py:106} INFO - [0m18:12:16
[2025-03-18T18:12:16.633+0000] {subprocess.py:106} INFO - [0m18:12:16  Done. PASS=2 WARN=0 ERROR=1 SKIP=0 TOTAL=3
[2025-03-18T18:12:19.834+0000] {subprocess.py:110} INFO - Command exited with return code 1
[2025-03-18T18:12:20.109+0000] {taskinstance.py:3313} ERROR - Task failed with exception
Traceback (most recent call last):
  File "/home/mohammed/venv/lib/python3.11/site-packages/airflow/models/taskinstance.py", line 768, in _execute_task
    result = _execute_callable(context=context, **execute_callable_kwargs)
             ^^^^^^^^^^^^^^^^^^^^^^^^^^^^^^^^^^^^^^^^^^^^^^^^^^^^^^^^^^^^^
  File "/home/mohammed/venv/lib/python3.11/site-packages/airflow/models/taskinstance.py", line 734, in _execute_callable
    return ExecutionCallableRunner(
           ^^^^^^^^^^^^^^^^^^^^^^^^
  File "/home/mohammed/venv/lib/python3.11/site-packages/airflow/utils/operator_helpers.py", line 252, in run
    return self.func(*args, **kwargs)
           ^^^^^^^^^^^^^^^^^^^^^^^^^^
  File "/home/mohammed/venv/lib/python3.11/site-packages/airflow/models/baseoperator.py", line 424, in wrapper
    return func(self, *args, **kwargs)
           ^^^^^^^^^^^^^^^^^^^^^^^^^^^
  File "/home/mohammed/venv/lib/python3.11/site-packages/airflow/operators/bash.py", line 276, in execute
    raise AirflowException(
airflow.exceptions.AirflowException: Bash command failed. The command returned a non-zero exit code 1.
[2025-03-18T18:12:20.192+0000] {logging_mixin.py:190} INFO - Task instance in failure state
[2025-03-18T18:12:20.199+0000] {logging_mixin.py:190} INFO - Task start:2025-03-18 18:11:32.510141+00:00 end:2025-03-18 18:12:20.161350+00:00 duration:47.651209
[2025-03-18T18:12:20.202+0000] {logging_mixin.py:190} INFO - Task:<Task(BashOperator): dbt_run> dag:<DAG: load_dbt_clean_reviews_pipeline> dagrun:<DagRun load_dbt_clean_reviews_pipeline @ 2024-04-18 00:00:00+00:00: scheduled__2024-04-18T00:00:00+00:00, state:running, queued_at: 2025-03-18 17:11:17.147755+00:00. externally triggered: False>
[2025-03-18T18:12:20.203+0000] {logging_mixin.py:190} INFO - Failure caused by Bash command failed. The command returned a non-zero exit code 1.
[2025-03-18T18:12:20.204+0000] {taskinstance.py:1226} INFO - Marking task as FAILED. dag_id=load_dbt_clean_reviews_pipeline, task_id=dbt_run, run_id=scheduled__2024-04-18T00:00:00+00:00, execution_date=20240418T000000, start_date=20250318T181132, end_date=20250318T181220
[2025-03-18T18:12:20.409+0000] {taskinstance.py:341} INFO - ::group::Post task execution logs
[2025-03-18T18:12:20.416+0000] {standard_task_runner.py:124} ERROR - Failed to execute job 863 for task dbt_run (Bash command failed. The command returned a non-zero exit code 1.; 975)
Traceback (most recent call last):
  File "/home/mohammed/venv/lib/python3.11/site-packages/airflow/task/task_runner/standard_task_runner.py", line 117, in _start_by_fork
    ret = args.func(args, dag=self.dag)
          ^^^^^^^^^^^^^^^^^^^^^^^^^^^^^
  File "/home/mohammed/venv/lib/python3.11/site-packages/airflow/cli/cli_config.py", line 49, in command
    return func(*args, **kwargs)
           ^^^^^^^^^^^^^^^^^^^^^
  File "/home/mohammed/venv/lib/python3.11/site-packages/airflow/utils/cli.py", line 116, in wrapper
    return f(*args, **kwargs)
           ^^^^^^^^^^^^^^^^^^
  File "/home/mohammed/venv/lib/python3.11/site-packages/airflow/cli/commands/task_command.py", line 483, in task_run
    task_return_code = _run_task_by_selected_method(args, _dag, ti)
                       ^^^^^^^^^^^^^^^^^^^^^^^^^^^^^^^^^^^^^^^^^^^^
  File "/home/mohammed/venv/lib/python3.11/site-packages/airflow/cli/commands/task_command.py", line 256, in _run_task_by_selected_method
    return _run_raw_task(args, ti)
           ^^^^^^^^^^^^^^^^^^^^^^^
  File "/home/mohammed/venv/lib/python3.11/site-packages/airflow/cli/commands/task_command.py", line 341, in _run_raw_task
    return ti._run_raw_task(
           ^^^^^^^^^^^^^^^^^
  File "/home/mohammed/venv/lib/python3.11/site-packages/airflow/utils/session.py", line 97, in wrapper
    return func(*args, session=session, **kwargs)
           ^^^^^^^^^^^^^^^^^^^^^^^^^^^^^^^^^^^^^^
  File "/home/mohammed/venv/lib/python3.11/site-packages/airflow/models/taskinstance.py", line 3006, in _run_raw_task
    return _run_raw_task(
           ^^^^^^^^^^^^^^
  File "/home/mohammed/venv/lib/python3.11/site-packages/airflow/models/taskinstance.py", line 274, in _run_raw_task
    TaskInstance._execute_task_with_callbacks(
  File "/home/mohammed/venv/lib/python3.11/site-packages/airflow/models/taskinstance.py", line 3161, in _execute_task_with_callbacks
    result = self._execute_task(context, task_orig)
             ^^^^^^^^^^^^^^^^^^^^^^^^^^^^^^^^^^^^^^
  File "/home/mohammed/venv/lib/python3.11/site-packages/airflow/models/taskinstance.py", line 3185, in _execute_task
    return _execute_task(self, context, task_orig)
           ^^^^^^^^^^^^^^^^^^^^^^^^^^^^^^^^^^^^^^^
  File "/home/mohammed/venv/lib/python3.11/site-packages/airflow/models/taskinstance.py", line 768, in _execute_task
    result = _execute_callable(context=context, **execute_callable_kwargs)
             ^^^^^^^^^^^^^^^^^^^^^^^^^^^^^^^^^^^^^^^^^^^^^^^^^^^^^^^^^^^^^
  File "/home/mohammed/venv/lib/python3.11/site-packages/airflow/models/taskinstance.py", line 734, in _execute_callable
    return ExecutionCallableRunner(
           ^^^^^^^^^^^^^^^^^^^^^^^^
  File "/home/mohammed/venv/lib/python3.11/site-packages/airflow/utils/operator_helpers.py", line 252, in run
    return self.func(*args, **kwargs)
           ^^^^^^^^^^^^^^^^^^^^^^^^^^
  File "/home/mohammed/venv/lib/python3.11/site-packages/airflow/models/baseoperator.py", line 424, in wrapper
    return func(self, *args, **kwargs)
           ^^^^^^^^^^^^^^^^^^^^^^^^^^^
  File "/home/mohammed/venv/lib/python3.11/site-packages/airflow/operators/bash.py", line 276, in execute
    raise AirflowException(
airflow.exceptions.AirflowException: Bash command failed. The command returned a non-zero exit code 1.
[2025-03-18T18:12:20.484+0000] {local_task_job_runner.py:266} INFO - Task exited with return code 1
[2025-03-18T18:12:20.904+0000] {taskinstance.py:3901} INFO - 0 downstream tasks scheduled from follow-on schedule check
[2025-03-18T18:12:20.921+0000] {local_task_job_runner.py:245} INFO - ::endgroup::
