[2025-03-28T23:01:55.418+0000] {local_task_job_runner.py:123} INFO - ::group::Pre task execution logs
[2025-03-28T23:01:55.765+0000] {taskinstance.py:2614} INFO - Dependencies all met for dep_context=non-requeueable deps ti=<TaskInstance: bank_reviews_etl_and_analysis_pipeline.dbt_run_decisionnal scheduled__2024-12-15T00:00:00+00:00 [queued]>
[2025-03-28T23:01:55.827+0000] {taskinstance.py:2614} INFO - Dependencies all met for dep_context=requeueable deps ti=<TaskInstance: bank_reviews_etl_and_analysis_pipeline.dbt_run_decisionnal scheduled__2024-12-15T00:00:00+00:00 [queued]>
[2025-03-28T23:01:55.828+0000] {taskinstance.py:2867} INFO - Starting attempt 2 of 2
[2025-03-28T23:01:56.970+0000] {taskinstance.py:2890} INFO - Executing <Task(BashOperator): dbt_run_decisionnal> on 2024-12-15 00:00:00+00:00
[2025-03-28T23:01:57.028+0000] {standard_task_runner.py:72} INFO - Started process 593867 to run task
[2025-03-28T23:01:57.071+0000] {standard_task_runner.py:104} INFO - Running: ['airflow', 'tasks', 'run', 'bank_reviews_etl_and_analysis_pipeline', 'dbt_run_decisionnal', 'scheduled__2024-12-15T00:00:00+00:00', '--job-id', '2480', '--raw', '--subdir', 'DAGS_FOLDER/dag_load_reviews.py', '--cfg-path', '/tmp/tmpdp0eo7t8']
[2025-03-28T23:01:57.079+0000] {standard_task_runner.py:105} INFO - Job 2480: Subtask dbt_run_decisionnal
[2025-03-28T23:01:57.901+0000] {task_command.py:467} INFO - Running <TaskInstance: bank_reviews_etl_and_analysis_pipeline.dbt_run_decisionnal scheduled__2024-12-15T00:00:00+00:00 [running]> on host DESKTOP-IM7V4RI.
[2025-03-28T23:01:59.311+0000] {taskinstance.py:3134} INFO - Exporting env vars: AIRFLOW_CTX_DAG_OWNER='mohammed' AIRFLOW_CTX_DAG_ID='bank_reviews_etl_and_analysis_pipeline' AIRFLOW_CTX_TASK_ID='dbt_run_decisionnal' AIRFLOW_CTX_EXECUTION_DATE='2024-12-15T00:00:00+00:00' AIRFLOW_CTX_TRY_NUMBER='2' AIRFLOW_CTX_DAG_RUN_ID='scheduled__2024-12-15T00:00:00+00:00'
[2025-03-28T23:01:59.341+0000] {logging_mixin.py:190} INFO - Task instance is in running state
[2025-03-28T23:01:59.341+0000] {logging_mixin.py:190} INFO -  Previous state of the Task instance: queued
[2025-03-28T23:01:59.342+0000] {logging_mixin.py:190} INFO - Current task name:dbt_run_decisionnal state:running start_date:2025-03-28 23:01:55.765730+00:00
[2025-03-28T23:01:59.343+0000] {logging_mixin.py:190} INFO - Dag name:bank_reviews_etl_and_analysis_pipeline and current dag run status:running
[2025-03-28T23:01:59.344+0000] {taskinstance.py:732} INFO - ::endgroup::
[2025-03-28T23:01:59.357+0000] {subprocess.py:78} INFO - Tmp dir root location: /tmp
[2025-03-28T23:01:59.374+0000] {subprocess.py:88} INFO - Running command: ['/usr/bin/bash', '-c', 'cd /home/mohammed/.dbt/dbt_projects/bank_reviews_decisionnal && dbt run']
[2025-03-28T23:01:59.585+0000] {subprocess.py:99} INFO - Output:
[2025-03-28T23:02:24.558+0000] {subprocess.py:106} INFO - [0m23:02:24  Running with dbt=1.9.3
[2025-03-28T23:02:27.753+0000] {subprocess.py:106} INFO - [0m23:02:27  Registered adapter: postgres=1.9.0
[2025-03-28T23:02:35.533+0000] {subprocess.py:106} INFO - [0m23:02:35  [[33mWARNING[0m]: Configuration paths exist in your dbt_project.yml file which do not apply to any resources.
[2025-03-28T23:02:35.559+0000] {subprocess.py:106} INFO - There are 1 unused configuration paths:
[2025-03-28T23:02:35.562+0000] {subprocess.py:106} INFO - - models.bank_reviews_decisionnal.decisionnal
[2025-03-28T23:02:39.362+0000] {subprocess.py:106} INFO - [0m23:02:39  Found 5 models, 2 sources, 547 macros
[2025-03-28T23:02:39.425+0000] {subprocess.py:106} INFO - [0m23:02:39
[2025-03-28T23:02:39.428+0000] {subprocess.py:106} INFO - [0m23:02:39  Concurrency: 4 threads (target='dev')
[2025-03-28T23:02:39.430+0000] {subprocess.py:106} INFO - [0m23:02:39
[2025-03-28T23:02:43.523+0000] {subprocess.py:106} INFO - [0m23:02:43  1 of 5 START sql table model decisionnal.dim_bank .............................. [RUN]
[2025-03-28T23:02:43.599+0000] {subprocess.py:106} INFO - [0m23:02:43  3 of 5 START sql table model decisionnal.dim_location .......................... [RUN]
[2025-03-28T23:02:43.687+0000] {subprocess.py:106} INFO - [0m23:02:43  2 of 5 START sql table model decisionnal.dim_branch ............................ [RUN]
[2025-03-28T23:02:43.803+0000] {subprocess.py:106} INFO - [0m23:02:43  4 of 5 START sql table model decisionnal.dim_sentiment ......................... [RUN]
[2025-03-28T23:02:46.963+0000] {subprocess.py:106} INFO - [0m23:02:46  2 of 5 OK created sql table model decisionnal.dim_branch ....................... [[32mSELECT 298[0m in 3.27s]
[2025-03-28T23:02:47.050+0000] {subprocess.py:106} INFO - [0m23:02:47  1 of 5 OK created sql table model decisionnal.dim_bank ......................... [[32mSELECT 299[0m in 3.48s]
[2025-03-28T23:02:47.077+0000] {subprocess.py:106} INFO - [0m23:02:47  3 of 5 OK created sql table model decisionnal.dim_location ..................... [[32mSELECT 298[0m in 3.38s]
[2025-03-28T23:02:47.617+0000] {subprocess.py:106} INFO - [0m23:02:47  4 of 5 OK created sql table model decisionnal.dim_sentiment .................... [[32mSELECT 2591[0m in 3.81s]
[2025-03-28T23:02:47.635+0000] {subprocess.py:106} INFO - [0m23:02:47  5 of 5 START sql table model decisionnal.fact_reviews .......................... [RUN]
[2025-03-28T23:02:50.904+0000] {subprocess.py:106} INFO - [0m23:02:50  5 of 5 ERROR creating sql table model decisionnal.fact_reviews ................. [[31mERROR[0m in 3.26s]
[2025-03-28T23:02:51.141+0000] {subprocess.py:106} INFO - [0m23:02:51
[2025-03-28T23:02:51.183+0000] {subprocess.py:106} INFO - [0m23:02:51  Finished running 5 table models in 0 hours 0 minutes and 11.71 seconds (11.71s).
[2025-03-28T23:02:52.630+0000] {subprocess.py:106} INFO - [0m23:02:52
[2025-03-28T23:02:52.632+0000] {subprocess.py:106} INFO - [0m23:02:52  [31mCompleted with 1 error, 0 partial successes, and 0 warnings:[0m
[2025-03-28T23:02:52.633+0000] {subprocess.py:106} INFO - [0m23:02:52
[2025-03-28T23:02:52.661+0000] {subprocess.py:106} INFO - [0m23:02:52    Database Error in model fact_reviews (models/fact_reviews.sql)
[2025-03-28T23:02:52.661+0000] {subprocess.py:106} INFO -   column cr.topics does not exist
[2025-03-28T23:02:52.662+0000] {subprocess.py:106} INFO -   LINE 24:     cr.topics,
[2025-03-28T23:02:52.676+0000] {subprocess.py:106} INFO -                ^
[2025-03-28T23:02:52.676+0000] {subprocess.py:106} INFO -   HINT:  Perhaps you meant to reference the column "cr.topic".
[2025-03-28T23:02:52.677+0000] {subprocess.py:106} INFO -   compiled code at target/run/bank_reviews_decisionnal/models/fact_reviews.sql
[2025-03-28T23:02:52.694+0000] {subprocess.py:106} INFO - [0m23:02:52
[2025-03-28T23:02:52.699+0000] {subprocess.py:106} INFO - [0m23:02:52  Done. PASS=4 WARN=0 ERROR=1 SKIP=0 TOTAL=5
[2025-03-28T23:02:58.049+0000] {subprocess.py:110} INFO - Command exited with return code 1
[2025-03-28T23:02:58.937+0000] {taskinstance.py:3313} ERROR - Task failed with exception
Traceback (most recent call last):
  File "/home/mohammed/venv/lib/python3.11/site-packages/airflow/models/taskinstance.py", line 768, in _execute_task
    result = _execute_callable(context=context, **execute_callable_kwargs)
             ^^^^^^^^^^^^^^^^^^^^^^^^^^^^^^^^^^^^^^^^^^^^^^^^^^^^^^^^^^^^^
  File "/home/mohammed/venv/lib/python3.11/site-packages/airflow/models/taskinstance.py", line 734, in _execute_callable
    return ExecutionCallableRunner(
           ^^^^^^^^^^^^^^^^^^^^^^^^
  File "/home/mohammed/venv/lib/python3.11/site-packages/airflow/utils/operator_helpers.py", line 252, in run
    return self.func(*args, **kwargs)
           ^^^^^^^^^^^^^^^^^^^^^^^^^^
  File "/home/mohammed/venv/lib/python3.11/site-packages/airflow/models/baseoperator.py", line 424, in wrapper
    return func(self, *args, **kwargs)
           ^^^^^^^^^^^^^^^^^^^^^^^^^^^
  File "/home/mohammed/venv/lib/python3.11/site-packages/airflow/operators/bash.py", line 276, in execute
    raise AirflowException(
airflow.exceptions.AirflowException: Bash command failed. The command returned a non-zero exit code 1.
[2025-03-28T23:02:59.118+0000] {logging_mixin.py:190} INFO - Task instance in failure state
[2025-03-28T23:02:59.119+0000] {logging_mixin.py:190} INFO - Task start:2025-03-28 23:01:55.765730+00:00 end:2025-03-28 23:02:59.047008+00:00 duration:63.281278
[2025-03-28T23:02:59.125+0000] {logging_mixin.py:190} INFO - Task:<Task(BashOperator): dbt_run_decisionnal> dag:<DAG: bank_reviews_etl_and_analysis_pipeline> dagrun:<DagRun bank_reviews_etl_and_analysis_pipeline @ 2024-12-15 00:00:00+00:00: scheduled__2024-12-15T00:00:00+00:00, state:running, queued_at: 2025-03-28 22:55:59.341379+00:00. externally triggered: False>
[2025-03-28T23:02:59.126+0000] {logging_mixin.py:190} INFO - Failure caused by Bash command failed. The command returned a non-zero exit code 1.
[2025-03-28T23:02:59.127+0000] {taskinstance.py:1226} INFO - Marking task as FAILED. dag_id=bank_reviews_etl_and_analysis_pipeline, task_id=dbt_run_decisionnal, run_id=scheduled__2024-12-15T00:00:00+00:00, execution_date=20241215T000000, start_date=20250328T230155, end_date=20250328T230259
[2025-03-28T23:03:00.733+0000] {taskinstance.py:341} INFO - ::group::Post task execution logs
[2025-03-28T23:03:00.742+0000] {standard_task_runner.py:124} ERROR - Failed to execute job 2480 for task dbt_run_decisionnal (Bash command failed. The command returned a non-zero exit code 1.; 593867)
Traceback (most recent call last):
  File "/home/mohammed/venv/lib/python3.11/site-packages/airflow/task/task_runner/standard_task_runner.py", line 117, in _start_by_fork
    ret = args.func(args, dag=self.dag)
          ^^^^^^^^^^^^^^^^^^^^^^^^^^^^^
  File "/home/mohammed/venv/lib/python3.11/site-packages/airflow/cli/cli_config.py", line 49, in command
    return func(*args, **kwargs)
           ^^^^^^^^^^^^^^^^^^^^^
  File "/home/mohammed/venv/lib/python3.11/site-packages/airflow/utils/cli.py", line 116, in wrapper
    return f(*args, **kwargs)
           ^^^^^^^^^^^^^^^^^^
  File "/home/mohammed/venv/lib/python3.11/site-packages/airflow/cli/commands/task_command.py", line 483, in task_run
    task_return_code = _run_task_by_selected_method(args, _dag, ti)
                       ^^^^^^^^^^^^^^^^^^^^^^^^^^^^^^^^^^^^^^^^^^^^
  File "/home/mohammed/venv/lib/python3.11/site-packages/airflow/cli/commands/task_command.py", line 256, in _run_task_by_selected_method
    return _run_raw_task(args, ti)
           ^^^^^^^^^^^^^^^^^^^^^^^
  File "/home/mohammed/venv/lib/python3.11/site-packages/airflow/cli/commands/task_command.py", line 341, in _run_raw_task
    return ti._run_raw_task(
           ^^^^^^^^^^^^^^^^^
  File "/home/mohammed/venv/lib/python3.11/site-packages/airflow/utils/session.py", line 97, in wrapper
    return func(*args, session=session, **kwargs)
           ^^^^^^^^^^^^^^^^^^^^^^^^^^^^^^^^^^^^^^
  File "/home/mohammed/venv/lib/python3.11/site-packages/airflow/models/taskinstance.py", line 3006, in _run_raw_task
    return _run_raw_task(
           ^^^^^^^^^^^^^^
  File "/home/mohammed/venv/lib/python3.11/site-packages/airflow/models/taskinstance.py", line 274, in _run_raw_task
    TaskInstance._execute_task_with_callbacks(
  File "/home/mohammed/venv/lib/python3.11/site-packages/airflow/models/taskinstance.py", line 3161, in _execute_task_with_callbacks
    result = self._execute_task(context, task_orig)
             ^^^^^^^^^^^^^^^^^^^^^^^^^^^^^^^^^^^^^^
  File "/home/mohammed/venv/lib/python3.11/site-packages/airflow/models/taskinstance.py", line 3185, in _execute_task
    return _execute_task(self, context, task_orig)
           ^^^^^^^^^^^^^^^^^^^^^^^^^^^^^^^^^^^^^^^
  File "/home/mohammed/venv/lib/python3.11/site-packages/airflow/models/taskinstance.py", line 768, in _execute_task
    result = _execute_callable(context=context, **execute_callable_kwargs)
             ^^^^^^^^^^^^^^^^^^^^^^^^^^^^^^^^^^^^^^^^^^^^^^^^^^^^^^^^^^^^^
  File "/home/mohammed/venv/lib/python3.11/site-packages/airflow/models/taskinstance.py", line 734, in _execute_callable
    return ExecutionCallableRunner(
           ^^^^^^^^^^^^^^^^^^^^^^^^
  File "/home/mohammed/venv/lib/python3.11/site-packages/airflow/utils/operator_helpers.py", line 252, in run
    return self.func(*args, **kwargs)
           ^^^^^^^^^^^^^^^^^^^^^^^^^^
  File "/home/mohammed/venv/lib/python3.11/site-packages/airflow/models/baseoperator.py", line 424, in wrapper
    return func(self, *args, **kwargs)
           ^^^^^^^^^^^^^^^^^^^^^^^^^^^
  File "/home/mohammed/venv/lib/python3.11/site-packages/airflow/operators/bash.py", line 276, in execute
    raise AirflowException(
airflow.exceptions.AirflowException: Bash command failed. The command returned a non-zero exit code 1.
[2025-03-28T23:03:00.810+0000] {local_task_job_runner.py:266} INFO - Task exited with return code 1
[2025-03-28T23:03:01.074+0000] {taskinstance.py:3901} INFO - 0 downstream tasks scheduled from follow-on schedule check
[2025-03-28T23:03:01.094+0000] {local_task_job_runner.py:245} INFO - ::endgroup::
