[2025-03-28T23:11:48.624+0000] {local_task_job_runner.py:123} INFO - ::group::Pre task execution logs
[2025-03-28T23:11:48.716+0000] {taskinstance.py:2614} INFO - Dependencies all met for dep_context=non-requeueable deps ti=<TaskInstance: bank_reviews_etl_and_analysis_pipeline.dbt_run_decisionnal manual__2025-03-28T23:11:45.765865+00:00 [queued]>
[2025-03-28T23:11:48.741+0000] {taskinstance.py:2614} INFO - Dependencies all met for dep_context=requeueable deps ti=<TaskInstance: bank_reviews_etl_and_analysis_pipeline.dbt_run_decisionnal manual__2025-03-28T23:11:45.765865+00:00 [queued]>
[2025-03-28T23:11:48.741+0000] {taskinstance.py:2867} INFO - Starting attempt 1 of 2
[2025-03-28T23:11:48.776+0000] {taskinstance.py:2890} INFO - Executing <Task(BashOperator): dbt_run_decisionnal> on 2025-03-28 23:11:45.765865+00:00
[2025-03-28T23:11:48.785+0000] {standard_task_runner.py:72} INFO - Started process 602270 to run task
[2025-03-28T23:11:48.798+0000] {standard_task_runner.py:104} INFO - Running: ['airflow', 'tasks', 'run', 'bank_reviews_etl_and_analysis_pipeline', 'dbt_run_decisionnal', 'manual__2025-03-28T23:11:45.765865+00:00', '--job-id', '2489', '--raw', '--subdir', 'DAGS_FOLDER/dag_load_reviews.py', '--cfg-path', '/tmp/tmp709rr6sr']
[2025-03-28T23:11:48.802+0000] {standard_task_runner.py:105} INFO - Job 2489: Subtask dbt_run_decisionnal
[2025-03-28T23:11:48.933+0000] {task_command.py:467} INFO - Running <TaskInstance: bank_reviews_etl_and_analysis_pipeline.dbt_run_decisionnal manual__2025-03-28T23:11:45.765865+00:00 [running]> on host DESKTOP-IM7V4RI.
[2025-03-28T23:11:49.183+0000] {taskinstance.py:3134} INFO - Exporting env vars: AIRFLOW_CTX_DAG_OWNER='mohammed' AIRFLOW_CTX_DAG_ID='bank_reviews_etl_and_analysis_pipeline' AIRFLOW_CTX_TASK_ID='dbt_run_decisionnal' AIRFLOW_CTX_EXECUTION_DATE='2025-03-28T23:11:45.765865+00:00' AIRFLOW_CTX_TRY_NUMBER='1' AIRFLOW_CTX_DAG_RUN_ID='manual__2025-03-28T23:11:45.765865+00:00'
[2025-03-28T23:11:49.185+0000] {logging_mixin.py:190} INFO - Task instance is in running state
[2025-03-28T23:11:49.186+0000] {logging_mixin.py:190} INFO -  Previous state of the Task instance: queued
[2025-03-28T23:11:49.186+0000] {logging_mixin.py:190} INFO - Current task name:dbt_run_decisionnal state:running start_date:2025-03-28 23:11:48.717033+00:00
[2025-03-28T23:11:49.187+0000] {logging_mixin.py:190} INFO - Dag name:bank_reviews_etl_and_analysis_pipeline and current dag run status:running
[2025-03-28T23:11:49.187+0000] {taskinstance.py:732} INFO - ::endgroup::
[2025-03-28T23:11:49.188+0000] {subprocess.py:78} INFO - Tmp dir root location: /tmp
[2025-03-28T23:11:49.190+0000] {subprocess.py:88} INFO - Running command: ['/usr/bin/bash', '-c', 'cd /home/mohammed/.dbt/dbt_projects/bank_reviews_decisionnal && dbt run --full-refresh']
[2025-03-28T23:11:49.206+0000] {subprocess.py:99} INFO - Output:
[2025-03-28T23:11:52.873+0000] {subprocess.py:106} INFO - [0m23:11:52  Running with dbt=1.9.3
[2025-03-28T23:11:53.306+0000] {subprocess.py:106} INFO - [0m23:11:53  Registered adapter: postgres=1.9.0
[2025-03-28T23:11:53.605+0000] {subprocess.py:106} INFO - [0m23:11:53  [[33mWARNING[0m]: Configuration paths exist in your dbt_project.yml file which do not apply to any resources.
[2025-03-28T23:11:53.606+0000] {subprocess.py:106} INFO - There are 1 unused configuration paths:
[2025-03-28T23:11:53.606+0000] {subprocess.py:106} INFO - - models.bank_reviews_decisionnal.decisionnal
[2025-03-28T23:11:53.899+0000] {subprocess.py:106} INFO - [0m23:11:53  Found 5 models, 2 sources, 547 macros
[2025-03-28T23:11:53.904+0000] {subprocess.py:106} INFO - [0m23:11:53
[2025-03-28T23:11:53.905+0000] {subprocess.py:106} INFO - [0m23:11:53  Concurrency: 4 threads (target='dev')
[2025-03-28T23:11:53.906+0000] {subprocess.py:106} INFO - [0m23:11:53
[2025-03-28T23:11:54.291+0000] {subprocess.py:106} INFO - [0m23:11:54  1 of 5 START sql table model decisionnal.dim_bank .............................. [RUN]
[2025-03-28T23:11:54.295+0000] {subprocess.py:106} INFO - [0m23:11:54  2 of 5 START sql table model decisionnal.dim_branch ............................ [RUN]
[2025-03-28T23:11:54.297+0000] {subprocess.py:106} INFO - [0m23:11:54  3 of 5 START sql table model decisionnal.dim_location .......................... [RUN]
[2025-03-28T23:11:54.299+0000] {subprocess.py:106} INFO - [0m23:11:54  4 of 5 START sql table model decisionnal.dim_sentiment ......................... [RUN]
[2025-03-28T23:11:54.779+0000] {subprocess.py:106} INFO - [0m23:11:54  3 of 5 ERROR creating sql table model decisionnal.dim_location ................. [[31mERROR[0m in 0.46s]
[2025-03-28T23:11:54.782+0000] {subprocess.py:106} INFO - [0m23:11:54  2 of 5 ERROR creating sql table model decisionnal.dim_branch ................... [[31mERROR[0m in 0.48s]
[2025-03-28T23:11:54.784+0000] {subprocess.py:106} INFO - [0m23:11:54  1 of 5 ERROR creating sql table model decisionnal.dim_bank ..................... [[31mERROR[0m in 0.48s]
[2025-03-28T23:11:54.810+0000] {subprocess.py:106} INFO - [0m23:11:54  4 of 5 ERROR creating sql table model decisionnal.dim_sentiment ................ [[31mERROR[0m in 0.50s]
[2025-03-28T23:11:54.816+0000] {subprocess.py:106} INFO - [0m23:11:54  5 of 5 SKIP relation decisionnal.fact_reviews .................................. [[33mSKIP[0m]
[2025-03-28T23:11:54.852+0000] {subprocess.py:106} INFO - [0m23:11:54
[2025-03-28T23:11:54.853+0000] {subprocess.py:106} INFO - [0m23:11:54  Finished running 5 table models in 0 hours 0 minutes and 0.95 seconds (0.95s).
[2025-03-28T23:11:54.914+0000] {subprocess.py:106} INFO - [0m23:11:54
[2025-03-28T23:11:54.915+0000] {subprocess.py:106} INFO - [0m23:11:54  [31mCompleted with 4 errors, 0 partial successes, and 0 warnings:[0m
[2025-03-28T23:11:54.916+0000] {subprocess.py:106} INFO - [0m23:11:54
[2025-03-28T23:11:54.917+0000] {subprocess.py:106} INFO - [0m23:11:54    Database Error in model dim_location (models/dim_location.sql)
[2025-03-28T23:11:54.917+0000] {subprocess.py:106} INFO -   relation "decisionnal.dim_location" does not exist
[2025-03-28T23:11:54.917+0000] {subprocess.py:106} INFO -   compiled code at target/run/bank_reviews_decisionnal/models/dim_location.sql
[2025-03-28T23:11:54.918+0000] {subprocess.py:106} INFO - [0m23:11:54
[2025-03-28T23:11:54.918+0000] {subprocess.py:106} INFO - [0m23:11:54    Database Error in model dim_branch (models/dim_branch.sql)
[2025-03-28T23:11:54.919+0000] {subprocess.py:106} INFO -   relation "decisionnal.dim_branch" does not exist
[2025-03-28T23:11:54.919+0000] {subprocess.py:106} INFO -   compiled code at target/run/bank_reviews_decisionnal/models/dim_branch.sql
[2025-03-28T23:11:54.920+0000] {subprocess.py:106} INFO - [0m23:11:54
[2025-03-28T23:11:54.921+0000] {subprocess.py:106} INFO - [0m23:11:54    Database Error in model dim_bank (models/dim_bank.sql)
[2025-03-28T23:11:54.921+0000] {subprocess.py:106} INFO -   relation "decisionnal.dim_bank" does not exist
[2025-03-28T23:11:54.922+0000] {subprocess.py:106} INFO -   compiled code at target/run/bank_reviews_decisionnal/models/dim_bank.sql
[2025-03-28T23:11:54.922+0000] {subprocess.py:106} INFO - [0m23:11:54
[2025-03-28T23:11:54.924+0000] {subprocess.py:106} INFO - [0m23:11:54    Database Error in model dim_sentiment (models/dim_sentiment.sql)
[2025-03-28T23:11:54.924+0000] {subprocess.py:106} INFO -   relation "decisionnal.dim_sentiment" does not exist
[2025-03-28T23:11:54.924+0000] {subprocess.py:106} INFO -   compiled code at target/run/bank_reviews_decisionnal/models/dim_sentiment.sql
[2025-03-28T23:11:54.924+0000] {subprocess.py:106} INFO - [0m23:11:54
[2025-03-28T23:11:54.925+0000] {subprocess.py:106} INFO - [0m23:11:54  Done. PASS=0 WARN=0 ERROR=4 SKIP=1 TOTAL=5
[2025-03-28T23:11:56.437+0000] {subprocess.py:110} INFO - Command exited with return code 1
[2025-03-28T23:11:56.485+0000] {taskinstance.py:3313} ERROR - Task failed with exception
Traceback (most recent call last):
  File "/home/mohammed/venv/lib/python3.11/site-packages/airflow/models/taskinstance.py", line 768, in _execute_task
    result = _execute_callable(context=context, **execute_callable_kwargs)
             ^^^^^^^^^^^^^^^^^^^^^^^^^^^^^^^^^^^^^^^^^^^^^^^^^^^^^^^^^^^^^
  File "/home/mohammed/venv/lib/python3.11/site-packages/airflow/models/taskinstance.py", line 734, in _execute_callable
    return ExecutionCallableRunner(
           ^^^^^^^^^^^^^^^^^^^^^^^^
  File "/home/mohammed/venv/lib/python3.11/site-packages/airflow/utils/operator_helpers.py", line 252, in run
    return self.func(*args, **kwargs)
           ^^^^^^^^^^^^^^^^^^^^^^^^^^
  File "/home/mohammed/venv/lib/python3.11/site-packages/airflow/models/baseoperator.py", line 424, in wrapper
    return func(self, *args, **kwargs)
           ^^^^^^^^^^^^^^^^^^^^^^^^^^^
  File "/home/mohammed/venv/lib/python3.11/site-packages/airflow/operators/bash.py", line 276, in execute
    raise AirflowException(
airflow.exceptions.AirflowException: Bash command failed. The command returned a non-zero exit code 1.
[2025-03-28T23:11:56.502+0000] {logging_mixin.py:190} INFO - Task instance in failure state
[2025-03-28T23:11:56.502+0000] {logging_mixin.py:190} INFO - Task start:2025-03-28 23:11:48.717033+00:00 end:2025-03-28 23:11:56.500192+00:00 duration:7.783159
[2025-03-28T23:11:56.503+0000] {logging_mixin.py:190} INFO - Task:<Task(BashOperator): dbt_run_decisionnal> dag:<DAG: bank_reviews_etl_and_analysis_pipeline> dagrun:<DagRun bank_reviews_etl_and_analysis_pipeline @ 2025-03-28 23:11:45.765865+00:00: manual__2025-03-28T23:11:45.765865+00:00, state:running, queued_at: 2025-03-28 23:11:45.790770+00:00. externally triggered: True>
[2025-03-28T23:11:56.503+0000] {logging_mixin.py:190} INFO - Failure caused by Bash command failed. The command returned a non-zero exit code 1.
[2025-03-28T23:11:56.504+0000] {taskinstance.py:1226} INFO - Marking task as UP_FOR_RETRY. dag_id=bank_reviews_etl_and_analysis_pipeline, task_id=dbt_run_decisionnal, run_id=manual__2025-03-28T23:11:45.765865+00:00, execution_date=20250328T231145, start_date=20250328T231148, end_date=20250328T231156
[2025-03-28T23:11:56.670+0000] {taskinstance.py:341} INFO - ::group::Post task execution logs
[2025-03-28T23:11:56.672+0000] {standard_task_runner.py:124} ERROR - Failed to execute job 2489 for task dbt_run_decisionnal (Bash command failed. The command returned a non-zero exit code 1.; 602270)
Traceback (most recent call last):
  File "/home/mohammed/venv/lib/python3.11/site-packages/airflow/task/task_runner/standard_task_runner.py", line 117, in _start_by_fork
    ret = args.func(args, dag=self.dag)
          ^^^^^^^^^^^^^^^^^^^^^^^^^^^^^
  File "/home/mohammed/venv/lib/python3.11/site-packages/airflow/cli/cli_config.py", line 49, in command
    return func(*args, **kwargs)
           ^^^^^^^^^^^^^^^^^^^^^
  File "/home/mohammed/venv/lib/python3.11/site-packages/airflow/utils/cli.py", line 116, in wrapper
    return f(*args, **kwargs)
           ^^^^^^^^^^^^^^^^^^
  File "/home/mohammed/venv/lib/python3.11/site-packages/airflow/cli/commands/task_command.py", line 483, in task_run
    task_return_code = _run_task_by_selected_method(args, _dag, ti)
                       ^^^^^^^^^^^^^^^^^^^^^^^^^^^^^^^^^^^^^^^^^^^^
  File "/home/mohammed/venv/lib/python3.11/site-packages/airflow/cli/commands/task_command.py", line 256, in _run_task_by_selected_method
    return _run_raw_task(args, ti)
           ^^^^^^^^^^^^^^^^^^^^^^^
  File "/home/mohammed/venv/lib/python3.11/site-packages/airflow/cli/commands/task_command.py", line 341, in _run_raw_task
    return ti._run_raw_task(
           ^^^^^^^^^^^^^^^^^
  File "/home/mohammed/venv/lib/python3.11/site-packages/airflow/utils/session.py", line 97, in wrapper
    return func(*args, session=session, **kwargs)
           ^^^^^^^^^^^^^^^^^^^^^^^^^^^^^^^^^^^^^^
  File "/home/mohammed/venv/lib/python3.11/site-packages/airflow/models/taskinstance.py", line 3006, in _run_raw_task
    return _run_raw_task(
           ^^^^^^^^^^^^^^
  File "/home/mohammed/venv/lib/python3.11/site-packages/airflow/models/taskinstance.py", line 274, in _run_raw_task
    TaskInstance._execute_task_with_callbacks(
  File "/home/mohammed/venv/lib/python3.11/site-packages/airflow/models/taskinstance.py", line 3161, in _execute_task_with_callbacks
    result = self._execute_task(context, task_orig)
             ^^^^^^^^^^^^^^^^^^^^^^^^^^^^^^^^^^^^^^
  File "/home/mohammed/venv/lib/python3.11/site-packages/airflow/models/taskinstance.py", line 3185, in _execute_task
    return _execute_task(self, context, task_orig)
           ^^^^^^^^^^^^^^^^^^^^^^^^^^^^^^^^^^^^^^^
  File "/home/mohammed/venv/lib/python3.11/site-packages/airflow/models/taskinstance.py", line 768, in _execute_task
    result = _execute_callable(context=context, **execute_callable_kwargs)
             ^^^^^^^^^^^^^^^^^^^^^^^^^^^^^^^^^^^^^^^^^^^^^^^^^^^^^^^^^^^^^
  File "/home/mohammed/venv/lib/python3.11/site-packages/airflow/models/taskinstance.py", line 734, in _execute_callable
    return ExecutionCallableRunner(
           ^^^^^^^^^^^^^^^^^^^^^^^^
  File "/home/mohammed/venv/lib/python3.11/site-packages/airflow/utils/operator_helpers.py", line 252, in run
    return self.func(*args, **kwargs)
           ^^^^^^^^^^^^^^^^^^^^^^^^^^
  File "/home/mohammed/venv/lib/python3.11/site-packages/airflow/models/baseoperator.py", line 424, in wrapper
    return func(self, *args, **kwargs)
           ^^^^^^^^^^^^^^^^^^^^^^^^^^^
  File "/home/mohammed/venv/lib/python3.11/site-packages/airflow/operators/bash.py", line 276, in execute
    raise AirflowException(
airflow.exceptions.AirflowException: Bash command failed. The command returned a non-zero exit code 1.
[2025-03-28T23:11:56.709+0000] {local_task_job_runner.py:266} INFO - Task exited with return code 1
[2025-03-28T23:11:56.815+0000] {taskinstance.py:3901} INFO - 0 downstream tasks scheduled from follow-on schedule check
[2025-03-28T23:11:56.822+0000] {local_task_job_runner.py:245} INFO - ::endgroup::
